Workbook

Sheet Inputs
A1: FINANCIAL MODEL INPUTS
A3: Timeline | B3: Unit | C3: Jan-25 | D3: Feb-25 | E3: Mar-25 | F3: Apr-25 | G3: May-25 | H3: Jun-25 | I3: Jul-25 | J3: Aug-25 | K3: Sep-25 | L3: Oct-25 | M3: Nov-25 | N3: Dec-25
A5: REVENUE ASSUMPTIONS
A6: Monthly Revenue Growth | B6: % | C6: 0.05
A7: Base Revenue (Month 1) | B7: $ | C7: 100000
A8: Revenue | B8: $ | C8: =C7 | D8: =C8*(1+$C$6) | E8: =D8*(1+$C$6) | F8: =E8*(1+$C$6) | G8: =F8*(1+$C$6) | H8: =G8*(1+$C$6) | I8: =H8*(1+$C$6) | J8: =I8*(1+$C$6) | K8: =J8*(1+$C$6) | ... N8: =M8*(1+$C$6)
A10: COST OF GOODS SOLD
A11: COGS % of Revenue | B11: % | C11: 0.4
A13: OPERATING EXPENSES
A14: Salaries & Wages | B14: $ | C14: 25000
A15: Rent | B15: $ | C15: 5000
A16: Marketing | B16: $ | C16: 8000
A17: Other Operating Expenses | B17: $ | C17: 3000
A19: WORKING CAPITAL
A20: AR Days | B20: days | C20: 45
A21: Inventory Days | B21: days | C21: 30
A22: AP Days | B22: days | C22: 30
A23: Prepayments (months) | B23: months | C23: 1
A24: Accrued Expenses % of OpEx | B24: % | C24: 0.15
A25: Deferred Revenue (months) | B25: months | C25: 1
A27: CAPITAL EXPENDITURE
A28: Monthly CapEx | B28: $ | C28: 50000 | D28: 0 | E28: 0 | F28: 0 | G28: 0 | H28: 0 | I28: 0 | J28: 0 | K28: 0 | L28: 0 | M28: 0 | N28: 0
A29: Depreciation Rate (annual) | B29: % | C29: 0.2
A30: Monthly Depreciation Rate | B30: % | C30: =C29/12
A32: DEBT
A33: Interest Rate (annual) | B33: % | C33: 0.06
A34: Monthly Interest Rate | B34: % | C34: =C33/12
A35: New Borrowing | B35: $ | C35: 200000 | D35: 0 | E35: 0 | F35: 0 | G35: 0 | H35: 0 | I35: 0 | J35: 0 | K35: 0 | L35: 0 | M35: 0 | N35: 0
A36: Debt Repayment | B36: $ | C36: 5000 | D36: 5000 | E36: 5000 | F36: 5000 | G36: 5000 | H36: 5000 | I36: 5000 | J36: 5000 | K36: 5000 | L36: 5000 | M36: 5000 | N36: 5000
A38: EQUITY
A39: Share Capital Injection | B39: $ | C39: 100000 | D39: 0 | E39: 0 | F39: 0 | G39: 0 | H39: 0 | I39: 0 | J39: 0 | K39: 0 | L39: 0 | M39: 0 | N39: 0
A40: Dividends Paid | B40: $ | C40: 0 | D40: 0 | E40: 0 | F40: 0 | G40: 0 | H40: 0 | I40: 0 | J40: 0 | K40: 0 | L40: 0 | M40: 0 | N40: 0
A42: OPENING BALANCES
A43: Opening Cash | B43: $ | C43: 50000
A44: Opening AR | B44: $ | C44: 0
A45: Opening Inventory | B45: $ | C45: 0
A46: Opening Prepayments | B46: $ | C46: 0
A47: Opening Fixed Assets (Gross) | B47: $ | C47: 0
A48: Opening Accumulated Depreciation | B48: $ | C48: 0
A49: Opening AP | B49: $ | C49: 0
...

Sheet Workings
A1: CONTROL ACCOUNTS - WORKINGS
A3: Timeline | C3: =Inputs!C3 | D3: =Inputs!D3 | E3: =Inputs!E3 | F3: =Inputs!F3 | G3: =Inputs!G3 | H3: =Inputs!H3 | I3: =Inputs!I3 | J3: =Inputs!J3 | ... N3: =Inputs!N3
A5: CASH CONTROL ACCOUNT
A6: Opening Balance | C6: =Inputs!$C$59 | D6: =C17 | E6: =D17 | F6: =E17 | G6: =F17 | H6: =G17 | I6: =H17 | J6: =I17 | K6: =J17 | ... N6: =M17
A7: Cash Inflows:
A8: Cash from Customers | C8: =C32 | D8: =D32 | E8: =E32 | F8: =F32 | G8: =G32 | H8: =H32 | I8: =I32 | J8: =J32 | ... N8: =N32
A9: New Borrowing | C9: =Inputs!C$52 | D9: =Inputs!D$52 | E9: =Inputs!E$52 | F9: =Inputs!F$52 | G9: =Inputs!G$52 | H9: =Inputs!H$52 | I9: =Inputs!I$52 | J9: =Inputs!J$52 | ... N9: =Inputs!N$52
A10: Share Capital Injection | C10: =Inputs!C$57 | D10: =Inputs!D$57 | E10: =Inputs!E$57 | F10: =Inputs!F$57 | G10: =Inputs!G$57 | H10: =Inputs!H$57 | I10: =Inputs!I$57 | J10: =Inputs!J$57 | ... N10: =Inputs!N$57
A11: Total Inflows | C11: =SUM(C8:C10) | D11: =SUM(D8:D10) | E11: =SUM(E8:E10) | F11: =SUM(F8:F10) | G11: =SUM(G8:G10) | H11: =SUM(H8:H10) | I11: =SUM(I8:I10) | J11: =SUM(J8:J10) | ... N11: =SUM(N8:N10)
A12: Cash Outflows:
A13: Payments to Suppliers | C13: =C69 | D13: =D69 | E13: =E69 | F13: =F69 | G13: =G69 | H13: =H69 | I13: =I69 | J13: =J69 | ... N13: =N69
A14: Operating Expenses Paid | C14: =C90 | D14: =D90 | E14: =E90 | F14: =F90 | G14: =G90 | H14: =H90 | I14: =I90 | J14: =J90 | ... N14: =N90
A15: Capital Expenditure | C15: =Inputs!C$44 | D15: =Inputs!D$44 | E15: =Inputs!E$44 | F15: =Inputs!F$44 | G15: =Inputs!G$44 | H15: =Inputs!H$44 | I15: =Inputs!I$44 | J15: =Inputs!J$44 | ... N15: =Inputs!N$44
A16: Interest Paid | C16: =C118 | D16: =D118 | E16: =E118 | F16: =F118 | G16: =G118 | H16: =H118 | I16: =I118 | J16: =J118 | ... N16: =N118
A17: Debt Repayment | C17: =Inputs!C$53 | D17: =Inputs!D$53 | E17: =Inputs!E$53 | F17: =Inputs!F$53 | G17: =Inputs!G$53 | H17: =Inputs!H$53 | I17: =Inputs!I$53 | J17: =Inputs!J$53 | ... N17: =Inputs!N$53
A18: Dividends Paid | C18: =Inputs!C$58 | D18: =Inputs!D$58 | E18: =Inputs!E$58 | F18: =Inputs!F$58 | G18: =Inputs!G$58 | H18: =Inputs!H$58 | I18: =Inputs!I$58 | J18: =Inputs!J$58 | ... N18: =Inputs!N$58
A19: Total Outflows | C19: =SUM(C13:C18) | D19: =SUM(D13:D18) | E19: =SUM(E13:E18) | F19: =SUM(F13:F18) | G19: =SUM(G13:G18) | H19: =SUM(H13:H18) | I19: =SUM(I13:I18) | J19: =SUM(J13:J18) | ... N19: =SUM(N13:N18)
A20: Closing Balance | C20: =C7+C13-C19 | D20: =D7+D13-D19 | E20: =E7+E13-E19 | F20: =F7+F13-F19 | G20: =G7+G13-G19 | H20: =H7+H13-H19 | I20: =I7+I13-I19 | J20: =J7+J13-J19 | ... N20: =N7+N13-N19
A22: ACCOUNTS RECEIVABLE CONTROL
A23: Opening Balance | C23: =Inputs!$C$60 | D23: =C26 | E23: =D26 | F23: =E26 | G23: =F26 | H23: =G26 | I23: =H26 | J23: =I26 | K23: =J26 | ... N23: =M26
A24: Credit Sales (Revenue) | C24: =Inputs!C$9 | D24: =Inputs!D$9 | E24: =Inputs!E$9 | F24: =Inputs!F$9 | G24: =Inputs!G$9 | H24: =Inputs!H$9 | I24: =Inputs!I$9 | J24: =Inputs!J$9 | ... N24: =Inputs!N$9
A25: Cash Received from Customers | C25: =(C23*30)/(Inputs!$C$23+30) | D25: =(D23*30)/(Inputs!$C$23+30) | E25: =(E23*30)/(Inputs!$C$23+30) | F25: =(F23*30)/(Inputs!$C$23+30) | G25: =(G23*30)/(Inputs!$C$23+30) | H25: =(H23*30)/(Inputs!$C$23+30) | I25: =(I23*30)/(Inputs!$C$23+30) | J25: =(J23*30)/(Inputs!$C$23+30) | ... N25: =(N23*30)/(Inputs!$C$23+30)
A26: Closing Balance | C26: =C23+C24-C25 | D26: =D23+D24-D25 | E26: =E23+E24-E25 | F26: =F23+F24-F25 | G26: =G23+G24-G25 | H26: =H23+H24-H25 | I26: =I23+I24-I25 | J26: =J23+J24-J25 | ... N26: =N23+N24-N25
A28: INVENTORY CONTROL
A29: Opening Balance | C29: =Inputs!$C$61 | D29: =C33 | E29: =D33 | F29: =E33 | G29: =F33 | H29: =G33 | I29: =H33 | J29: =I33 | K29: =J33 | ... N29: =M33
A30: Purchases | C30: =(Inputs!C$9*Inputs!$C$12+Inputs!$C$24*30)/30 | D30: =(Inputs!D$9*Inputs!$C$12+Inputs!$C$24*30)/30 | E30: =(Inputs!E$9*Inputs!$C$12+Inputs!$C$24*30)/30 | F30: =(Inputs!F$9*Inputs!$C$12+Inputs!$C$24*30)/30 | G30: =(Inputs!G$9*Inputs!$C$12+Inputs!$C$24*30)/30 | H30: =(Inputs!H$9*Inputs!$C$12+Inputs!$C$24*30)/30 | I30: =(Inputs!I$9*Inputs!$C$12+Inputs!$C$24*30)/30 | J30: =(Inputs!J$9*Inputs!$C$12+Inputs!$C$24*30)/30 | ... N30: =(Inputs!N$9*Inputs!$C$12+Inputs!$C$24*30)/30
A31: COGS Withdrawal | C31: =Inputs!C$9*Inputs!$C$12 | D31: =Inputs!D$9*Inputs!$C$12 | E31: =Inputs!E$9*Inputs!$C$12 | F31: =Inputs!F$9*Inputs!$C$12 | G31: =Inputs!G$9*Inputs!$C$12 | H31: =Inputs!H$9*Inputs!$C$12 | I31: =Inputs!I$9*Inputs!$C$12 | J31: =Inputs!J$9*Inputs!$C$12 | ... N31: =Inputs!N$9*Inputs!$C$12
A32: Adjustments | C32: 0 | D32: 0 | E32: 0 | F32: 0 | G32: 0 | H32: 0 | I32: 0 | J32: 0 | K32: 0 | L32: 0 | M32: 0 | N32: 0
A33: Closing Balance | C33: =C29+C30-C31+C32 | D33: =D29+D30-D31+D32 | E33: =E29+E30-E31+E32 | F33: =F29+F30-F31+F32 | G33: =G29+G30-G31+G32 | H33: =H29+H30-H31+H32 | I33: =I29+I30-I31+I32 | J33: =J29+J30-J31+J32 | ... N33: =N29+N30-N31+N32
A35: PREPAYMENTS CONTROL
A36: Opening Balance | C36: =Inputs!$C$62 | D36: =C39 | E36: =D39 | F36: =E39 | G36: =F39 | H36: =G39 | I36: =H39 | J36: =I39 | K36: =J39 | ... N36: =M39
A37: New Prepayments (cash paid) | C37: =(Inputs!$C$17+Inputs!$C$18+Inputs!$C$19)*Inputs!$C$26 | D37: =(Inputs!$C$17+Inputs!$C$18+Inputs!$C$19)*Inputs!$C$26 | E37: =(Inputs!$C$17+Inputs!$C$18+Inputs!$C$19)*Inputs!$C$26 | F37: =(Inputs!$C$17+Inputs!$C$18+Inputs!$C$19)*Inputs!$C$26 | G37: =(Inputs!$C$17+Inputs!$C$18+Inputs!$C$19)*Inputs!$C$26 | H37: =(Inputs!$C$17+Inputs!$C$18+Inputs!$C$19)*Inputs!$C$26 | I37: =(Inputs!$C$17+Inputs!$C$18+Inputs!$C$19)*Inputs!$C$26 | J37: =(Inputs!$C$17+Inputs!$C$18+Inputs!$C$19)*Inputs!$C$26 | ... N37: =(Inputs!$C$17+Inputs!$C$18+Inputs!$C$19)*Inputs!$C$26
A38: Amortization (expense) | C38: =C36+C37 | D38: =D36+D37 | E38: =E36+E37 | F38: =F36+F37 | G38: =G36+G37 | H38: =H36+H37 | I38: =I36+I37 | J38: =J36+J37 | ... N38: =N36+N37
A39: Closing Balance | C39: =C36+C37-C38 | D39: =D36+D37-D38 | E39: =E36+E37-E38 | F39: =F36+F37-F38 | G39: =G36+G37-G38 | H39: =H36+H37-H38 | I39: =I36+I37-I38 | J39: =J36+J37-J38 | ... N39: =N36+N37-N38
A41: ACCOUNTS PAYABLE CONTROL
A42: Opening Balance | C42: =Inputs!$C$65 | D42: =C45 | E42: =D45 | F42: =E45 | G42: =F45 | H42: =G45 | I42: =H45 | J42: =I45 | K42: =J45 | ... N42: =M45
A43: Purchases on Credit | C43: =C41 | D43: =D41 | E43: =E41 | F43: =F41 | G43: =G41 | H43: =H41 | I43: =I41 | J43: =J41 | ... N43: =N41
A44: Cash Payments to Suppliers | C44: =(C42*30)/(Inputs!$C$25+30) | D44: =(D42*30)/(Inputs!$C$25+30) | E44: =(E42*30)/(Inputs!$C$25+30) | F44: =(F42*30)/(Inputs!$C$25+30) | G44: =(G42*30)/(Inputs!$C$25+30) | H44: =(H42*30)/(Inputs!$C$25+30) | I44: =(I42*30)/(Inputs!$C$25+30) | J44: =(J42*30)/(Inputs!$C$25+30) | ... N44: =(N42*30)/(Inputs!$C$25+30)
A45: Closing Balance | C45: =C42+C43-C44 | D45: =D42+D43-D44 | E45: =E42+E43-E44 | F45: =F42+F43-F44 | G45: =G42+G43-G44 | H45: =H42+H43-H44 | I45: =I42+I43-I44 | J45: =J42+J43-J44 | ... N45: =N42+N43-N44
A47: ACCRUED EXPENSES CONTROL
...

Sheet Income Statement
A1: INCOME STATEMENT
A3: Period | C3: =Inputs!C3 | D3: =Inputs!D3 | E3: =Inputs!E3 | F3: =Inputs!F3 | G3: =Inputs!G3 | H3: =Inputs!H3 | I3: =Inputs!I3 | J3: =Inputs!J3 | ... N3: =Inputs!N3
A5: Revenue | C5: =Inputs!C$9 | D5: =Inputs!D$9 | E5: =Inputs!E$9 | F5: =Inputs!F$9 | G5: =Inputs!G$9 | H5: =Inputs!H$9 | I5: =Inputs!I$9 | J5: =Inputs!J$9 | ... N5: =Inputs!N$9
A6: Cost of Goods Sold | C6: =Workings!C42 | D6: =Workings!D42 | E6: =Workings!E42 | F6: =Workings!F42 | G6: =Workings!G42 | H6: =Workings!H42 | I6: =Workings!I42 | J6: =Workings!J42 | ... N6: =Workings!N42
A7: Gross Profit | C7: =C5-C6 | D7: =D5-D6 | E7: =E5-E6 | F7: =F5-F6 | G7: =G5-G6 | H7: =H5-H6 | I7: =I5-I6 | J7: =J5-J6 | ... N7: =N5-N6
A9: Operating Expenses:
A10: Salaries & Wages | C10: =Inputs!$C$15 | D10: =Inputs!$C$15 | E10: =Inputs!$C$15 | F10: =Inputs!$C$15 | G10: =Inputs!$C$15 | H10: =Inputs!$C$15 | I10: =Inputs!$C$15 | J10: =Inputs!$C$15 | ... N10: =Inputs!$C$15
A11: Rent | C11: =Inputs!$C$17 | D11: =Inputs!$C$17 | E11: =Inputs!$C$17 | F11: =Inputs!$C$17 | G11: =Inputs!$C$17 | H11: =Inputs!$C$17 | I11: =Inputs!$C$17 | J11: =Inputs!$C$17 | ... N11: =Inputs!$C$17
A12: Marketing | C12: =Inputs!$C$18 | D12: =Inputs!$C$18 | E12: =Inputs!$C$18 | F12: =Inputs!$C$18 | G12: =Inputs!$C$18 | H12: =Inputs!$C$18 | I12: =Inputs!$C$18 | J12: =Inputs!$C$18 | ... N12: =Inputs!$C$18
A13: Other Operating Expenses | C13: =Inputs!$C$19 | D13: =Inputs!$C$19 | E13: =Inputs!$C$19 | F13: =Inputs!$C$19 | G13: =Inputs!$C$19 | H13: =Inputs!$C$19 | I13: =Inputs!$C$19 | J13: =Inputs!$C$19 | ... N13: =Inputs!$C$19
A14: Depreciation | C14: =Workings!C112 | D14: =Workings!D112 | E14: =Workings!E112 | F14: =Workings!F112 | G14: =Workings!G112 | H14: =Workings!H112 | I14: =Workings!I112 | J14: =Workings!J112 | ... N14: =Workings!N112
A15: Total Operating Expenses | C15: =SUM(C10:C14) | D15: =SUM(D10:D14) | E15: =SUM(E10:E14) | F15: =SUM(F10:F14) | G15: =SUM(G10:G14) | H15: =SUM(H10:H14) | I15: =SUM(I10:I14) | J15: =SUM(J10:J14) | ... N15: =SUM(N10:N14)
A17: EBIT | C17: =C8-C15 | D17: =D8-D15 | E17: =E8-E15 | F17: =F8-F15 | G17: =G8-G15 | H17: =H8-H15 | I17: =I8-I15 | J17: =J8-J15 | ... N17: =N8-N15
A19: Interest Expense | C19: =Workings!C117 | D19: =Workings!D117 | E19: =Workings!E117 | F19: =Workings!F117 | G19: =Workings!G117 | H19: =Workings!H117 | I19: =Workings!I117 | J19: =Workings!J117 | ... N19: =Workings!N117
A20: Earnings Before Tax | C20: =C17-C19 | D20: =D17-D19 | E20: =E17-E19 | F20: =F17-F19 | G20: =G17-G19 | H20: =H17-H19 | I20: =I17-I19 | J20: =J17-J19 | ... N20: =N17-N19
A22: Income Tax | C22: 0 | D22: 0 | E22: 0 | F22: 0 | G22: 0 | H22: 0 | I22: 0 | J22: 0 | K22: 0 | L22: 0 | M22: 0 | N22: 0
A24: NET INCOME | C24: =C20-C22 | D24: =D20-D22 | E24: =E20-E22 | F24: =F20-F22 | G24: =G20-G22 | H24: =H20-H22 | I24: =I20-I22 | J24: =J20-J22 | ... N24: =N20-N22

Sheet Balance Sheet
A1: BALANCE SHEET
A3: Period Ending | C3: =Inputs!C3 | D3: =Inputs!D3 | E3: =Inputs!E3 | F3: =Inputs!F3 | G3: =Inputs!G3 | H3: =Inputs!H3 | I3: =Inputs!I3 | J3: =Inputs!J3 | ... N3: =Inputs!N3
A5: ASSETS
A6: Current Assets:
A7: Cash | C7: =Workings!C18 | D7: =Workings!D18 | E7: =Workings!E18 | F7: =Workings!F18 | G7: =Workings!G18 | H7: =Workings!H18 | I7: =Workings!I18 | J7: =Workings!J18 | ... N7: =Workings!N18
A8: Accounts Receivable | C8: =Workings!C32 | D8: =Workings!D32 | E8: =Workings!E32 | F8: =Workings!F32 | G8: =Workings!G32 | H8: =Workings!H32 | I8: =Workings!I32 | J8: =Workings!J32 | ... N8: =Workings!N32
A9: Inventory | C9: =Workings!C45 | D9: =Workings!D45 | E9: =Workings!E45 | F9: =Workings!F45 | G9: =Workings!G45 | H9: =Workings!H45 | I9: =Workings!I45 | J9: =Workings!J45 | ... N9: =Workings!N45
A10: Prepayments | C10: =Workings!C54 | D10: =Workings!D54 | E10: =Workings!E54 | F10: =Workings!F54 | G10: =Workings!G54 | H10: =Workings!H54 | I10: =Workings!I54 | J10: =Workings!J54 | ... N10: =Workings!N54
A11: Total Current Assets | C11: =SUM(C7:C10) | D11: =SUM(D7:D10) | E11: =SUM(E7:E10) | F11: =SUM(F7:F10) | G11: =SUM(G7:G10) | H11: =SUM(H7:H10) | I11: =SUM(I7:I10) | J11: =SUM(J7:J10) | ... N11: =SUM(N7:N10)
A13: Non-Current Assets:
A14: Fixed Assets (Gross) | C14: =Workings!C105 | D14: =Workings!D105 | E14: =Workings!E105 | F14: =Workings!F105 | G14: =Workings!G105 | H14: =Workings!H105 | I14: =Workings!I105 | J14: =Workings!J105 | ... N14: =Workings!N105
A15: Accumulated Depreciation | C15: =-Workings!C112 | D15: =-Workings!D112 | E15: =-Workings!E112 | F15: =-Workings!F112 | G15: =-Workings!G112 | H15: =-Workings!H112 | I15: =-Workings!I112 | J15: =-Workings!J112 | ... N15: =-Workings!N112
A16: Fixed Assets (Net) | C16: =C14+C15 | D16: =D14+D15 | E16: =E14+E15 | F16: =F14+F15 | G16: =G14+G15 | H16: =H14+H15 | I16: =I14+I15 | J16: =J14+J15 | ... N16: =N14+N15
A18: TOTAL ASSETS | C18: =C9+C16 | D18: =D9+D16 | E18: =E9+E16 | F18: =F9+F16 | G18: =G9+G16 | H18: =H9+H16 | I18: =I9+I16 | J18: =J9+J16 | ... N18: =N9+N16
A20: LIABILITIES
A21: Current Liabilities:
A22: Accounts Payable | C22: =Workings!C69 | D22: =Workings!D69 | E22: =Workings!E69 | F22: =Workings!F69 | G22: =Workings!G69 | H22: =Workings!H69 | I22: =Workings!I69 | J22: =Workings!J69 | ... N22: =Workings!N69
A23: Accrued Expenses | C23: =Workings!C90 | D23: =Workings!D90 | E23: =Workings!E90 | F23: =Workings!F90 | G23: =Workings!G90 | H23: =Workings!H90 | I23: =Workings!I90 | J23: =Workings!J90 | ... N23: =Workings!N90
A24: Deferred Revenue | C24: =Workings!C97 | D24: =Workings!D97 | E24: =Workings!E97 | F24: =Workings!F97 | G24: =Workings!G97 | H24: =Workings!H97 | I24: =Workings!I97 | J24: =Workings!J97 | ... N24: =Workings!N97
A25: Total Current Liabilities | C25: =SUM(C22:C24) | D25: =SUM(D22:D24) | E25: =SUM(E22:E24) | F25: =SUM(F22:F24) | G25: =SUM(G22:G24) | H25: =SUM(H22:H24) | I25: =SUM(I22:I24) | J25: =SUM(J22:J24) | ... N25: =SUM(N22:N24)
A27: Non-Current Liabilities:
A28: Long-term Debt | C28: =Workings!C123 | D28: =Workings!D123 | E28: =Workings!E123 | F28: =Workings!F123 | G28: =Workings!G123 | H28: =Workings!H123 | I28: =Workings!I123 | J28: =Workings!J123 | ... N28: =Workings!N123
A29: Total Non-Current Liabilities | C29: =C28 | D29: =D28 | E29: =E28 | F29: =F28 | G29: =G28 | H29: =H28 | I29: =I28 | J29: =J28 | ... N29: =N28
A31: TOTAL LIABILITIES | C31: =C23+C29 | D31: =D23+D29 | E31: =E23+E29 | F31: =F23+F29 | G31: =G23+G29 | H31: =H23+H29 | I31: =I23+I29 | J31: =J23+J29 | ... N31: =N23+N29
A33: EQUITY
A34: Share Capital | C34: =Workings!C128 | D34: =Workings!D128 | E34: =Workings!E128 | F34: =Workings!F128 | G34: =Workings!G128 | H34: =Workings!H128 | I34: =Workings!I128 | J34: =Workings!J128 | ... N34: =Workings!N128
A35: Retained Earnings | C35: =Workings!C134 | D35: =Workings!D134 | E35: =Workings!E134 | F35: =Workings!F134 | G35: =Workings!G134 | H35: =Workings!H134 | I35: =Workings!I134 | J35: =Workings!J134 | ... N35: =Workings!N134
A36: TOTAL EQUITY | C36: =SUM(C34:C35) | D36: =SUM(D34:D35) | E36: =SUM(E34:E35) | F36: =SUM(F34:F35) | G36: =SUM(G34:G35) | H36: =SUM(H34:H35) | I36: =SUM(I34:I35) | J36: =SUM(J34:J35) | ... N36: =SUM(N34:N35)
A38: TOTAL LIABILITIES + EQUITY | C38: =C26+C36 | D38: =D26+D36 | E38: =E26+E36 | F38: =F26+F36 | G38: =G26+G36 | H38: =H26+H36 | I38: =I26+I36 | J38: =J26+J36 | ... N38: =N26+N36
A40: BALANCE CHECK (should be 0) | C40: =C22-C38 | D40: =D22-D38 | E40: =E22-E38 | F40: =F22-F38 | G40: =G22-G38 | H40: =H22-H38 | I40: =I22-I38 | J40: =J22-J38 | ... N40: =N22-N38

Sheet Cash Flow Statement
A1: CASH FLOW STATEMENT (INDIRECT METHOD)
A3: Period | C3: =Inputs!C3 | D3: =Inputs!D3 | E3: =Inputs!E3 | F3: =Inputs!F3 | G3: =Inputs!G3 | H3: =Inputs!H3 | I3: =Inputs!I3 | J3: =Inputs!J3 | ... N3: =Inputs!N3
A5: CASH FROM OPERATING ACTIVITIES
A6: Net Income | C6: ='Income Statement'!C20 | D6: ='Income Statement'!D20 | E6: ='Income Statement'!E20 | F6: ='Income Statement'!F20 | G6: ='Income Statement'!G20 | H6: ='Income Statement'!H20 | I6: ='Income Statement'!I20 | J6: ='Income Statement'!J20 | ... N6: ='Income Statement'!N20
A7: Adjustments:
A8: Depreciation | C8: =Workings!C112 | D8: =Workings!D112 | E8: =Workings!E112 | F8: =Workings!F112 | G8: =Workings!G112 | H8: =Workings!H112 | I8: =Workings!I112 | J8: =Workings!J112 | ... N8: =Workings!N112
A9: Changes in Working Capital:
A10: (Increase)/Decrease in AR | C10: =Inputs!$C$60-'Balance Sheet'!C8 | D10: ='Balance Sheet'!C8-'Balance Sheet'!D8 | E10: ='Balance Sheet'!D8-'Balance Sheet'!E8 | F10: ='Balance Sheet'!E8-'Balance Sheet'!F8 | G10: ='Balance Sheet'!F8-'Balance Sheet'!G8 | H10: ='Balance Sheet'!G8-'Balance Sheet'!H8 | I10: ='Balance Sheet'!H8-'Balance Sheet'!I8 | J10: ='Balance Sheet'!I8-'Balance Sheet'!J8 | K10: ='Balance Sheet'!J8-'Balance Sheet'!K8 | ... N10: ='Balance Sheet'!M8-'Balance Sheet'!N8
A11: (Increase)/Decrease in Inventory | C11: =Inputs!$C$61-'Balance Sheet'!C9 | D11: ='Balance Sheet'!C9-'Balance Sheet'!D9 | E11: ='Balance Sheet'!D9-'Balance Sheet'!E9 | F11: ='Balance Sheet'!E9-'Balance Sheet'!F9 | G11: ='Balance Sheet'!F9-'Balance Sheet'!G9 | H11: ='Balance Sheet'!G9-'Balance Sheet'!H9 | I11: ='Balance Sheet'!H9-'Balance Sheet'!I9 | J11: ='Balance Sheet'!I9-'Balance Sheet'!J9 | K11: ='Balance Sheet'!J9-'Balance Sheet'!K9 | ... N11: ='Balance Sheet'!M9-'Balance Sheet'!N9
A12: (Increase)/Decrease in Prepayments | C12: =Inputs!$C$62-'Balance Sheet'!C10 | D12: ='Balance Sheet'!C10-'Balance Sheet'!D10 | E12: ='Balance Sheet'!D10-'Balance Sheet'!E10 | F12: ='Balance Sheet'!E10-'Balance Sheet'!F10 | G12: ='Balance Sheet'!F10-'Balance Sheet'!G10 | H12: ='Balance Sheet'!G10-'Balance Sheet'!H10 | I12: ='Balance Sheet'!H10-'Balance Sheet'!I10 | J12: ='Balance Sheet'!I10-'Balance Sheet'!J10 | K12: ='Balance Sheet'!J10-'Balance Sheet'!K10 | ... N12: ='Balance Sheet'!M10-'Balance Sheet'!N10
A13: Increase/(Decrease) in AP | C13: ='Balance Sheet'!C24-Inputs!$C$65 | D13: ='Balance Sheet'!D24-'Balance Sheet'!C24 | E13: ='Balance Sheet'!E24-'Balance Sheet'!D24 | F13: ='Balance Sheet'!F24-'Balance Sheet'!E24 | G13: ='Balance Sheet'!G24-'Balance Sheet'!F24 | H13: ='Balance Sheet'!H24-'Balance Sheet'!G24 | I13: ='Balance Sheet'!I24-'Balance Sheet'!H24 | J13: ='Balance Sheet'!J24-'Balance Sheet'!I24 | K13: ='Balance Sheet'!K24-'Balance Sheet'!J24 | ... N13: ='Balance Sheet'!N24-'Balance Sheet'!M24
A14: Increase/(Decrease) in Accrued Exp | C14: ='Balance Sheet'!C25-Inputs!$C$66 | D14: ='Balance Sheet'!D25-'Balance Sheet'!C25 | E14: ='Balance Sheet'!E25-'Balance Sheet'!D25 | F14: ='Balance Sheet'!F25-'Balance Sheet'!E25 | G14: ='Balance Sheet'!G25-'Balance Sheet'!F25 | H14: ='Balance Sheet'!H25-'Balance Sheet'!G25 | I14: ='Balance Sheet'!I25-'Balance Sheet'!H25 | J14: ='Balance Sheet'!J25-'Balance Sheet'!I25 | K14: ='Balance Sheet'!K25-'Balance Sheet'!J25 | ... N14: ='Balance Sheet'!N25-'Balance Sheet'!M25
A15: Increase/(Decrease) in Deferred Rev | C15: ='Balance Sheet'!C26-Inputs!$C$67 | D15: ='Balance Sheet'!D26-'Balance Sheet'!C26 | E15: ='Balance Sheet'!E26-'Balance Sheet'!D26 | F15: ='Balance Sheet'!F26-'Balance Sheet'!E26 | G15: ='Balance Sheet'!G26-'Balance Sheet'!F26 | H15: ='Balance Sheet'!H26-'Balance Sheet'!G26 | I15: ='Balance Sheet'!I26-'Balance Sheet'!H26 | J15: ='Balance Sheet'!J26-'Balance Sheet'!I26 | K15: ='Balance Sheet'!K26-'Balance Sheet'!J26 | ... N15: ='Balance Sheet'!N26-'Balance Sheet'!M26
A16: Net Cash from Operating Activities | C16: =SUM(C5:C15) | D16: =SUM(D5:D15) | E16: =SUM(E5:E15) | F16: =SUM(F5:F15) | G16: =SUM(G5:G15) | H16: =SUM(H5:H15) | I16: =SUM(I5:I15) | J16: =SUM(J5:J15) | ... N16: =SUM(N5:N15)
A18: CASH FROM INVESTING ACTIVITIES
A19: Capital Expenditure | C19: =-Inputs!C$44 | D19: =-Inputs!D$44 | E19: =-Inputs!E$44 | F19: =-Inputs!F$44 | G19: =-Inputs!G$44 | H19: =-Inputs!H$44 | I19: =-Inputs!I$44 | J19: =-Inputs!J$44 | ... N19: =-Inputs!N$44
A20: Proceeds from Asset Disposals | C20: 0 | D20: 0 | E20: 0 | F20: 0 | G20: 0 | H20: 0 | I20: 0 | J20: 0 | K20: 0 | L20: 0 | M20: 0 | N20: 0
A21: Net Cash from Investing Activities | C21: =SUM(C19:C20) | D21: =SUM(D19:D20) | E21: =SUM(E19:E20) | F21: =SUM(F19:F20) | G21: =SUM(G19:G20) | H21: =SUM(H19:H20) | I21: =SUM(I19:I20) | J21: =SUM(J19:J20) | ... N21: =SUM(N19:N20)
A23: CASH FROM FINANCING ACTIVITIES
A24: New Borrowing | C24: =Inputs!C$52 | D24: =Inputs!D$52 | E24: =Inputs!E$52 | F24: =Inputs!F$52 | G24: =Inputs!G$52 | H24: =Inputs!H$52 | I24: =Inputs!I$52 | J24: =Inputs!J$52 | ... N24: =Inputs!N$52
A25: Debt Repayment | C25: =-Inputs!C$53 | D25: =-Inputs!D$53 | E25: =-Inputs!E$53 | F25: =-Inputs!F$53 | G25: =-Inputs!G$53 | H25: =-Inputs!H$53 | I25: =-Inputs!I$53 | J25: =-Inputs!J$53 | ... N25: =-Inputs!N$53
A26: Interest Paid | C26: =-Workings!C118 | D26: =-Workings!D118 | E26: =-Workings!E118 | F26: =-Workings!F118 | G26: =-Workings!G118 | H26: =-Workings!H118 | I26: =-Workings!I118 | J26: =-Workings!J118 | ... N26: =-Workings!N118
A27: Share Capital Raised | C27: =Inputs!C$57 | D27: =Inputs!D$57 | E27: =Inputs!E$57 | F27: =Inputs!F$57 | G27: =Inputs!G$57 | H27: =Inputs!H$57 | I27: =Inputs!I$57 | J27: =Inputs!J$57 | ... N27: =Inputs!N$57
A28: Dividends Paid | C28: =-Inputs!C$58 | D28: =-Inputs!D$58 | E28: =-Inputs!E$58 | F28: =-Inputs!F$58 | G28: =-Inputs!G$58 | H28: =-Inputs!H$58 | I28: =-Inputs!I$58 | J28: =-Inputs!J$58 | ... N28: =-Inputs!N$58
A29: Net Cash from Financing Activities | C29: =SUM(C24:C28) | D29: =SUM(D24:D28) | E29: =SUM(E24:E28) | F29: =SUM(F24:F28) | G29: =SUM(G24:G28) | H29: =SUM(H24:H28) | I29: =SUM(I24:I28) | J29: =SUM(J24:J28) | ... N29: =SUM(N24:N28)
A31: Net Increase/(Decrease) in Cash | C31: =C15+C22+C29 | D31: =D15+D22+D29 | E31: =E15+E22+E29 | F31: =F15+F22+F29 | G31: =G15+G22+G29 | H31: =H15+H22+H29 | I31: =I15+I22+I29 | J31: =J15+J22+J29 | ... N31: =N15+N22+N29
A33: Opening Cash Balance | C33: =Inputs!$C$59 | D33: =C34 | E33: =D34 | F33: =E34 | G33: =F34 | H33: =G34 | I33: =H34 | J33: =I34 | K33: =J34 | ... N33: =M34
A34: Closing Cash Balance | C34: =C31+C33 | D34: =D31+D33 | E34: =E31+E33 | F34: =F31+F33 | G34: =G31+G33 | H34: =H31+H33 | I34: =I31+I33 | J34: =J31+J33 | ... N34: =N31+N33
A36: CASH CHECK (should be 0) | C36: =C35-'Balance Sheet'!C7 | D36: =D35-'Balance Sheet'!D7 | E36: =E35-'Balance Sheet'!E7 | F36: =F35-'Balance Sheet'!F7 | G36: =G35-'Balance Sheet'!G7 | H36: =H35-'Balance Sheet'!H7 | I36: =I35-'Balance Sheet'!I7 | J36: =J35-'Balance Sheet'!J7 | ... N36: =N35-'Balance Sheet'!N7
