Workbook

Sheet Cover
A1: BEER BREWERY FINANCIAL MODEL
A2: Australia & New Zealand Operations
A4: Model Version: | B4: 1.0
A5: Date Created: | B5: 16-Nov-2025
A6: Currency: | B6: AUD
A7: Projection Period: | B7: 10 years (120 months)
A10: NAVIGATION
A11: Control & Inputs | B11: → | C11: =HYPERLINK("#'Control'!A1","Go to Control")
A12: Assumptions (Global) | B12: → | C12: =HYPERLINK("#'Assumptions_Global'!A1","Go to Assumptions_Global")
A13: Product Matrix | B13: → | C13: =HYPERLINK("#'Product_Matrix'!A1","Go to Product_Matrix")
A14: Volume Assumptions | B14: → | C14: =HYPERLINK("#'Volume_Assumptions'!A1","Go to Volume_Assumptions")
A15: Pricing & Revenue | B15: → | C15: =HYPERLINK("#'Pricing_Revenue'!A1","Go to Pricing_Revenue")
A16: Production & Capacity | B16: → | C16: =HYPERLINK("#'Production_Capacity'!A1","Go to Production_Capacity")
A17: COGS | B17: → | C17: =HYPERLINK("#'COGS_Buildup'!A1","Go to COGS_Buildup")
A18: Logistics | B18: → | C18: =HYPERLINK("#'Logistics_Distribution'!A1","Go to Logistics_Distribution")
A19: SG&A | B19: → | C19: =HYPERLINK("#'SG&A'!A1","Go to SG&A")
A20: Capex | B20: → | C20: =HYPERLINK("#'Capex_Schedule'!A1","Go to Capex_Schedule")
A21: Working Capital | B21: → | C21: =HYPERLINK("#'Working_Capital'!A1","Go to Working_Capital")
A22: Debt | B22: → | C22: =HYPERLINK("#'Debt_Schedule'!A1","Go to Debt_Schedule")
A23: Equity | B23: → | C23: =HYPERLINK("#'Equity'!A1","Go to Equity")
A24: P&L | B24: → | C24: =HYPERLINK("#'P&L'!A1","Go to P&L")
A25: Cash Flow | B25: → | C25: =HYPERLINK("#'CashFlow'!A1","Go to CashFlow")
A26: Balance Sheet | B26: → | C26: =HYPERLINK("#'BalanceSheet'!A1","Go to BalanceSheet")
A27: KPI Dashboard | B27: → | C27: =HYPERLINK("#'KPI_Dashboard'!A1","Go to KPI_Dashboard")
A28: Checks & Errors | B28: → | C28: =HYPERLINK("#'Checks_Errors'!A1","Go to Checks_Errors")
A31: USER INSTRUCTIONS
A32: 1. Start with CONTROL sheet - select scenario (Base/Upside/Downside)
A33: 2. Review all BLUE cells (inputs) in assumption sheets
A34: 3. All other cells are calculated - do not edit
A35: 4. Enable iterative calculation: File → Options → Formulas
A36: 5. Check Checks_Errors sheet for model integrity
A37: 6. Review outputs in P&L, CashFlow, BalanceSheet, KPIs

Sheet Control
A1: CONTROL PANEL
A3: Model Timeline
A4: Model start date | B4: 45658 | C4: ← INPUT
A5: Projection period (months) | B5: 120
A6: Model end date | B6: =EDATE(B4,B5-1) | C6: =DATE formula
A8: Scenario Selection
A9: Active scenario | B9: Base | C9: ← DROPDOWN
A10: Scenario index | B10: =MATCH(B9,{"Base";"Upside";"Downside"},0) | C10: Returns 1/2/3
A12: Model Settings
A13: Enable Excel iterations? | B13: YES | C13: Manual check | D13: File→Options→Formulas
A14: Max iterations | B14: 100
A15: Max change | B15: 0.001

Sheet Assumptions_Global
A1: GLOBAL ASSUMPTIONS
A3: Inflation & Escalation
A4: Assumption | B4: Base | C4: Upside | D4: Downside | E4: Active
A5: CPI (general inflation) % p.a. | B5: 0.025 | C5: 0.03 | D5: 0.02 | E5: =INDEX(B5:D5,1,Control!$B$10)
A6: Wage inflation % p.a. | B6: 0.03 | C6: 0.035 | D6: 0.025 | E6: =INDEX(B6:D6,1,Control!$B$10)
A7: Materials cost inflation % p.a. | B7: 0.025 | C7: 0.035 | D7: 0.02 | E7: =INDEX(B7:D7,1,Control!$B$10)
A8: Packaging cost inflation % p.a. | B8: 0.03 | C8: 0.04 | D8: 0.025 | E8: =INDEX(B8:D8,1,Control!$B$10)
A9: Utilities inflation % p.a. | B9: 0.04 | C9: 0.05 | D9: 0.03 | E9: =INDEX(B9:D9,1,Control!$B$10)
A11: Tax & Regulatory
A12: Corporate tax rate % | B12: 0.3 | C12: 0.3 | D12: 0.3 | E12: =INDEX(B12:D12,1,Control!$B$10)
A13: Excise duty ($/LAL) | B13: 58.26 | C13: 58.26 | D13: 58.26 | E13: =INDEX(B13:D13,1,Control!$B$10)
A14: Excise shock (Year 3+) | B14: 0 | C14: 0 | D14: 0.1 | E14: =INDEX(B14:D14,1,Control!$B$10)
A15: VAT/GST rate % | B15: 0.1 | C15: 0.1 | D15: 0.1 | E15: =INDEX(B15:D15,1,Control!$B$10)
A17: Discount Rate (for NPV)
A18: WACC / Discount rate % | B18: 0.12 | C18: 0.11 | D18: 0.13 | E18: =INDEX(B18:D18,1,Control!$B$10)

Sheet Product_Matrix
A1: PRODUCT MATRIX
A3: Brand List
A4: Brand ID | B4: Brand Name | C4: Brand Type | D4: ABV % | E4: Recipe Type
A5: 1 | B5: SkyBrew | C5: Lager | D5: 0.045 | E5: Core
A6: 2 | B6: AllDark | C6: Stout | D6: 0.058 | E6: Craft
A7: 3 | B7: GoldCoast | C7: Pale Ale | D7: 0.052 | E7: Craft
A8: 4 | B8: CityLight | C8: Light Lager | D8: 0.035 | E8: Core
A9: 5 | B9: HarborIPA | C9: IPA | D9: 0.062 | E9: Premium
A11: Pack Type List
A12: Pack ID | B12: Pack Type | C12: HL per unit | D12: Packaging | E12: Returnable?
A13: 1 | B13: Bottles | C13: 0.00033 | D13: Glass 330ml | E13: No
A14: 2 | B14: Cans | C14: 0.00037 | D14: Aluminum 375ml | E14: No
A15: 3 | B15: Kegs | C15: 0.5 | D15: Stainless 50L | E15: Yes
A17: Channel List
A18: Channel ID | B18: Channel Name | C18: Customer Type
A19: 1 | B19: OnTrade | C19: Bars, Restaurants, Pubs
A20: 2 | B20: OffTrade | C20: Retail, Supermarkets, Bottle shops

Sheet Volume_Assumptions
A1: VOLUME ASSUMPTIONS
A3: Period | F3: 1 | G3: 2 | H3: 3 | I3: 4 | J3: 5 | K3: 6 | L3: 7 | M3: 8 | N3: 9 | O3: 10 | P3: 11 | Q3: 12 | R3: 13 | S3: 14 | T3: 15 | U3: 16 | V3: 17 | W3: 18 | X3: 19 | Y3: 20 | Z3: 21 | AA3: 22 | AB3: 23 | AC3: 24 | AD3: 25 | AE3: 26 | AF3: 27 | AG3: 28 | AH3: 29 | AI3: 30 | AJ3: 31 | AK3: 32 | AL3: 33 | AM3: 34 | AN3: 35 | AO3: 36 | AP3: 37 | AQ3: 38 | AR3: 39 | AS3: 40 | AT3: 41 | AU3: 42 | AV3: 43 | AW3: 44 | AX3: 45 | AY3: 46 | AZ3: 47 | BA3: 48 | BB3: 49 | BC3: 50 | BD3: 51 | BE3: 52 | BF3: 53 | BG3: 54 | BH3: 55 | BI3: 56 | BJ3: 57 | BK3: 58 | BL3: 59 | BM3: 60 | BN3: 61 | BO3: 62 | BP3: 63 | BQ3: 64 | BR3: 65 | BS3: 66 | BT3: 67 | BU3: 68 | BV3: 69 | BW3: 70 | BX3: 71 | BY3: 72 | BZ3: 73 | CA3: 74 | CB3: 75 | CC3: 76 | CD3: 77 | CE3: 78 | CF3: 79 | CG3: 80 | CH3: 81 | CI3: 82 | CJ3: 83 | CK3: 84 | CL3: 85 | CM3: 86 | CN3: 87 | CO3: 88 | CP3: 89 | CQ3: 90 | CR3: 91 | CS3: 92 | CT3: 93 | CU3: 94 | CV3: 95 | CW3: 96 | CX3: 97 | CY3: 98 | CZ3: 99 | DA3: 100 | DB3: 101 | DC3: 102 | DD3: 103 | DE3: 104 | DF3: 105 | DG3: 106 | DH3: 107 | DI3: 108 | DJ3: 109 | DK3: 110 | DL3: 111 | DM3: 112 | DN3: 113 | DO3: 114 | DP3: 115 | DQ3: 116 | DR3: 117 | DS3: 118 | DT3: 119 | DU3: 120
A4: Date | F4: =EDATE(Control!$B$4,0) | G4: =EDATE(Control!$B$4,1) | H4: =EDATE(Control!$B$4,2) | I4: =EDATE(Control!$B$4,3) | J4: =EDATE(Control!$B$4,4) | K4: =EDATE(Control!$B$4,5) | L4: =EDATE(Control!$B$4,6) | M4: =EDATE(Control!$B$4,7) | N4: =EDATE(Control!$B$4,8) | O4: =EDATE(Control!$B$4,9) | P4: =EDATE(Control!$B$4,10) | Q4: =EDATE(Control!$B$4,11) | R4: =EDATE(Control!$B$4,12) | S4: =EDATE(Control!$B$4,13) | T4: =EDATE(Control!$B$4,14) | U4: =EDATE(Control!$B$4,15) | V4: =EDATE(Control!$B$4,16) | W4: =EDATE(Control!$B$4,17) | X4: =EDATE(Control!$B$4,18) | Y4: =EDATE(Control!$B$4,19) | Z4: =EDATE(Control!$B$4,20) | AA4: =EDATE(Control!$B$4,21) | AB4: =EDATE(Control!$B$4,22) | AC4: =EDATE(Control!$B$4,23) | AD4: =EDATE(Control!$B$4,24) | AE4: =EDATE(Control!$B$4,25) | AF4: =EDATE(Control!$B$4,26) | AG4: =EDATE(Control!$B$4,27) | AH4: =EDATE(Control!$B$4,28) | AI4: =EDATE(Control!$B$4,29) | AJ4: =EDATE(Control!$B$4,30) | AK4: =EDATE(Control!$B$4,31) | AL4: =EDATE(Control!$B$4,32) | AM4: =EDATE(Control!$B$4,33) | AN4: =EDATE(Control!$B$4,34) | AO4: =EDATE(Control!$B$4,35) | AP4: =EDATE(Control!$B$4,36) | AQ4: =EDATE(Control!$B$4,37) | AR4: =EDATE(Control!$B$4,38) | AS4: =EDATE(Control!$B$4,39) | AT4: =EDATE(Control!$B$4,40) | AU4: =EDATE(Control!$B$4,41) | AV4: =EDATE(Control!$B$4,42) | AW4: =EDATE(Control!$B$4,43) | AX4: =EDATE(Control!$B$4,44) | AY4: =EDATE(Control!$B$4,45) | AZ4: =EDATE(Control!$B$4,46) | BA4: =EDATE(Control!$B$4,47) | BB4: =EDATE(Control!$B$4,48) | BC4: =EDATE(Control!$B$4,49) | BD4: =EDATE(Control!$B$4,50) | BE4: =EDATE(Control!$B$4,51) | BF4: =EDATE(Control!$B$4,52) | BG4: =EDATE(Control!$B$4,53) | BH4: =EDATE(Control!$B$4,54) | BI4: =EDATE(Control!$B$4,55) | BJ4: =EDATE(Control!$B$4,56) | BK4: =EDATE(Control!$B$4,57) | BL4: =EDATE(Control!$B$4,58) | BM4: =EDATE(Control!$B$4,59) | BN4: =EDATE(Control!$B$4,60) | BO4: =EDATE(Control!$B$4,61) | BP4: =EDATE(Control!$B$4,62) | BQ4: =EDATE(Control!$B$4,63) | BR4: =EDATE(Control!$B$4,64) | BS4: =EDATE(Control!$B$4,65) | BT4: =EDATE(Control!$B$4,66) | BU4: =EDATE(Control!$B$4,67) | BV4: =EDATE(Control!$B$4,68) | BW4: =EDATE(Control!$B$4,69) | BX4: =EDATE(Control!$B$4,70) | BY4: =EDATE(Control!$B$4,71) | BZ4: =EDATE(Control!$B$4,72) | CA4: =EDATE(Control!$B$4,73) | CB4: =EDATE(Control!$B$4,74) | CC4: =EDATE(Control!$B$4,75) | CD4: =EDATE(Control!$B$4,76) | CE4: =EDATE(Control!$B$4,77) | CF4: =EDATE(Control!$B$4,78) | CG4: =EDATE(Control!$B$4,79) | CH4: =EDATE(Control!$B$4,80) | CI4: =EDATE(Control!$B$4,81) | CJ4: =EDATE(Control!$B$4,82) | CK4: =EDATE(Control!$B$4,83) | CL4: =EDATE(Control!$B$4,84) | CM4: =EDATE(Control!$B$4,85) | CN4: =EDATE(Control!$B$4,86) | CO4: =EDATE(Control!$B$4,87) | CP4: =EDATE(Control!$B$4,88) | CQ4: =EDATE(Control!$B$4,89) | CR4: =EDATE(Control!$B$4,90) | CS4: =EDATE(Control!$B$4,91) | CT4: =EDATE(Control!$B$4,92) | CU4: =EDATE(Control!$B$4,93) | CV4: =EDATE(Control!$B$4,94) | CW4: =EDATE(Control!$B$4,95) | CX4: =EDATE(Control!$B$4,96) | CY4: =EDATE(Control!$B$4,97) | CZ4: =EDATE(Control!$B$4,98) | DA4: =EDATE(Control!$B$4,99) | DB4: =EDATE(Control!$B$4,100) | DC4: =EDATE(Control!$B$4,101) | DD4: =EDATE(Control!$B$4,102) | DE4: =EDATE(Control!$B$4,103) | DF4: =EDATE(Control!$B$4,104) | DG4: =EDATE(Control!$B$4,105) | DH4: =EDATE(Control!$B$4,106) | DI4: =EDATE(Control!$B$4,107) | DJ4: =EDATE(Control!$B$4,108) | DK4: =EDATE(Control!$B$4,109) | DL4: =EDATE(Control!$B$4,110) | DM4: =EDATE(Control!$B$4,111) | DN4: =EDATE(Control!$B$4,112) | DO4: =EDATE(Control!$B$4,113) | DP4: =EDATE(Control!$B$4,114) | DQ4: =EDATE(Control!$B$4,115) | DR4: =EDATE(Control!$B$4,116) | DS4: =EDATE(Control!$B$4,117) | DT4: =EDATE(Control!$B$4,118) | DU4: =EDATE(Control!$B$4,119)
A5: Year | F5: =(1-1)/12 | G5: =(2-1)/12 | H5: =(3-1)/12 | I5: =(4-1)/12 | J5: =(5-1)/12 | K5: =(6-1)/12 | L5: =(7-1)/12 | M5: =(8-1)/12 | N5: =(9-1)/12 | O5: =(10-1)/12 | P5: =(11-1)/12 | Q5: =(12-1)/12 | R5: =(13-1)/12 | S5: =(14-1)/12 | T5: =(15-1)/12 | U5: =(16-1)/12 | V5: =(17-1)/12 | W5: =(18-1)/12 | X5: =(19-1)/12 | Y5: =(20-1)/12 | Z5: =(21-1)/12 | AA5: =(22-1)/12 | AB5: =(23-1)/12 | AC5: =(24-1)/12 | AD5: =(25-1)/12 | AE5: =(26-1)/12 | AF5: =(27-1)/12 | AG5: =(28-1)/12 | AH5: =(29-1)/12 | AI5: =(30-1)/12 | AJ5: =(31-1)/12 | AK5: =(32-1)/12 | AL5: =(33-1)/12 | AM5: =(34-1)/12 | AN5: =(35-1)/12 | AO5: =(36-1)/12 | AP5: =(37-1)/12 | AQ5: =(38-1)/12 | AR5: =(39-1)/12 | AS5: =(40-1)/12 | AT5: =(41-1)/12 | AU5: =(42-1)/12 | AV5: =(43-1)/12 | AW5: =(44-1)/12 | AX5: =(45-1)/12 | AY5: =(46-1)/12 | AZ5: =(47-1)/12 | BA5: =(48-1)/12 | BB5: =(49-1)/12 | BC5: =(50-1)/12 | BD5: =(51-1)/12 | BE5: =(52-1)/12 | BF5: =(53-1)/12 | BG5: =(54-1)/12 | BH5: =(55-1)/12 | BI5: =(56-1)/12 | BJ5: =(57-1)/12 | BK5: =(58-1)/12 | BL5: =(59-1)/12 | BM5: =(60-1)/12 | BN5: =(61-1)/12 | BO5: =(62-1)/12 | BP5: =(63-1)/12 | BQ5: =(64-1)/12 | BR5: =(65-1)/12 | BS5: =(66-1)/12 | BT5: =(67-1)/12 | BU5: =(68-1)/12 | BV5: =(69-1)/12 | BW5: =(70-1)/12 | BX5: =(71-1)/12 | BY5: =(72-1)/12 | BZ5: =(73-1)/12 | CA5: =(74-1)/12 | CB5: =(75-1)/12 | CC5: =(76-1)/12 | CD5: =(77-1)/12 | CE5: =(78-1)/12 | CF5: =(79-1)/12 | CG5: =(80-1)/12 | CH5: =(81-1)/12 | CI5: =(82-1)/12 | CJ5: =(83-1)/12 | CK5: =(84-1)/12 | CL5: =(85-1)/12 | CM5: =(86-1)/12 | CN5: =(87-1)/12 | CO5: =(88-1)/12 | CP5: =(89-1)/12 | CQ5: =(90-1)/12 | CR5: =(91-1)/12 | CS5: =(92-1)/12 | CT5: =(93-1)/12 | CU5: =(94-1)/12 | CV5: =(95-1)/12 | CW5: =(96-1)/12 | CX5: =(97-1)/12 | CY5: =(98-1)/12 | CZ5: =(99-1)/12 | DA5: =(100-1)/12 | DB5: =(101-1)/12 | DC5: =(102-1)/12 | DD5: =(103-1)/12 | DE5: =(104-1)/12 | DF5: =(105-1)/12 | DG5: =(106-1)/12 | DH5: =(107-1)/12 | DI5: =(108-1)/12 | DJ5: =(109-1)/12 | DK5: =(110-1)/12 | DL5: =(111-1)/12 | DM5: =(112-1)/12 | DN5: =(113-1)/12 | DO5: =(114-1)/12 | DP5: =(115-1)/12 | DQ5: =(116-1)/12 | DR5: =(117-1)/12 | DS5: =(118-1)/12 | DT5: =(119-1)/12 | DU5: =(120-1)/12
A6: FY | F6: =YEAR(F4) | G6: =YEAR(G4) | H6: =YEAR(H4) | I6: =YEAR(I4) | J6: =YEAR(J4) | K6: =YEAR(K4) | L6: =YEAR(L4) | M6: =YEAR(M4) | ... DU6: =YEAR(DU4)
A7: Quarter | F7: ="Q"&ROUNDUP(MONTH(F4)/3,0) | G7: ="Q"&ROUNDUP(MONTH(G4)/3,0) | H7: ="Q"&ROUNDUP(MONTH(H4)/3,0) | I7: ="Q"&ROUNDUP(MONTH(I4)/3,0) | J7: ="Q"&ROUNDUP(MONTH(J4)/3,0) | K7: ="Q"&ROUNDUP(MONTH(K4)/3,0) | L7: ="Q"&ROUNDUP(MONTH(L4)/3,0) | M7: ="Q"&ROUNDUP(MONTH(M4)/3,0) | ... DU7: ="Q"&ROUNDUP(MONTH(DU4)/3,0)
A10: Seasonality Factors
A11: Month (1-12) | B11: 1 | C11: 2 | D11: 3 | E11: 4 | F11: 5 | G11: 6 | H11: 7 | I11: 8 | J11: 9 | K11: 10 | L11: 11 | M11: 12
A12: Month name | B12: Jan | C12: Feb | D12: Mar | E12: Apr | F12: May | G12: Jun | H12: Jul | I12: Aug | J12: Sep | K12: Oct | L12: Nov | M12: Dec
A13: Seasonality factor | B13: 1.2 | C13: 1.15 | D13: 1.05 | E13: 0.95 | F13: 0.9 | G13: 0.85 | H13: 0.85 | I13: 0.88 | J13: 0.95 | K13: 1 | L13: 1.1 | M13: 1.12
A14: Check sum | B14: =SUM(B13:M13) | C14: (must = 12.00)
A18: Brand-Pack-Channel | B18: Year 1 Base (HL p.a.) | C18: Growth % Base | D18: Upside | E18: Downside
A19: SkyBrew-Bottles-OnTrade | B19: 50000 | C19: 0.03 | D19: 0.05 | E19: 0.01 | F19: =($B19/12)*(1+INDEX($C19:$E19,1,Control!$B$10))^F5*INDEX($B$13:$M$13,1,MOD(1-1,12)+1) | G19: =($B19/12)*(1+INDEX($C19:$E19,1,Control!$B$10))^G5*INDEX($B$13:$M$13,1,MOD(2-1,12)+1) | H19: =($B19/12)*(1+INDEX($C19:$E19,1,Control!$B$10))^H5*INDEX($B$13:$M$13,1,MOD(3-1,12)+1) | I19: =($B19/12)*(1+INDEX($C19:$E19,1,Control!$B$10))^I5*INDEX($B$13:$M$13,1,MOD(4-1,12)+1) | J19: =($B19/12)*(1+INDEX($C19:$E19,1,Control!$B$10))^J5*INDEX($B$13:$M$13,1,MOD(5-1,12)+1) | K19: =($B19/12)*(1+INDEX($C19:$E19,1,Control!$B$10))^K5*INDEX($B$13:$M$13,1,MOD(6-1,12)+1) | L19: =($B19/12)*(1+INDEX($C19:$E19,1,Control!$B$10))^L5*INDEX($B$13:$M$13,1,MOD(7-1,12)+1) | M19: =($B19/12)*(1+INDEX($C19:$E19,1,Control!$B$10))^M5*INDEX($B$13:$M$13,1,MOD(8-1,12)+1) | N19: =($B19/12)*(1+INDEX($C19:$E19,1,Control!$B$10))^N5*INDEX($B$13:$M$13,1,MOD(9-1,12)+1) | O19: =($B19/12)*(1+INDEX($C19:$E19,1,Control!$B$10))^O5*INDEX($B$13:$M$13,1,MOD(10-1,12)+1) | P19: =($B19/12)*(1+INDEX($C19:$E19,1,Control!$B$10))^P5*INDEX($B$13:$M$13,1,MOD(11-1,12)+1) | Q19: =($B19/12)*(1+INDEX($C19:$E19,1,Control!$B$10))^Q5*INDEX($B$13:$M$13,1,MOD(12-1,12)+1) | R19: =($B19/12)*(1+INDEX($C19:$E19,1,Control!$B$10))^R5*INDEX($B$13:$M$13,1,MOD(13-1,12)+1) | S19: =($B19/12)*(1+INDEX($C19:$E19,1,Control!$B$10))^S5*INDEX($B$13:$M$13,1,MOD(14-1,12)+1) | T19: =($B19/12)*(1+INDEX($C19:$E19,1,Control!$B$10))^T5*INDEX($B$13:$M$13,1,MOD(15-1,12)+1) | U19: =($B19/12)*(1+INDEX($C19:$E19,1,Control!$B$10))^U5*INDEX($B$13:$M$13,1,MOD(16-1,12)+1) | V19: =($B19/12)*(1+INDEX($C19:$E19,1,Control!$B$10))^V5*INDEX($B$13:$M$13,1,MOD(17-1,12)+1) | W19: =($B19/12)*(1+INDEX($C19:$E19,1,Control!$B$10))^W5*INDEX($B$13:$M$13,1,MOD(18-1,12)+1) | X19: =($B19/12)*(1+INDEX($C19:$E19,1,Control!$B$10))^X5*INDEX($B$13:$M$13,1,MOD(19-1,12)+1) | Y19: =($B19/12)*(1+INDEX($C19:$E19,1,Control!$B$10))^Y5*INDEX($B$13:$M$13,1,MOD(20-1,12)+1) | Z19: =($B19/12)*(1+INDEX($C19:$E19,1,Control!$B$10))^Z5*INDEX($B$13:$M$13,1,MOD(21-1,12)+1) | AA19: =($B19/12)*(1+INDEX($C19:$E19,1,Control!$B$10))^AA5*INDEX($B$13:$M$13,1,MOD(22-1,12)+1) | AB19: =($B19/12)*(1+INDEX($C19:$E19,1,Control!$B$10))^AB5*INDEX($B$13:$M$13,1,MOD(23-1,12)+1) | AC19: =($B19/12)*(1+INDEX($C19:$E19,1,Control!$B$10))^AC5*INDEX($B$13:$M$13,1,MOD(24-1,12)+1) | AD19: =($B19/12)*(1+INDEX($C19:$E19,1,Control!$B$10))^AD5*INDEX($B$13:$M$13,1,MOD(25-1,12)+1) | AE19: =($B19/12)*(1+INDEX($C19:$E19,1,Control!$B$10))^AE5*INDEX($B$13:$M$13,1,MOD(26-1,12)+1) | AF19: =($B19/12)*(1+INDEX($C19:$E19,1,Control!$B$10))^AF5*INDEX($B$13:$M$13,1,MOD(27-1,12)+1) | AG19: =($B19/12)*(1+INDEX($C19:$E19,1,Control!$B$10))^AG5*INDEX($B$13:$M$13,1,MOD(28-1,12)+1) | AH19: =($B19/12)*(1+INDEX($C19:$E19,1,Control!$B$10))^AH5*INDEX($B$13:$M$13,1,MOD(29-1,12)+1) | AI19: =($B19/12)*(1+INDEX($C19:$E19,1,Control!$B$10))^AI5*INDEX($B$13:$M$13,1,MOD(30-1,12)+1) | AJ19: =($B19/12)*(1+INDEX($C19:$E19,1,Control!$B$10))^AJ5*INDEX($B$13:$M$13,1,MOD(31-1,12)+1) | AK19: =($B19/12)*(1+INDEX($C19:$E19,1,Control!$B$10))^AK5*INDEX($B$13:$M$13,1,MOD(32-1,12)+1) | AL19: =($B19/12)*(1+INDEX($C19:$E19,1,Control!$B$10))^AL5*INDEX($B$13:$M$13,1,MOD(33-1,12)+1) | AM19: =($B19/12)*(1+INDEX($C19:$E19,1,Control!$B$10))^AM5*INDEX($B$13:$M$13,1,MOD(34-1,12)+1) | AN19: =($B19/12)*(1+INDEX($C19:$E19,1,Control!$B$10))^AN5*INDEX($B$13:$M$13,1,MOD(35-1,12)+1) | AO19: =($B19/12)*(1+INDEX($C19:$E19,1,Control!$B$10))^AO5*INDEX($B$13:$M$13,1,MOD(36-1,12)+1) | AP19: =($B19/12)*(1+INDEX($C19:$E19,1,Control!$B$10))^AP5*INDEX($B$13:$M$13,1,MOD(37-1,12)+1) | AQ19: =($B19/12)*(1+INDEX($C19:$E19,1,Control!$B$10))^AQ5*INDEX($B$13:$M$13,1,MOD(38-1,12)+1) | AR19: =($B19/12)*(1+INDEX($C19:$E19,1,Control!$B$10))^AR5*INDEX($B$13:$M$13,1,MOD(39-1,12)+1) | AS19: =($B19/12)*(1+INDEX($C19:$E19,1,Control!$B$10))^AS5*INDEX($B$13:$M$13,1,MOD(40-1,12)+1) | AT19: =($B19/12)*(1+INDEX($C19:$E19,1,Control!$B$10))^AT5*INDEX($B$13:$M$13,1,MOD(41-1,12)+1) | AU19: =($B19/12)*(1+INDEX($C19:$E19,1,Control!$B$10))^AU5*INDEX($B$13:$M$13,1,MOD(42-1,12)+1) | AV19: =($B19/12)*(1+INDEX($C19:$E19,1,Control!$B$10))^AV5*INDEX($B$13:$M$13,1,MOD(43-1,12)+1) | AW19: =($B19/12)*(1+INDEX($C19:$E19,1,Control!$B$10))^AW5*INDEX($B$13:$M$13,1,MOD(44-1,12)+1) | AX19: =($B19/12)*(1+INDEX($C19:$E19,1,Control!$B$10))^AX5*INDEX($B$13:$M$13,1,MOD(45-1,12)+1) | AY19: =($B19/12)*(1+INDEX($C19:$E19,1,Control!$B$10))^AY5*INDEX($B$13:$M$13,1,MOD(46-1,12)+1) | AZ19: =($B19/12)*(1+INDEX($C19:$E19,1,Control!$B$10))^AZ5*INDEX($B$13:$M$13,1,MOD(47-1,12)+1) | BA19: =($B19/12)*(1+INDEX($C19:$E19,1,Control!$B$10))^BA5*INDEX($B$13:$M$13,1,MOD(48-1,12)+1) | BB19: =($B19/12)*(1+INDEX($C19:$E19,1,Control!$B$10))^BB5*INDEX($B$13:$M$13,1,MOD(49-1,12)+1) | BC19: =($B19/12)*(1+INDEX($C19:$E19,1,Control!$B$10))^BC5*INDEX($B$13:$M$13,1,MOD(50-1,12)+1) | BD19: =($B19/12)*(1+INDEX($C19:$E19,1,Control!$B$10))^BD5*INDEX($B$13:$M$13,1,MOD(51-1,12)+1) | BE19: =($B19/12)*(1+INDEX($C19:$E19,1,Control!$B$10))^BE5*INDEX($B$13:$M$13,1,MOD(52-1,12)+1) | BF19: =($B19/12)*(1+INDEX($C19:$E19,1,Control!$B$10))^BF5*INDEX($B$13:$M$13,1,MOD(53-1,12)+1) | BG19: =($B19/12)*(1+INDEX($C19:$E19,1,Control!$B$10))^BG5*INDEX($B$13:$M$13,1,MOD(54-1,12)+1) | BH19: =($B19/12)*(1+INDEX($C19:$E19,1,Control!$B$10))^BH5*INDEX($B$13:$M$13,1,MOD(55-1,12)+1) | BI19: =($B19/12)*(1+INDEX($C19:$E19,1,Control!$B$10))^BI5*INDEX($B$13:$M$13,1,MOD(56-1,12)+1) | BJ19: =($B19/12)*(1+INDEX($C19:$E19,1,Control!$B$10))^BJ5*INDEX($B$13:$M$13,1,MOD(57-1,12)+1) | BK19: =($B19/12)*(1+INDEX($C19:$E19,1,Control!$B$10))^BK5*INDEX($B$13:$M$13,1,MOD(58-1,12)+1) | BL19: =($B19/12)*(1+INDEX($C19:$E19,1,Control!$B$10))^BL5*INDEX($B$13:$M$13,1,MOD(59-1,12)+1) | BM19: =($B19/12)*(1+INDEX($C19:$E19,1,Control!$B$10))^BM5*INDEX($B$13:$M$13,1,MOD(60-1,12)+1) | BN19: =($B19/12)*(1+INDEX($C19:$E19,1,Control!$B$10))^BN5*INDEX($B$13:$M$13,1,MOD(61-1,12)+1) | BO19: =($B19/12)*(1+INDEX($C19:$E19,1,Control!$B$10))^BO5*INDEX($B$13:$M$13,1,MOD(62-1,12)+1) | BP19: =($B19/12)*(1+INDEX($C19:$E19,1,Control!$B$10))^BP5*INDEX($B$13:$M$13,1,MOD(63-1,12)+1) | BQ19: =($B19/12)*(1+INDEX($C19:$E19,1,Control!$B$10))^BQ5*INDEX($B$13:$M$13,1,MOD(64-1,12)+1) | BR19: =($B19/12)*(1+INDEX($C19:$E19,1,Control!$B$10))^BR5*INDEX($B$13:$M$13,1,MOD(65-1,12)+1) | BS19: =($B19/12)*(1+INDEX($C19:$E19,1,Control!$B$10))^BS5*INDEX($B$13:$M$13,1,MOD(66-1,12)+1) | BT19: =($B19/12)*(1+INDEX($C19:$E19,1,Control!$B$10))^BT5*INDEX($B$13:$M$13,1,MOD(67-1,12)+1) | BU19: =($B19/12)*(1+INDEX($C19:$E19,1,Control!$B$10))^BU5*INDEX($B$13:$M$13,1,MOD(68-1,12)+1) | BV19: =($B19/12)*(1+INDEX($C19:$E19,1,Control!$B$10))^BV5*INDEX($B$13:$M$13,1,MOD(69-1,12)+1) | BW19: =($B19/12)*(1+INDEX($C19:$E19,1,Control!$B$10))^BW5*INDEX($B$13:$M$13,1,MOD(70-1,12)+1) | BX19: =($B19/12)*(1+INDEX($C19:$E19,1,Control!$B$10))^BX5*INDEX($B$13:$M$13,1,MOD(71-1,12)+1) | BY19: =($B19/12)*(1+INDEX($C19:$E19,1,Control!$B$10))^BY5*INDEX($B$13:$M$13,1,MOD(72-1,12)+1) | BZ19: =($B19/12)*(1+INDEX($C19:$E19,1,Control!$B$10))^BZ5*INDEX($B$13:$M$13,1,MOD(73-1,12)+1) | CA19: =($B19/12)*(1+INDEX($C19:$E19,1,Control!$B$10))^CA5*INDEX($B$13:$M$13,1,MOD(74-1,12)+1) | CB19: =($B19/12)*(1+INDEX($C19:$E19,1,Control!$B$10))^CB5*INDEX($B$13:$M$13,1,MOD(75-1,12)+1) | CC19: =($B19/12)*(1+INDEX($C19:$E19,1,Control!$B$10))^CC5*INDEX($B$13:$M$13,1,MOD(76-1,12)+1) | CD19: =($B19/12)*(1+INDEX($C19:$E19,1,Control!$B$10))^CD5*INDEX($B$13:$M$13,1,MOD(77-1,12)+1) | CE19: =($B19/12)*(1+INDEX($C19:$E19,1,Control!$B$10))^CE5*INDEX($B$13:$M$13,1,MOD(78-1,12)+1) | CF19: =($B19/12)*(1+INDEX($C19:$E19,1,Control!$B$10))^CF5*INDEX($B$13:$M$13,1,MOD(79-1,12)+1) | CG19: =($B19/12)*(1+INDEX($C19:$E19,1,Control!$B$10))^CG5*INDEX($B$13:$M$13,1,MOD(80-1,12)+1) | CH19: =($B19/12)*(1+INDEX($C19:$E19,1,Control!$B$10))^CH5*INDEX($B$13:$M$13,1,MOD(81-1,12)+1) | CI19: =($B19/12)*(1+INDEX($C19:$E19,1,Control!$B$10))^CI5*INDEX($B$13:$M$13,1,MOD(82-1,12)+1) | CJ19: =($B19/12)*(1+INDEX($C19:$E19,1,Control!$B$10))^CJ5*INDEX($B$13:$M$13,1,MOD(83-1,12)+1) | CK19: =($B19/12)*(1+INDEX($C19:$E19,1,Control!$B$10))^CK5*INDEX($B$13:$M$13,1,MOD(84-1,12)+1) | CL19: =($B19/12)*(1+INDEX($C19:$E19,1,Control!$B$10))^CL5*INDEX($B$13:$M$13,1,MOD(85-1,12)+1) | CM19: =($B19/12)*(1+INDEX($C19:$E19,1,Control!$B$10))^CM5*INDEX($B$13:$M$13,1,MOD(86-1,12)+1) | CN19: =($B19/12)*(1+INDEX($C19:$E19,1,Control!$B$10))^CN5*INDEX($B$13:$M$13,1,MOD(87-1,12)+1) | CO19: =($B19/12)*(1+INDEX($C19:$E19,1,Control!$B$10))^CO5*INDEX($B$13:$M$13,1,MOD(88-1,12)+1) | CP19: =($B19/12)*(1+INDEX($C19:$E19,1,Control!$B$10))^CP5*INDEX($B$13:$M$13,1,MOD(89-1,12)+1) | CQ19: =($B19/12)*(1+INDEX($C19:$E19,1,Control!$B$10))^CQ5*INDEX($B$13:$M$13,1,MOD(90-1,12)+1) | CR19: =($B19/12)*(1+INDEX($C19:$E19,1,Control!$B$10))^CR5*INDEX($B$13:$M$13,1,MOD(91-1,12)+1) | CS19: =($B19/12)*(1+INDEX($C19:$E19,1,Control!$B$10))^CS5*INDEX($B$13:$M$13,1,MOD(92-1,12)+1) | CT19: =($B19/12)*(1+INDEX($C19:$E19,1,Control!$B$10))^CT5*INDEX($B$13:$M$13,1,MOD(93-1,12)+1) | CU19: =($B19/12)*(1+INDEX($C19:$E19,1,Control!$B$10))^CU5*INDEX($B$13:$M$13,1,MOD(94-1,12)+1) | CV19: =($B19/12)*(1+INDEX($C19:$E19,1,Control!$B$10))^CV5*INDEX($B$13:$M$13,1,MOD(95-1,12)+1) | CW19: =($B19/12)*(1+INDEX($C19:$E19,1,Control!$B$10))^CW5*INDEX($B$13:$M$13,1,MOD(96-1,12)+1) | CX19: =($B19/12)*(1+INDEX($C19:$E19,1,Control!$B$10))^CX5*INDEX($B$13:$M$13,1,MOD(97-1,12)+1) | CY19: =($B19/12)*(1+INDEX($C19:$E19,1,Control!$B$10))^CY5*INDEX($B$13:$M$13,1,MOD(98-1,12)+1) | CZ19: =($B19/12)*(1+INDEX($C19:$E19,1,Control!$B$10))^CZ5*INDEX($B$13:$M$13,1,MOD(99-1,12)+1) | DA19: =($B19/12)*(1+INDEX($C19:$E19,1,Control!$B$10))^DA5*INDEX($B$13:$M$13,1,MOD(100-1,12)+1) | DB19: =($B19/12)*(1+INDEX($C19:$E19,1,Control!$B$10))^DB5*INDEX($B$13:$M$13,1,MOD(101-1,12)+1) | DC19: =($B19/12)*(1+INDEX($C19:$E19,1,Control!$B$10))^DC5*INDEX($B$13:$M$13,1,MOD(102-1,12)+1) | DD19: =($B19/12)*(1+INDEX($C19:$E19,1,Control!$B$10))^DD5*INDEX($B$13:$M$13,1,MOD(103-1,12)+1) | DE19: =($B19/12)*(1+INDEX($C19:$E19,1,Control!$B$10))^DE5*INDEX($B$13:$M$13,1,MOD(104-1,12)+1) | DF19: =($B19/12)*(1+INDEX($C19:$E19,1,Control!$B$10))^DF5*INDEX($B$13:$M$13,1,MOD(105-1,12)+1) | DG19: =($B19/12)*(1+INDEX($C19:$E19,1,Control!$B$10))^DG5*INDEX($B$13:$M$13,1,MOD(106-1,12)+1) | DH19: =($B19/12)*(1+INDEX($C19:$E19,1,Control!$B$10))^DH5*INDEX($B$13:$M$13,1,MOD(107-1,12)+1) | DI19: =($B19/12)*(1+INDEX($C19:$E19,1,Control!$B$10))^DI5*INDEX($B$13:$M$13,1,MOD(108-1,12)+1) | DJ19: =($B19/12)*(1+INDEX($C19:$E19,1,Control!$B$10))^DJ5*INDEX($B$13:$M$13,1,MOD(109-1,12)+1) | DK19: =($B19/12)*(1+INDEX($C19:$E19,1,Control!$B$10))^DK5*INDEX($B$13:$M$13,1,MOD(110-1,12)+1) | DL19: =($B19/12)*(1+INDEX($C19:$E19,1,Control!$B$10))^DL5*INDEX($B$13:$M$13,1,MOD(111-1,12)+1) | DM19: =($B19/12)*(1+INDEX($C19:$E19,1,Control!$B$10))^DM5*INDEX($B$13:$M$13,1,MOD(112-1,12)+1) | DN19: =($B19/12)*(1+INDEX($C19:$E19,1,Control!$B$10))^DN5*INDEX($B$13:$M$13,1,MOD(113-1,12)+1) | DO19: =($B19/12)*(1+INDEX($C19:$E19,1,Control!$B$10))^DO5*INDEX($B$13:$M$13,1,MOD(114-1,12)+1) | DP19: =($B19/12)*(1+INDEX($C19:$E19,1,Control!$B$10))^DP5*INDEX($B$13:$M$13,1,MOD(115-1,12)+1) | DQ19: =($B19/12)*(1+INDEX($C19:$E19,1,Control!$B$10))^DQ5*INDEX($B$13:$M$13,1,MOD(116-1,12)+1) | DR19: =($B19/12)*(1+INDEX($C19:$E19,1,Control!$B$10))^DR5*INDEX($B$13:$M$13,1,MOD(117-1,12)+1) | DS19: =($B19/12)*(1+INDEX($C19:$E19,1,Control!$B$10))^DS5*INDEX($B$13:$M$13,1,MOD(118-1,12)+1) | DT19: =($B19/12)*(1+INDEX($C19:$E19,1,Control!$B$10))^DT5*INDEX($B$13:$M$13,1,MOD(119-1,12)+1) | DU19: =($B19/12)*(1+INDEX($C19:$E19,1,Control!$B$10))^DU5*INDEX($B$13:$M$13,1,MOD(120-1,12)+1)
A20: SkyBrew-Bottles-OffTrade | B20: 80000 | C20: 0.03 | D20: 0.05 | E20: 0.01 | F20: =($B20/12)*(1+INDEX($C20:$E20,1,Control!$B$10))^F5*INDEX($B$13:$M$13,1,MOD(1-1,12)+1) | G20: =($B20/12)*(1+INDEX($C20:$E20,1,Control!$B$10))^G5*INDEX($B$13:$M$13,1,MOD(2-1,12)+1) | H20: =($B20/12)*(1+INDEX($C20:$E20,1,Control!$B$10))^H5*INDEX($B$13:$M$13,1,MOD(3-1,12)+1) | I20: =($B20/12)*(1+INDEX($C20:$E20,1,Control!$B$10))^I5*INDEX($B$13:$M$13,1,MOD(4-1,12)+1) | J20: =($B20/12)*(1+INDEX($C20:$E20,1,Control!$B$10))^J5*INDEX($B$13:$M$13,1,MOD(5-1,12)+1) | K20: =($B20/12)*(1+INDEX($C20:$E20,1,Control!$B$10))^K5*INDEX($B$13:$M$13,1,MOD(6-1,12)+1) | L20: =($B20/12)*(1+INDEX($C20:$E20,1,Control!$B$10))^L5*INDEX($B$13:$M$13,1,MOD(7-1,12)+1) | M20: =($B20/12)*(1+INDEX($C20:$E20,1,Control!$B$10))^M5*INDEX($B$13:$M$13,1,MOD(8-1,12)+1) | N20: =($B20/12)*(1+INDEX($C20:$E20,1,Control!$B$10))^N5*INDEX($B$13:$M$13,1,MOD(9-1,12)+1) | O20: =($B20/12)*(1+INDEX($C20:$E20,1,Control!$B$10))^O5*INDEX($B$13:$M$13,1,MOD(10-1,12)+1) | P20: =($B20/12)*(1+INDEX($C20:$E20,1,Control!$B$10))^P5*INDEX($B$13:$M$13,1,MOD(11-1,12)+1) | Q20: =($B20/12)*(1+INDEX($C20:$E20,1,Control!$B$10))^Q5*INDEX($B$13:$M$13,1,MOD(12-1,12)+1) | R20: =($B20/12)*(1+INDEX($C20:$E20,1,Control!$B$10))^R5*INDEX($B$13:$M$13,1,MOD(13-1,12)+1) | S20: =($B20/12)*(1+INDEX($C20:$E20,1,Control!$B$10))^S5*INDEX($B$13:$M$13,1,MOD(14-1,12)+1) | T20: =($B20/12)*(1+INDEX($C20:$E20,1,Control!$B$10))^T5*INDEX($B$13:$M$13,1,MOD(15-1,12)+1) | U20: =($B20/12)*(1+INDEX($C20:$E20,1,Control!$B$10))^U5*INDEX($B$13:$M$13,1,MOD(16-1,12)+1) | V20: =($B20/12)*(1+INDEX($C20:$E20,1,Control!$B$10))^V5*INDEX($B$13:$M$13,1,MOD(17-1,12)+1) | W20: =($B20/12)*(1+INDEX($C20:$E20,1,Control!$B$10))^W5*INDEX($B$13:$M$13,1,MOD(18-1,12)+1) | X20: =($B20/12)*(1+INDEX($C20:$E20,1,Control!$B$10))^X5*INDEX($B$13:$M$13,1,MOD(19-1,12)+1) | Y20: =($B20/12)*(1+INDEX($C20:$E20,1,Control!$B$10))^Y5*INDEX($B$13:$M$13,1,MOD(20-1,12)+1) | Z20: =($B20/12)*(1+INDEX($C20:$E20,1,Control!$B$10))^Z5*INDEX($B$13:$M$13,1,MOD(21-1,12)+1) | AA20: =($B20/12)*(1+INDEX($C20:$E20,1,Control!$B$10))^AA5*INDEX($B$13:$M$13,1,MOD(22-1,12)+1) | AB20: =($B20/12)*(1+INDEX($C20:$E20,1,Control!$B$10))^AB5*INDEX($B$13:$M$13,1,MOD(23-1,12)+1) | AC20: =($B20/12)*(1+INDEX($C20:$E20,1,Control!$B$10))^AC5*INDEX($B$13:$M$13,1,MOD(24-1,12)+1) | AD20: =($B20/12)*(1+INDEX($C20:$E20,1,Control!$B$10))^AD5*INDEX($B$13:$M$13,1,MOD(25-1,12)+1) | AE20: =($B20/12)*(1+INDEX($C20:$E20,1,Control!$B$10))^AE5*INDEX($B$13:$M$13,1,MOD(26-1,12)+1) | AF20: =($B20/12)*(1+INDEX($C20:$E20,1,Control!$B$10))^AF5*INDEX($B$13:$M$13,1,MOD(27-1,12)+1) | AG20: =($B20/12)*(1+INDEX($C20:$E20,1,Control!$B$10))^AG5*INDEX($B$13:$M$13,1,MOD(28-1,12)+1) | AH20: =($B20/12)*(1+INDEX($C20:$E20,1,Control!$B$10))^AH5*INDEX($B$13:$M$13,1,MOD(29-1,12)+1) | AI20: =($B20/12)*(1+INDEX($C20:$E20,1,Control!$B$10))^AI5*INDEX($B$13:$M$13,1,MOD(30-1,12)+1) | AJ20: =($B20/12)*(1+INDEX($C20:$E20,1,Control!$B$10))^AJ5*INDEX($B$13:$M$13,1,MOD(31-1,12)+1) | AK20: =($B20/12)*(1+INDEX($C20:$E20,1,Control!$B$10))^AK5*INDEX($B$13:$M$13,1,MOD(32-1,12)+1) | AL20: =($B20/12)*(1+INDEX($C20:$E20,1,Control!$B$10))^AL5*INDEX($B$13:$M$13,1,MOD(33-1,12)+1) | AM20: =($B20/12)*(1+INDEX($C20:$E20,1,Control!$B$10))^AM5*INDEX($B$13:$M$13,1,MOD(34-1,12)+1) | AN20: =($B20/12)*(1+INDEX($C20:$E20,1,Control!$B$10))^AN5*INDEX($B$13:$M$13,1,MOD(35-1,12)+1) | AO20: =($B20/12)*(1+INDEX($C20:$E20,1,Control!$B$10))^AO5*INDEX($B$13:$M$13,1,MOD(36-1,12)+1) | AP20: =($B20/12)*(1+INDEX($C20:$E20,1,Control!$B$10))^AP5*INDEX($B$13:$M$13,1,MOD(37-1,12)+1) | AQ20: =($B20/12)*(1+INDEX($C20:$E20,1,Control!$B$10))^AQ5*INDEX($B$13:$M$13,1,MOD(38-1,12)+1) | AR20: =($B20/12)*(1+INDEX($C20:$E20,1,Control!$B$10))^AR5*INDEX($B$13:$M$13,1,MOD(39-1,12)+1) | AS20: =($B20/12)*(1+INDEX($C20:$E20,1,Control!$B$10))^AS5*INDEX($B$13:$M$13,1,MOD(40-1,12)+1) | AT20: =($B20/12)*(1+INDEX($C20:$E20,1,Control!$B$10))^AT5*INDEX($B$13:$M$13,1,MOD(41-1,12)+1) | AU20: =($B20/12)*(1+INDEX($C20:$E20,1,Control!$B$10))^AU5*INDEX($B$13:$M$13,1,MOD(42-1,12)+1) | AV20: =($B20/12)*(1+INDEX($C20:$E20,1,Control!$B$10))^AV5*INDEX($B$13:$M$13,1,MOD(43-1,12)+1) | AW20: =($B20/12)*(1+INDEX($C20:$E20,1,Control!$B$10))^AW5*INDEX($B$13:$M$13,1,MOD(44-1,12)+1) | AX20: =($B20/12)*(1+INDEX($C20:$E20,1,Control!$B$10))^AX5*INDEX($B$13:$M$13,1,MOD(45-1,12)+1) | AY20: =($B20/12)*(1+INDEX($C20:$E20,1,Control!$B$10))^AY5*INDEX($B$13:$M$13,1,MOD(46-1,12)+1) | AZ20: =($B20/12)*(1+INDEX($C20:$E20,1,Control!$B$10))^AZ5*INDEX($B$13:$M$13,1,MOD(47-1,12)+1) | BA20: =($B20/12)*(1+INDEX($C20:$E20,1,Control!$B$10))^BA5*INDEX($B$13:$M$13,1,MOD(48-1,12)+1) | BB20: =($B20/12)*(1+INDEX($C20:$E20,1,Control!$B$10))^BB5*INDEX($B$13:$M$13,1,MOD(49-1,12)+1) | BC20: =($B20/12)*(1+INDEX($C20:$E20,1,Control!$B$10))^BC5*INDEX($B$13:$M$13,1,MOD(50-1,12)+1) | BD20: =($B20/12)*(1+INDEX($C20:$E20,1,Control!$B$10))^BD5*INDEX($B$13:$M$13,1,MOD(51-1,12)+1) | BE20: =($B20/12)*(1+INDEX($C20:$E20,1,Control!$B$10))^BE5*INDEX($B$13:$M$13,1,MOD(52-1,12)+1) | BF20: =($B20/12)*(1+INDEX($C20:$E20,1,Control!$B$10))^BF5*INDEX($B$13:$M$13,1,MOD(53-1,12)+1) | BG20: =($B20/12)*(1+INDEX($C20:$E20,1,Control!$B$10))^BG5*INDEX($B$13:$M$13,1,MOD(54-1,12)+1) | BH20: =($B20/12)*(1+INDEX($C20:$E20,1,Control!$B$10))^BH5*INDEX($B$13:$M$13,1,MOD(55-1,12)+1) | BI20: =($B20/12)*(1+INDEX($C20:$E20,1,Control!$B$10))^BI5*INDEX($B$13:$M$13,1,MOD(56-1,12)+1) | BJ20: =($B20/12)*(1+INDEX($C20:$E20,1,Control!$B$10))^BJ5*INDEX($B$13:$M$13,1,MOD(57-1,12)+1) | BK20: =($B20/12)*(1+INDEX($C20:$E20,1,Control!$B$10))^BK5*INDEX($B$13:$M$13,1,MOD(58-1,12)+1) | BL20: =($B20/12)*(1+INDEX($C20:$E20,1,Control!$B$10))^BL5*INDEX($B$13:$M$13,1,MOD(59-1,12)+1) | BM20: =($B20/12)*(1+INDEX($C20:$E20,1,Control!$B$10))^BM5*INDEX($B$13:$M$13,1,MOD(60-1,12)+1) | BN20: =($B20/12)*(1+INDEX($C20:$E20,1,Control!$B$10))^BN5*INDEX($B$13:$M$13,1,MOD(61-1,12)+1) | BO20: =($B20/12)*(1+INDEX($C20:$E20,1,Control!$B$10))^BO5*INDEX($B$13:$M$13,1,MOD(62-1,12)+1) | BP20: =($B20/12)*(1+INDEX($C20:$E20,1,Control!$B$10))^BP5*INDEX($B$13:$M$13,1,MOD(63-1,12)+1) | BQ20: =($B20/12)*(1+INDEX($C20:$E20,1,Control!$B$10))^BQ5*INDEX($B$13:$M$13,1,MOD(64-1,12)+1) | BR20: =($B20/12)*(1+INDEX($C20:$E20,1,Control!$B$10))^BR5*INDEX($B$13:$M$13,1,MOD(65-1,12)+1) | BS20: =($B20/12)*(1+INDEX($C20:$E20,1,Control!$B$10))^BS5*INDEX($B$13:$M$13,1,MOD(66-1,12)+1) | BT20: =($B20/12)*(1+INDEX($C20:$E20,1,Control!$B$10))^BT5*INDEX($B$13:$M$13,1,MOD(67-1,12)+1) | BU20: =($B20/12)*(1+INDEX($C20:$E20,1,Control!$B$10))^BU5*INDEX($B$13:$M$13,1,MOD(68-1,12)+1) | BV20: =($B20/12)*(1+INDEX($C20:$E20,1,Control!$B$10))^BV5*INDEX($B$13:$M$13,1,MOD(69-1,12)+1) | BW20: =($B20/12)*(1+INDEX($C20:$E20,1,Control!$B$10))^BW5*INDEX($B$13:$M$13,1,MOD(70-1,12)+1) | BX20: =($B20/12)*(1+INDEX($C20:$E20,1,Control!$B$10))^BX5*INDEX($B$13:$M$13,1,MOD(71-1,12)+1) | BY20: =($B20/12)*(1+INDEX($C20:$E20,1,Control!$B$10))^BY5*INDEX($B$13:$M$13,1,MOD(72-1,12)+1) | BZ20: =($B20/12)*(1+INDEX($C20:$E20,1,Control!$B$10))^BZ5*INDEX($B$13:$M$13,1,MOD(73-1,12)+1) | CA20: =($B20/12)*(1+INDEX($C20:$E20,1,Control!$B$10))^CA5*INDEX($B$13:$M$13,1,MOD(74-1,12)+1) | CB20: =($B20/12)*(1+INDEX($C20:$E20,1,Control!$B$10))^CB5*INDEX($B$13:$M$13,1,MOD(75-1,12)+1) | CC20: =($B20/12)*(1+INDEX($C20:$E20,1,Control!$B$10))^CC5*INDEX($B$13:$M$13,1,MOD(76-1,12)+1) | CD20: =($B20/12)*(1+INDEX($C20:$E20,1,Control!$B$10))^CD5*INDEX($B$13:$M$13,1,MOD(77-1,12)+1) | CE20: =($B20/12)*(1+INDEX($C20:$E20,1,Control!$B$10))^CE5*INDEX($B$13:$M$13,1,MOD(78-1,12)+1) | CF20: =($B20/12)*(1+INDEX($C20:$E20,1,Control!$B$10))^CF5*INDEX($B$13:$M$13,1,MOD(79-1,12)+1) | CG20: =($B20/12)*(1+INDEX($C20:$E20,1,Control!$B$10))^CG5*INDEX($B$13:$M$13,1,MOD(80-1,12)+1) | CH20: =($B20/12)*(1+INDEX($C20:$E20,1,Control!$B$10))^CH5*INDEX($B$13:$M$13,1,MOD(81-1,12)+1) | CI20: =($B20/12)*(1+INDEX($C20:$E20,1,Control!$B$10))^CI5*INDEX($B$13:$M$13,1,MOD(82-1,12)+1) | CJ20: =($B20/12)*(1+INDEX($C20:$E20,1,Control!$B$10))^CJ5*INDEX($B$13:$M$13,1,MOD(83-1,12)+1) | CK20: =($B20/12)*(1+INDEX($C20:$E20,1,Control!$B$10))^CK5*INDEX($B$13:$M$13,1,MOD(84-1,12)+1) | CL20: =($B20/12)*(1+INDEX($C20:$E20,1,Control!$B$10))^CL5*INDEX($B$13:$M$13,1,MOD(85-1,12)+1) | CM20: =($B20/12)*(1+INDEX($C20:$E20,1,Control!$B$10))^CM5*INDEX($B$13:$M$13,1,MOD(86-1,12)+1) | CN20: =($B20/12)*(1+INDEX($C20:$E20,1,Control!$B$10))^CN5*INDEX($B$13:$M$13,1,MOD(87-1,12)+1) | CO20: =($B20/12)*(1+INDEX($C20:$E20,1,Control!$B$10))^CO5*INDEX($B$13:$M$13,1,MOD(88-1,12)+1) | CP20: =($B20/12)*(1+INDEX($C20:$E20,1,Control!$B$10))^CP5*INDEX($B$13:$M$13,1,MOD(89-1,12)+1) | CQ20: =($B20/12)*(1+INDEX($C20:$E20,1,Control!$B$10))^CQ5*INDEX($B$13:$M$13,1,MOD(90-1,12)+1) | CR20: =($B20/12)*(1+INDEX($C20:$E20,1,Control!$B$10))^CR5*INDEX($B$13:$M$13,1,MOD(91-1,12)+1) | CS20: =($B20/12)*(1+INDEX($C20:$E20,1,Control!$B$10))^CS5*INDEX($B$13:$M$13,1,MOD(92-1,12)+1) | CT20: =($B20/12)*(1+INDEX($C20:$E20,1,Control!$B$10))^CT5*INDEX($B$13:$M$13,1,MOD(93-1,12)+1) | CU20: =($B20/12)*(1+INDEX($C20:$E20,1,Control!$B$10))^CU5*INDEX($B$13:$M$13,1,MOD(94-1,12)+1) | CV20: =($B20/12)*(1+INDEX($C20:$E20,1,Control!$B$10))^CV5*INDEX($B$13:$M$13,1,MOD(95-1,12)+1) | CW20: =($B20/12)*(1+INDEX($C20:$E20,1,Control!$B$10))^CW5*INDEX($B$13:$M$13,1,MOD(96-1,12)+1) | CX20: =($B20/12)*(1+INDEX($C20:$E20,1,Control!$B$10))^CX5*INDEX($B$13:$M$13,1,MOD(97-1,12)+1) | CY20: =($B20/12)*(1+INDEX($C20:$E20,1,Control!$B$10))^CY5*INDEX($B$13:$M$13,1,MOD(98-1,12)+1) | CZ20: =($B20/12)*(1+INDEX($C20:$E20,1,Control!$B$10))^CZ5*INDEX($B$13:$M$13,1,MOD(99-1,12)+1) | DA20: =($B20/12)*(1+INDEX($C20:$E20,1,Control!$B$10))^DA5*INDEX($B$13:$M$13,1,MOD(100-1,12)+1) | DB20: =($B20/12)*(1+INDEX($C20:$E20,1,Control!$B$10))^DB5*INDEX($B$13:$M$13,1,MOD(101-1,12)+1) | DC20: =($B20/12)*(1+INDEX($C20:$E20,1,Control!$B$10))^DC5*INDEX($B$13:$M$13,1,MOD(102-1,12)+1) | DD20: =($B20/12)*(1+INDEX($C20:$E20,1,Control!$B$10))^DD5*INDEX($B$13:$M$13,1,MOD(103-1,12)+1) | DE20: =($B20/12)*(1+INDEX($C20:$E20,1,Control!$B$10))^DE5*INDEX($B$13:$M$13,1,MOD(104-1,12)+1) | DF20: =($B20/12)*(1+INDEX($C20:$E20,1,Control!$B$10))^DF5*INDEX($B$13:$M$13,1,MOD(105-1,12)+1) | DG20: =($B20/12)*(1+INDEX($C20:$E20,1,Control!$B$10))^DG5*INDEX($B$13:$M$13,1,MOD(106-1,12)+1) | DH20: =($B20/12)*(1+INDEX($C20:$E20,1,Control!$B$10))^DH5*INDEX($B$13:$M$13,1,MOD(107-1,12)+1) | DI20: =($B20/12)*(1+INDEX($C20:$E20,1,Control!$B$10))^DI5*INDEX($B$13:$M$13,1,MOD(108-1,12)+1) | DJ20: =($B20/12)*(1+INDEX($C20:$E20,1,Control!$B$10))^DJ5*INDEX($B$13:$M$13,1,MOD(109-1,12)+1) | DK20: =($B20/12)*(1+INDEX($C20:$E20,1,Control!$B$10))^DK5*INDEX($B$13:$M$13,1,MOD(110-1,12)+1) | DL20: =($B20/12)*(1+INDEX($C20:$E20,1,Control!$B$10))^DL5*INDEX($B$13:$M$13,1,MOD(111-1,12)+1) | DM20: =($B20/12)*(1+INDEX($C20:$E20,1,Control!$B$10))^DM5*INDEX($B$13:$M$13,1,MOD(112-1,12)+1) | DN20: =($B20/12)*(1+INDEX($C20:$E20,1,Control!$B$10))^DN5*INDEX($B$13:$M$13,1,MOD(113-1,12)+1) | DO20: =($B20/12)*(1+INDEX($C20:$E20,1,Control!$B$10))^DO5*INDEX($B$13:$M$13,1,MOD(114-1,12)+1) | DP20: =($B20/12)*(1+INDEX($C20:$E20,1,Control!$B$10))^DP5*INDEX($B$13:$M$13,1,MOD(115-1,12)+1) | DQ20: =($B20/12)*(1+INDEX($C20:$E20,1,Control!$B$10))^DQ5*INDEX($B$13:$M$13,1,MOD(116-1,12)+1) | DR20: =($B20/12)*(1+INDEX($C20:$E20,1,Control!$B$10))^DR5*INDEX($B$13:$M$13,1,MOD(117-1,12)+1) | DS20: =($B20/12)*(1+INDEX($C20:$E20,1,Control!$B$10))^DS5*INDEX($B$13:$M$13,1,MOD(118-1,12)+1) | DT20: =($B20/12)*(1+INDEX($C20:$E20,1,Control!$B$10))^DT5*INDEX($B$13:$M$13,1,MOD(119-1,12)+1) | DU20: =($B20/12)*(1+INDEX($C20:$E20,1,Control!$B$10))^DU5*INDEX($B$13:$M$13,1,MOD(120-1,12)+1)
A21: SkyBrew-Cans-OnTrade | B21: 20000 | C21: 0.03 | D21: 0.05 | E21: 0.01 | F21: =($B21/12)*(1+INDEX($C21:$E21,1,Control!$B$10))^F5*INDEX($B$13:$M$13,1,MOD(1-1,12)+1) | G21: =($B21/12)*(1+INDEX($C21:$E21,1,Control!$B$10))^G5*INDEX($B$13:$M$13,1,MOD(2-1,12)+1) | H21: =($B21/12)*(1+INDEX($C21:$E21,1,Control!$B$10))^H5*INDEX($B$13:$M$13,1,MOD(3-1,12)+1) | I21: =($B21/12)*(1+INDEX($C21:$E21,1,Control!$B$10))^I5*INDEX($B$13:$M$13,1,MOD(4-1,12)+1) | J21: =($B21/12)*(1+INDEX($C21:$E21,1,Control!$B$10))^J5*INDEX($B$13:$M$13,1,MOD(5-1,12)+1) | K21: =($B21/12)*(1+INDEX($C21:$E21,1,Control!$B$10))^K5*INDEX($B$13:$M$13,1,MOD(6-1,12)+1) | L21: =($B21/12)*(1+INDEX($C21:$E21,1,Control!$B$10))^L5*INDEX($B$13:$M$13,1,MOD(7-1,12)+1) | M21: =($B21/12)*(1+INDEX($C21:$E21,1,Control!$B$10))^M5*INDEX($B$13:$M$13,1,MOD(8-1,12)+1) | N21: =($B21/12)*(1+INDEX($C21:$E21,1,Control!$B$10))^N5*INDEX($B$13:$M$13,1,MOD(9-1,12)+1) | O21: =($B21/12)*(1+INDEX($C21:$E21,1,Control!$B$10))^O5*INDEX($B$13:$M$13,1,MOD(10-1,12)+1) | P21: =($B21/12)*(1+INDEX($C21:$E21,1,Control!$B$10))^P5*INDEX($B$13:$M$13,1,MOD(11-1,12)+1) | Q21: =($B21/12)*(1+INDEX($C21:$E21,1,Control!$B$10))^Q5*INDEX($B$13:$M$13,1,MOD(12-1,12)+1) | R21: =($B21/12)*(1+INDEX($C21:$E21,1,Control!$B$10))^R5*INDEX($B$13:$M$13,1,MOD(13-1,12)+1) | S21: =($B21/12)*(1+INDEX($C21:$E21,1,Control!$B$10))^S5*INDEX($B$13:$M$13,1,MOD(14-1,12)+1) | T21: =($B21/12)*(1+INDEX($C21:$E21,1,Control!$B$10))^T5*INDEX($B$13:$M$13,1,MOD(15-1,12)+1) | U21: =($B21/12)*(1+INDEX($C21:$E21,1,Control!$B$10))^U5*INDEX($B$13:$M$13,1,MOD(16-1,12)+1) | V21: =($B21/12)*(1+INDEX($C21:$E21,1,Control!$B$10))^V5*INDEX($B$13:$M$13,1,MOD(17-1,12)+1) | W21: =($B21/12)*(1+INDEX($C21:$E21,1,Control!$B$10))^W5*INDEX($B$13:$M$13,1,MOD(18-1,12)+1) | X21: =($B21/12)*(1+INDEX($C21:$E21,1,Control!$B$10))^X5*INDEX($B$13:$M$13,1,MOD(19-1,12)+1) | Y21: =($B21/12)*(1+INDEX($C21:$E21,1,Control!$B$10))^Y5*INDEX($B$13:$M$13,1,MOD(20-1,12)+1) | Z21: =($B21/12)*(1+INDEX($C21:$E21,1,Control!$B$10))^Z5*INDEX($B$13:$M$13,1,MOD(21-1,12)+1) | AA21: =($B21/12)*(1+INDEX($C21:$E21,1,Control!$B$10))^AA5*INDEX($B$13:$M$13,1,MOD(22-1,12)+1) | AB21: =($B21/12)*(1+INDEX($C21:$E21,1,Control!$B$10))^AB5*INDEX($B$13:$M$13,1,MOD(23-1,12)+1) | AC21: =($B21/12)*(1+INDEX($C21:$E21,1,Control!$B$10))^AC5*INDEX($B$13:$M$13,1,MOD(24-1,12)+1) | AD21: =($B21/12)*(1+INDEX($C21:$E21,1,Control!$B$10))^AD5*INDEX($B$13:$M$13,1,MOD(25-1,12)+1) | AE21: =($B21/12)*(1+INDEX($C21:$E21,1,Control!$B$10))^AE5*INDEX($B$13:$M$13,1,MOD(26-1,12)+1) | AF21: =($B21/12)*(1+INDEX($C21:$E21,1,Control!$B$10))^AF5*INDEX($B$13:$M$13,1,MOD(27-1,12)+1) | AG21: =($B21/12)*(1+INDEX($C21:$E21,1,Control!$B$10))^AG5*INDEX($B$13:$M$13,1,MOD(28-1,12)+1) | AH21: =($B21/12)*(1+INDEX($C21:$E21,1,Control!$B$10))^AH5*INDEX($B$13:$M$13,1,MOD(29-1,12)+1) | AI21: =($B21/12)*(1+INDEX($C21:$E21,1,Control!$B$10))^AI5*INDEX($B$13:$M$13,1,MOD(30-1,12)+1) | AJ21: =($B21/12)*(1+INDEX($C21:$E21,1,Control!$B$10))^AJ5*INDEX($B$13:$M$13,1,MOD(31-1,12)+1) | AK21: =($B21/12)*(1+INDEX($C21:$E21,1,Control!$B$10))^AK5*INDEX($B$13:$M$13,1,MOD(32-1,12)+1) | AL21: =($B21/12)*(1+INDEX($C21:$E21,1,Control!$B$10))^AL5*INDEX($B$13:$M$13,1,MOD(33-1,12)+1) | AM21: =($B21/12)*(1+INDEX($C21:$E21,1,Control!$B$10))^AM5*INDEX($B$13:$M$13,1,MOD(34-1,12)+1) | AN21: =($B21/12)*(1+INDEX($C21:$E21,1,Control!$B$10))^AN5*INDEX($B$13:$M$13,1,MOD(35-1,12)+1) | AO21: =($B21/12)*(1+INDEX($C21:$E21,1,Control!$B$10))^AO5*INDEX($B$13:$M$13,1,MOD(36-1,12)+1) | AP21: =($B21/12)*(1+INDEX($C21:$E21,1,Control!$B$10))^AP5*INDEX($B$13:$M$13,1,MOD(37-1,12)+1) | AQ21: =($B21/12)*(1+INDEX($C21:$E21,1,Control!$B$10))^AQ5*INDEX($B$13:$M$13,1,MOD(38-1,12)+1) | AR21: =($B21/12)*(1+INDEX($C21:$E21,1,Control!$B$10))^AR5*INDEX($B$13:$M$13,1,MOD(39-1,12)+1) | AS21: =($B21/12)*(1+INDEX($C21:$E21,1,Control!$B$10))^AS5*INDEX($B$13:$M$13,1,MOD(40-1,12)+1) | AT21: =($B21/12)*(1+INDEX($C21:$E21,1,Control!$B$10))^AT5*INDEX($B$13:$M$13,1,MOD(41-1,12)+1) | AU21: =($B21/12)*(1+INDEX($C21:$E21,1,Control!$B$10))^AU5*INDEX($B$13:$M$13,1,MOD(42-1,12)+1) | AV21: =($B21/12)*(1+INDEX($C21:$E21,1,Control!$B$10))^AV5*INDEX($B$13:$M$13,1,MOD(43-1,12)+1) | AW21: =($B21/12)*(1+INDEX($C21:$E21,1,Control!$B$10))^AW5*INDEX($B$13:$M$13,1,MOD(44-1,12)+1) | AX21: =($B21/12)*(1+INDEX($C21:$E21,1,Control!$B$10))^AX5*INDEX($B$13:$M$13,1,MOD(45-1,12)+1) | AY21: =($B21/12)*(1+INDEX($C21:$E21,1,Control!$B$10))^AY5*INDEX($B$13:$M$13,1,MOD(46-1,12)+1) | AZ21: =($B21/12)*(1+INDEX($C21:$E21,1,Control!$B$10))^AZ5*INDEX($B$13:$M$13,1,MOD(47-1,12)+1) | BA21: =($B21/12)*(1+INDEX($C21:$E21,1,Control!$B$10))^BA5*INDEX($B$13:$M$13,1,MOD(48-1,12)+1) | BB21: =($B21/12)*(1+INDEX($C21:$E21,1,Control!$B$10))^BB5*INDEX($B$13:$M$13,1,MOD(49-1,12)+1) | BC21: =($B21/12)*(1+INDEX($C21:$E21,1,Control!$B$10))^BC5*INDEX($B$13:$M$13,1,MOD(50-1,12)+1) | BD21: =($B21/12)*(1+INDEX($C21:$E21,1,Control!$B$10))^BD5*INDEX($B$13:$M$13,1,MOD(51-1,12)+1) | BE21: =($B21/12)*(1+INDEX($C21:$E21,1,Control!$B$10))^BE5*INDEX($B$13:$M$13,1,MOD(52-1,12)+1) | BF21: =($B21/12)*(1+INDEX($C21:$E21,1,Control!$B$10))^BF5*INDEX($B$13:$M$13,1,MOD(53-1,12)+1) | BG21: =($B21/12)*(1+INDEX($C21:$E21,1,Control!$B$10))^BG5*INDEX($B$13:$M$13,1,MOD(54-1,12)+1) | BH21: =($B21/12)*(1+INDEX($C21:$E21,1,Control!$B$10))^BH5*INDEX($B$13:$M$13,1,MOD(55-1,12)+1) | BI21: =($B21/12)*(1+INDEX($C21:$E21,1,Control!$B$10))^BI5*INDEX($B$13:$M$13,1,MOD(56-1,12)+1) | BJ21: =($B21/12)*(1+INDEX($C21:$E21,1,Control!$B$10))^BJ5*INDEX($B$13:$M$13,1,MOD(57-1,12)+1) | BK21: =($B21/12)*(1+INDEX($C21:$E21,1,Control!$B$10))^BK5*INDEX($B$13:$M$13,1,MOD(58-1,12)+1) | BL21: =($B21/12)*(1+INDEX($C21:$E21,1,Control!$B$10))^BL5*INDEX($B$13:$M$13,1,MOD(59-1,12)+1) | BM21: =($B21/12)*(1+INDEX($C21:$E21,1,Control!$B$10))^BM5*INDEX($B$13:$M$13,1,MOD(60-1,12)+1) | BN21: =($B21/12)*(1+INDEX($C21:$E21,1,Control!$B$10))^BN5*INDEX($B$13:$M$13,1,MOD(61-1,12)+1) | BO21: =($B21/12)*(1+INDEX($C21:$E21,1,Control!$B$10))^BO5*INDEX($B$13:$M$13,1,MOD(62-1,12)+1) | BP21: =($B21/12)*(1+INDEX($C21:$E21,1,Control!$B$10))^BP5*INDEX($B$13:$M$13,1,MOD(63-1,12)+1) | BQ21: =($B21/12)*(1+INDEX($C21:$E21,1,Control!$B$10))^BQ5*INDEX($B$13:$M$13,1,MOD(64-1,12)+1) | BR21: =($B21/12)*(1+INDEX($C21:$E21,1,Control!$B$10))^BR5*INDEX($B$13:$M$13,1,MOD(65-1,12)+1) | BS21: =($B21/12)*(1+INDEX($C21:$E21,1,Control!$B$10))^BS5*INDEX($B$13:$M$13,1,MOD(66-1,12)+1) | BT21: =($B21/12)*(1+INDEX($C21:$E21,1,Control!$B$10))^BT5*INDEX($B$13:$M$13,1,MOD(67-1,12)+1) | BU21: =($B21/12)*(1+INDEX($C21:$E21,1,Control!$B$10))^BU5*INDEX($B$13:$M$13,1,MOD(68-1,12)+1) | BV21: =($B21/12)*(1+INDEX($C21:$E21,1,Control!$B$10))^BV5*INDEX($B$13:$M$13,1,MOD(69-1,12)+1) | BW21: =($B21/12)*(1+INDEX($C21:$E21,1,Control!$B$10))^BW5*INDEX($B$13:$M$13,1,MOD(70-1,12)+1) | BX21: =($B21/12)*(1+INDEX($C21:$E21,1,Control!$B$10))^BX5*INDEX($B$13:$M$13,1,MOD(71-1,12)+1) | BY21: =($B21/12)*(1+INDEX($C21:$E21,1,Control!$B$10))^BY5*INDEX($B$13:$M$13,1,MOD(72-1,12)+1) | BZ21: =($B21/12)*(1+INDEX($C21:$E21,1,Control!$B$10))^BZ5*INDEX($B$13:$M$13,1,MOD(73-1,12)+1) | CA21: =($B21/12)*(1+INDEX($C21:$E21,1,Control!$B$10))^CA5*INDEX($B$13:$M$13,1,MOD(74-1,12)+1) | CB21: =($B21/12)*(1+INDEX($C21:$E21,1,Control!$B$10))^CB5*INDEX($B$13:$M$13,1,MOD(75-1,12)+1) | CC21: =($B21/12)*(1+INDEX($C21:$E21,1,Control!$B$10))^CC5*INDEX($B$13:$M$13,1,MOD(76-1,12)+1) | CD21: =($B21/12)*(1+INDEX($C21:$E21,1,Control!$B$10))^CD5*INDEX($B$13:$M$13,1,MOD(77-1,12)+1) | CE21: =($B21/12)*(1+INDEX($C21:$E21,1,Control!$B$10))^CE5*INDEX($B$13:$M$13,1,MOD(78-1,12)+1) | CF21: =($B21/12)*(1+INDEX($C21:$E21,1,Control!$B$10))^CF5*INDEX($B$13:$M$13,1,MOD(79-1,12)+1) | CG21: =($B21/12)*(1+INDEX($C21:$E21,1,Control!$B$10))^CG5*INDEX($B$13:$M$13,1,MOD(80-1,12)+1) | CH21: =($B21/12)*(1+INDEX($C21:$E21,1,Control!$B$10))^CH5*INDEX($B$13:$M$13,1,MOD(81-1,12)+1) | CI21: =($B21/12)*(1+INDEX($C21:$E21,1,Control!$B$10))^CI5*INDEX($B$13:$M$13,1,MOD(82-1,12)+1) | CJ21: =($B21/12)*(1+INDEX($C21:$E21,1,Control!$B$10))^CJ5*INDEX($B$13:$M$13,1,MOD(83-1,12)+1) | CK21: =($B21/12)*(1+INDEX($C21:$E21,1,Control!$B$10))^CK5*INDEX($B$13:$M$13,1,MOD(84-1,12)+1) | CL21: =($B21/12)*(1+INDEX($C21:$E21,1,Control!$B$10))^CL5*INDEX($B$13:$M$13,1,MOD(85-1,12)+1) | CM21: =($B21/12)*(1+INDEX($C21:$E21,1,Control!$B$10))^CM5*INDEX($B$13:$M$13,1,MOD(86-1,12)+1) | CN21: =($B21/12)*(1+INDEX($C21:$E21,1,Control!$B$10))^CN5*INDEX($B$13:$M$13,1,MOD(87-1,12)+1) | CO21: =($B21/12)*(1+INDEX($C21:$E21,1,Control!$B$10))^CO5*INDEX($B$13:$M$13,1,MOD(88-1,12)+1) | CP21: =($B21/12)*(1+INDEX($C21:$E21,1,Control!$B$10))^CP5*INDEX($B$13:$M$13,1,MOD(89-1,12)+1) | CQ21: =($B21/12)*(1+INDEX($C21:$E21,1,Control!$B$10))^CQ5*INDEX($B$13:$M$13,1,MOD(90-1,12)+1) | CR21: =($B21/12)*(1+INDEX($C21:$E21,1,Control!$B$10))^CR5*INDEX($B$13:$M$13,1,MOD(91-1,12)+1) | CS21: =($B21/12)*(1+INDEX($C21:$E21,1,Control!$B$10))^CS5*INDEX($B$13:$M$13,1,MOD(92-1,12)+1) | CT21: =($B21/12)*(1+INDEX($C21:$E21,1,Control!$B$10))^CT5*INDEX($B$13:$M$13,1,MOD(93-1,12)+1) | CU21: =($B21/12)*(1+INDEX($C21:$E21,1,Control!$B$10))^CU5*INDEX($B$13:$M$13,1,MOD(94-1,12)+1) | CV21: =($B21/12)*(1+INDEX($C21:$E21,1,Control!$B$10))^CV5*INDEX($B$13:$M$13,1,MOD(95-1,12)+1) | CW21: =($B21/12)*(1+INDEX($C21:$E21,1,Control!$B$10))^CW5*INDEX($B$13:$M$13,1,MOD(96-1,12)+1) | CX21: =($B21/12)*(1+INDEX($C21:$E21,1,Control!$B$10))^CX5*INDEX($B$13:$M$13,1,MOD(97-1,12)+1) | CY21: =($B21/12)*(1+INDEX($C21:$E21,1,Control!$B$10))^CY5*INDEX($B$13:$M$13,1,MOD(98-1,12)+1) | CZ21: =($B21/12)*(1+INDEX($C21:$E21,1,Control!$B$10))^CZ5*INDEX($B$13:$M$13,1,MOD(99-1,12)+1) | DA21: =($B21/12)*(1+INDEX($C21:$E21,1,Control!$B$10))^DA5*INDEX($B$13:$M$13,1,MOD(100-1,12)+1) | DB21: =($B21/12)*(1+INDEX($C21:$E21,1,Control!$B$10))^DB5*INDEX($B$13:$M$13,1,MOD(101-1,12)+1) | DC21: =($B21/12)*(1+INDEX($C21:$E21,1,Control!$B$10))^DC5*INDEX($B$13:$M$13,1,MOD(102-1,12)+1) | DD21: =($B21/12)*(1+INDEX($C21:$E21,1,Control!$B$10))^DD5*INDEX($B$13:$M$13,1,MOD(103-1,12)+1) | DE21: =($B21/12)*(1+INDEX($C21:$E21,1,Control!$B$10))^DE5*INDEX($B$13:$M$13,1,MOD(104-1,12)+1) | DF21: =($B21/12)*(1+INDEX($C21:$E21,1,Control!$B$10))^DF5*INDEX($B$13:$M$13,1,MOD(105-1,12)+1) | DG21: =($B21/12)*(1+INDEX($C21:$E21,1,Control!$B$10))^DG5*INDEX($B$13:$M$13,1,MOD(106-1,12)+1) | DH21: =($B21/12)*(1+INDEX($C21:$E21,1,Control!$B$10))^DH5*INDEX($B$13:$M$13,1,MOD(107-1,12)+1) | DI21: =($B21/12)*(1+INDEX($C21:$E21,1,Control!$B$10))^DI5*INDEX($B$13:$M$13,1,MOD(108-1,12)+1) | DJ21: =($B21/12)*(1+INDEX($C21:$E21,1,Control!$B$10))^DJ5*INDEX($B$13:$M$13,1,MOD(109-1,12)+1) | DK21: =($B21/12)*(1+INDEX($C21:$E21,1,Control!$B$10))^DK5*INDEX($B$13:$M$13,1,MOD(110-1,12)+1) | DL21: =($B21/12)*(1+INDEX($C21:$E21,1,Control!$B$10))^DL5*INDEX($B$13:$M$13,1,MOD(111-1,12)+1) | DM21: =($B21/12)*(1+INDEX($C21:$E21,1,Control!$B$10))^DM5*INDEX($B$13:$M$13,1,MOD(112-1,12)+1) | DN21: =($B21/12)*(1+INDEX($C21:$E21,1,Control!$B$10))^DN5*INDEX($B$13:$M$13,1,MOD(113-1,12)+1) | DO21: =($B21/12)*(1+INDEX($C21:$E21,1,Control!$B$10))^DO5*INDEX($B$13:$M$13,1,MOD(114-1,12)+1) | DP21: =($B21/12)*(1+INDEX($C21:$E21,1,Control!$B$10))^DP5*INDEX($B$13:$M$13,1,MOD(115-1,12)+1) | DQ21: =($B21/12)*(1+INDEX($C21:$E21,1,Control!$B$10))^DQ5*INDEX($B$13:$M$13,1,MOD(116-1,12)+1) | DR21: =($B21/12)*(1+INDEX($C21:$E21,1,Control!$B$10))^DR5*INDEX($B$13:$M$13,1,MOD(117-1,12)+1) | DS21: =($B21/12)*(1+INDEX($C21:$E21,1,Control!$B$10))^DS5*INDEX($B$13:$M$13,1,MOD(118-1,12)+1) | DT21: =($B21/12)*(1+INDEX($C21:$E21,1,Control!$B$10))^DT5*INDEX($B$13:$M$13,1,MOD(119-1,12)+1) | DU21: =($B21/12)*(1+INDEX($C21:$E21,1,Control!$B$10))^DU5*INDEX($B$13:$M$13,1,MOD(120-1,12)+1)
A22: SkyBrew-Cans-OffTrade | B22: 100000 | C22: 0.03 | D22: 0.05 | E22: 0.01 | F22: =($B22/12)*(1+INDEX($C22:$E22,1,Control!$B$10))^F5*INDEX($B$13:$M$13,1,MOD(1-1,12)+1) | G22: =($B22/12)*(1+INDEX($C22:$E22,1,Control!$B$10))^G5*INDEX($B$13:$M$13,1,MOD(2-1,12)+1) | H22: =($B22/12)*(1+INDEX($C22:$E22,1,Control!$B$10))^H5*INDEX($B$13:$M$13,1,MOD(3-1,12)+1) | I22: =($B22/12)*(1+INDEX($C22:$E22,1,Control!$B$10))^I5*INDEX($B$13:$M$13,1,MOD(4-1,12)+1) | J22: =($B22/12)*(1+INDEX($C22:$E22,1,Control!$B$10))^J5*INDEX($B$13:$M$13,1,MOD(5-1,12)+1) | K22: =($B22/12)*(1+INDEX($C22:$E22,1,Control!$B$10))^K5*INDEX($B$13:$M$13,1,MOD(6-1,12)+1) | L22: =($B22/12)*(1+INDEX($C22:$E22,1,Control!$B$10))^L5*INDEX($B$13:$M$13,1,MOD(7-1,12)+1) | M22: =($B22/12)*(1+INDEX($C22:$E22,1,Control!$B$10))^M5*INDEX($B$13:$M$13,1,MOD(8-1,12)+1) | N22: =($B22/12)*(1+INDEX($C22:$E22,1,Control!$B$10))^N5*INDEX($B$13:$M$13,1,MOD(9-1,12)+1) | O22: =($B22/12)*(1+INDEX($C22:$E22,1,Control!$B$10))^O5*INDEX($B$13:$M$13,1,MOD(10-1,12)+1) | P22: =($B22/12)*(1+INDEX($C22:$E22,1,Control!$B$10))^P5*INDEX($B$13:$M$13,1,MOD(11-1,12)+1) | Q22: =($B22/12)*(1+INDEX($C22:$E22,1,Control!$B$10))^Q5*INDEX($B$13:$M$13,1,MOD(12-1,12)+1) | R22: =($B22/12)*(1+INDEX($C22:$E22,1,Control!$B$10))^R5*INDEX($B$13:$M$13,1,MOD(13-1,12)+1) | S22: =($B22/12)*(1+INDEX($C22:$E22,1,Control!$B$10))^S5*INDEX($B$13:$M$13,1,MOD(14-1,12)+1) | T22: =($B22/12)*(1+INDEX($C22:$E22,1,Control!$B$10))^T5*INDEX($B$13:$M$13,1,MOD(15-1,12)+1) | U22: =($B22/12)*(1+INDEX($C22:$E22,1,Control!$B$10))^U5*INDEX($B$13:$M$13,1,MOD(16-1,12)+1) | V22: =($B22/12)*(1+INDEX($C22:$E22,1,Control!$B$10))^V5*INDEX($B$13:$M$13,1,MOD(17-1,12)+1) | W22: =($B22/12)*(1+INDEX($C22:$E22,1,Control!$B$10))^W5*INDEX($B$13:$M$13,1,MOD(18-1,12)+1) | X22: =($B22/12)*(1+INDEX($C22:$E22,1,Control!$B$10))^X5*INDEX($B$13:$M$13,1,MOD(19-1,12)+1) | Y22: =($B22/12)*(1+INDEX($C22:$E22,1,Control!$B$10))^Y5*INDEX($B$13:$M$13,1,MOD(20-1,12)+1) | Z22: =($B22/12)*(1+INDEX($C22:$E22,1,Control!$B$10))^Z5*INDEX($B$13:$M$13,1,MOD(21-1,12)+1) | AA22: =($B22/12)*(1+INDEX($C22:$E22,1,Control!$B$10))^AA5*INDEX($B$13:$M$13,1,MOD(22-1,12)+1) | AB22: =($B22/12)*(1+INDEX($C22:$E22,1,Control!$B$10))^AB5*INDEX($B$13:$M$13,1,MOD(23-1,12)+1) | AC22: =($B22/12)*(1+INDEX($C22:$E22,1,Control!$B$10))^AC5*INDEX($B$13:$M$13,1,MOD(24-1,12)+1) | AD22: =($B22/12)*(1+INDEX($C22:$E22,1,Control!$B$10))^AD5*INDEX($B$13:$M$13,1,MOD(25-1,12)+1) | AE22: =($B22/12)*(1+INDEX($C22:$E22,1,Control!$B$10))^AE5*INDEX($B$13:$M$13,1,MOD(26-1,12)+1) | AF22: =($B22/12)*(1+INDEX($C22:$E22,1,Control!$B$10))^AF5*INDEX($B$13:$M$13,1,MOD(27-1,12)+1) | AG22: =($B22/12)*(1+INDEX($C22:$E22,1,Control!$B$10))^AG5*INDEX($B$13:$M$13,1,MOD(28-1,12)+1) | AH22: =($B22/12)*(1+INDEX($C22:$E22,1,Control!$B$10))^AH5*INDEX($B$13:$M$13,1,MOD(29-1,12)+1) | AI22: =($B22/12)*(1+INDEX($C22:$E22,1,Control!$B$10))^AI5*INDEX($B$13:$M$13,1,MOD(30-1,12)+1) | AJ22: =($B22/12)*(1+INDEX($C22:$E22,1,Control!$B$10))^AJ5*INDEX($B$13:$M$13,1,MOD(31-1,12)+1) | AK22: =($B22/12)*(1+INDEX($C22:$E22,1,Control!$B$10))^AK5*INDEX($B$13:$M$13,1,MOD(32-1,12)+1) | AL22: =($B22/12)*(1+INDEX($C22:$E22,1,Control!$B$10))^AL5*INDEX($B$13:$M$13,1,MOD(33-1,12)+1) | AM22: =($B22/12)*(1+INDEX($C22:$E22,1,Control!$B$10))^AM5*INDEX($B$13:$M$13,1,MOD(34-1,12)+1) | AN22: =($B22/12)*(1+INDEX($C22:$E22,1,Control!$B$10))^AN5*INDEX($B$13:$M$13,1,MOD(35-1,12)+1) | AO22: =($B22/12)*(1+INDEX($C22:$E22,1,Control!$B$10))^AO5*INDEX($B$13:$M$13,1,MOD(36-1,12)+1) | AP22: =($B22/12)*(1+INDEX($C22:$E22,1,Control!$B$10))^AP5*INDEX($B$13:$M$13,1,MOD(37-1,12)+1) | AQ22: =($B22/12)*(1+INDEX($C22:$E22,1,Control!$B$10))^AQ5*INDEX($B$13:$M$13,1,MOD(38-1,12)+1) | AR22: =($B22/12)*(1+INDEX($C22:$E22,1,Control!$B$10))^AR5*INDEX($B$13:$M$13,1,MOD(39-1,12)+1) | AS22: =($B22/12)*(1+INDEX($C22:$E22,1,Control!$B$10))^AS5*INDEX($B$13:$M$13,1,MOD(40-1,12)+1) | AT22: =($B22/12)*(1+INDEX($C22:$E22,1,Control!$B$10))^AT5*INDEX($B$13:$M$13,1,MOD(41-1,12)+1) | AU22: =($B22/12)*(1+INDEX($C22:$E22,1,Control!$B$10))^AU5*INDEX($B$13:$M$13,1,MOD(42-1,12)+1) | AV22: =($B22/12)*(1+INDEX($C22:$E22,1,Control!$B$10))^AV5*INDEX($B$13:$M$13,1,MOD(43-1,12)+1) | AW22: =($B22/12)*(1+INDEX($C22:$E22,1,Control!$B$10))^AW5*INDEX($B$13:$M$13,1,MOD(44-1,12)+1) | AX22: =($B22/12)*(1+INDEX($C22:$E22,1,Control!$B$10))^AX5*INDEX($B$13:$M$13,1,MOD(45-1,12)+1) | AY22: =($B22/12)*(1+INDEX($C22:$E22,1,Control!$B$10))^AY5*INDEX($B$13:$M$13,1,MOD(46-1,12)+1) | AZ22: =($B22/12)*(1+INDEX($C22:$E22,1,Control!$B$10))^AZ5*INDEX($B$13:$M$13,1,MOD(47-1,12)+1) | BA22: =($B22/12)*(1+INDEX($C22:$E22,1,Control!$B$10))^BA5*INDEX($B$13:$M$13,1,MOD(48-1,12)+1) | BB22: =($B22/12)*(1+INDEX($C22:$E22,1,Control!$B$10))^BB5*INDEX($B$13:$M$13,1,MOD(49-1,12)+1) | BC22: =($B22/12)*(1+INDEX($C22:$E22,1,Control!$B$10))^BC5*INDEX($B$13:$M$13,1,MOD(50-1,12)+1) | BD22: =($B22/12)*(1+INDEX($C22:$E22,1,Control!$B$10))^BD5*INDEX($B$13:$M$13,1,MOD(51-1,12)+1) | BE22: =($B22/12)*(1+INDEX($C22:$E22,1,Control!$B$10))^BE5*INDEX($B$13:$M$13,1,MOD(52-1,12)+1) | BF22: =($B22/12)*(1+INDEX($C22:$E22,1,Control!$B$10))^BF5*INDEX($B$13:$M$13,1,MOD(53-1,12)+1) | BG22: =($B22/12)*(1+INDEX($C22:$E22,1,Control!$B$10))^BG5*INDEX($B$13:$M$13,1,MOD(54-1,12)+1) | BH22: =($B22/12)*(1+INDEX($C22:$E22,1,Control!$B$10))^BH5*INDEX($B$13:$M$13,1,MOD(55-1,12)+1) | BI22: =($B22/12)*(1+INDEX($C22:$E22,1,Control!$B$10))^BI5*INDEX($B$13:$M$13,1,MOD(56-1,12)+1) | BJ22: =($B22/12)*(1+INDEX($C22:$E22,1,Control!$B$10))^BJ5*INDEX($B$13:$M$13,1,MOD(57-1,12)+1) | BK22: =($B22/12)*(1+INDEX($C22:$E22,1,Control!$B$10))^BK5*INDEX($B$13:$M$13,1,MOD(58-1,12)+1) | BL22: =($B22/12)*(1+INDEX($C22:$E22,1,Control!$B$10))^BL5*INDEX($B$13:$M$13,1,MOD(59-1,12)+1) | BM22: =($B22/12)*(1+INDEX($C22:$E22,1,Control!$B$10))^BM5*INDEX($B$13:$M$13,1,MOD(60-1,12)+1) | BN22: =($B22/12)*(1+INDEX($C22:$E22,1,Control!$B$10))^BN5*INDEX($B$13:$M$13,1,MOD(61-1,12)+1) | BO22: =($B22/12)*(1+INDEX($C22:$E22,1,Control!$B$10))^BO5*INDEX($B$13:$M$13,1,MOD(62-1,12)+1) | BP22: =($B22/12)*(1+INDEX($C22:$E22,1,Control!$B$10))^BP5*INDEX($B$13:$M$13,1,MOD(63-1,12)+1) | BQ22: =($B22/12)*(1+INDEX($C22:$E22,1,Control!$B$10))^BQ5*INDEX($B$13:$M$13,1,MOD(64-1,12)+1) | BR22: =($B22/12)*(1+INDEX($C22:$E22,1,Control!$B$10))^BR5*INDEX($B$13:$M$13,1,MOD(65-1,12)+1) | BS22: =($B22/12)*(1+INDEX($C22:$E22,1,Control!$B$10))^BS5*INDEX($B$13:$M$13,1,MOD(66-1,12)+1) | BT22: =($B22/12)*(1+INDEX($C22:$E22,1,Control!$B$10))^BT5*INDEX($B$13:$M$13,1,MOD(67-1,12)+1) | BU22: =($B22/12)*(1+INDEX($C22:$E22,1,Control!$B$10))^BU5*INDEX($B$13:$M$13,1,MOD(68-1,12)+1) | BV22: =($B22/12)*(1+INDEX($C22:$E22,1,Control!$B$10))^BV5*INDEX($B$13:$M$13,1,MOD(69-1,12)+1) | BW22: =($B22/12)*(1+INDEX($C22:$E22,1,Control!$B$10))^BW5*INDEX($B$13:$M$13,1,MOD(70-1,12)+1) | BX22: =($B22/12)*(1+INDEX($C22:$E22,1,Control!$B$10))^BX5*INDEX($B$13:$M$13,1,MOD(71-1,12)+1) | BY22: =($B22/12)*(1+INDEX($C22:$E22,1,Control!$B$10))^BY5*INDEX($B$13:$M$13,1,MOD(72-1,12)+1) | BZ22: =($B22/12)*(1+INDEX($C22:$E22,1,Control!$B$10))^BZ5*INDEX($B$13:$M$13,1,MOD(73-1,12)+1) | CA22: =($B22/12)*(1+INDEX($C22:$E22,1,Control!$B$10))^CA5*INDEX($B$13:$M$13,1,MOD(74-1,12)+1) | CB22: =($B22/12)*(1+INDEX($C22:$E22,1,Control!$B$10))^CB5*INDEX($B$13:$M$13,1,MOD(75-1,12)+1) | CC22: =($B22/12)*(1+INDEX($C22:$E22,1,Control!$B$10))^CC5*INDEX($B$13:$M$13,1,MOD(76-1,12)+1) | CD22: =($B22/12)*(1+INDEX($C22:$E22,1,Control!$B$10))^CD5*INDEX($B$13:$M$13,1,MOD(77-1,12)+1) | CE22: =($B22/12)*(1+INDEX($C22:$E22,1,Control!$B$10))^CE5*INDEX($B$13:$M$13,1,MOD(78-1,12)+1) | CF22: =($B22/12)*(1+INDEX($C22:$E22,1,Control!$B$10))^CF5*INDEX($B$13:$M$13,1,MOD(79-1,12)+1) | CG22: =($B22/12)*(1+INDEX($C22:$E22,1,Control!$B$10))^CG5*INDEX($B$13:$M$13,1,MOD(80-1,12)+1) | CH22: =($B22/12)*(1+INDEX($C22:$E22,1,Control!$B$10))^CH5*INDEX($B$13:$M$13,1,MOD(81-1,12)+1) | CI22: =($B22/12)*(1+INDEX($C22:$E22,1,Control!$B$10))^CI5*INDEX($B$13:$M$13,1,MOD(82-1,12)+1) | CJ22: =($B22/12)*(1+INDEX($C22:$E22,1,Control!$B$10))^CJ5*INDEX($B$13:$M$13,1,MOD(83-1,12)+1) | CK22: =($B22/12)*(1+INDEX($C22:$E22,1,Control!$B$10))^CK5*INDEX($B$13:$M$13,1,MOD(84-1,12)+1) | CL22: =($B22/12)*(1+INDEX($C22:$E22,1,Control!$B$10))^CL5*INDEX($B$13:$M$13,1,MOD(85-1,12)+1) | CM22: =($B22/12)*(1+INDEX($C22:$E22,1,Control!$B$10))^CM5*INDEX($B$13:$M$13,1,MOD(86-1,12)+1) | CN22: =($B22/12)*(1+INDEX($C22:$E22,1,Control!$B$10))^CN5*INDEX($B$13:$M$13,1,MOD(87-1,12)+1) | CO22: =($B22/12)*(1+INDEX($C22:$E22,1,Control!$B$10))^CO5*INDEX($B$13:$M$13,1,MOD(88-1,12)+1) | CP22: =($B22/12)*(1+INDEX($C22:$E22,1,Control!$B$10))^CP5*INDEX($B$13:$M$13,1,MOD(89-1,12)+1) | CQ22: =($B22/12)*(1+INDEX($C22:$E22,1,Control!$B$10))^CQ5*INDEX($B$13:$M$13,1,MOD(90-1,12)+1) | CR22: =($B22/12)*(1+INDEX($C22:$E22,1,Control!$B$10))^CR5*INDEX($B$13:$M$13,1,MOD(91-1,12)+1) | CS22: =($B22/12)*(1+INDEX($C22:$E22,1,Control!$B$10))^CS5*INDEX($B$13:$M$13,1,MOD(92-1,12)+1) | CT22: =($B22/12)*(1+INDEX($C22:$E22,1,Control!$B$10))^CT5*INDEX($B$13:$M$13,1,MOD(93-1,12)+1) | CU22: =($B22/12)*(1+INDEX($C22:$E22,1,Control!$B$10))^CU5*INDEX($B$13:$M$13,1,MOD(94-1,12)+1) | CV22: =($B22/12)*(1+INDEX($C22:$E22,1,Control!$B$10))^CV5*INDEX($B$13:$M$13,1,MOD(95-1,12)+1) | CW22: =($B22/12)*(1+INDEX($C22:$E22,1,Control!$B$10))^CW5*INDEX($B$13:$M$13,1,MOD(96-1,12)+1) | CX22: =($B22/12)*(1+INDEX($C22:$E22,1,Control!$B$10))^CX5*INDEX($B$13:$M$13,1,MOD(97-1,12)+1) | CY22: =($B22/12)*(1+INDEX($C22:$E22,1,Control!$B$10))^CY5*INDEX($B$13:$M$13,1,MOD(98-1,12)+1) | CZ22: =($B22/12)*(1+INDEX($C22:$E22,1,Control!$B$10))^CZ5*INDEX($B$13:$M$13,1,MOD(99-1,12)+1) | DA22: =($B22/12)*(1+INDEX($C22:$E22,1,Control!$B$10))^DA5*INDEX($B$13:$M$13,1,MOD(100-1,12)+1) | DB22: =($B22/12)*(1+INDEX($C22:$E22,1,Control!$B$10))^DB5*INDEX($B$13:$M$13,1,MOD(101-1,12)+1) | DC22: =($B22/12)*(1+INDEX($C22:$E22,1,Control!$B$10))^DC5*INDEX($B$13:$M$13,1,MOD(102-1,12)+1) | DD22: =($B22/12)*(1+INDEX($C22:$E22,1,Control!$B$10))^DD5*INDEX($B$13:$M$13,1,MOD(103-1,12)+1) | DE22: =($B22/12)*(1+INDEX($C22:$E22,1,Control!$B$10))^DE5*INDEX($B$13:$M$13,1,MOD(104-1,12)+1) | DF22: =($B22/12)*(1+INDEX($C22:$E22,1,Control!$B$10))^DF5*INDEX($B$13:$M$13,1,MOD(105-1,12)+1) | DG22: =($B22/12)*(1+INDEX($C22:$E22,1,Control!$B$10))^DG5*INDEX($B$13:$M$13,1,MOD(106-1,12)+1) | DH22: =($B22/12)*(1+INDEX($C22:$E22,1,Control!$B$10))^DH5*INDEX($B$13:$M$13,1,MOD(107-1,12)+1) | DI22: =($B22/12)*(1+INDEX($C22:$E22,1,Control!$B$10))^DI5*INDEX($B$13:$M$13,1,MOD(108-1,12)+1) | DJ22: =($B22/12)*(1+INDEX($C22:$E22,1,Control!$B$10))^DJ5*INDEX($B$13:$M$13,1,MOD(109-1,12)+1) | DK22: =($B22/12)*(1+INDEX($C22:$E22,1,Control!$B$10))^DK5*INDEX($B$13:$M$13,1,MOD(110-1,12)+1) | DL22: =($B22/12)*(1+INDEX($C22:$E22,1,Control!$B$10))^DL5*INDEX($B$13:$M$13,1,MOD(111-1,12)+1) | DM22: =($B22/12)*(1+INDEX($C22:$E22,1,Control!$B$10))^DM5*INDEX($B$13:$M$13,1,MOD(112-1,12)+1) | DN22: =($B22/12)*(1+INDEX($C22:$E22,1,Control!$B$10))^DN5*INDEX($B$13:$M$13,1,MOD(113-1,12)+1) | DO22: =($B22/12)*(1+INDEX($C22:$E22,1,Control!$B$10))^DO5*INDEX($B$13:$M$13,1,MOD(114-1,12)+1) | DP22: =($B22/12)*(1+INDEX($C22:$E22,1,Control!$B$10))^DP5*INDEX($B$13:$M$13,1,MOD(115-1,12)+1) | DQ22: =($B22/12)*(1+INDEX($C22:$E22,1,Control!$B$10))^DQ5*INDEX($B$13:$M$13,1,MOD(116-1,12)+1) | DR22: =($B22/12)*(1+INDEX($C22:$E22,1,Control!$B$10))^DR5*INDEX($B$13:$M$13,1,MOD(117-1,12)+1) | DS22: =($B22/12)*(1+INDEX($C22:$E22,1,Control!$B$10))^DS5*INDEX($B$13:$M$13,1,MOD(118-1,12)+1) | DT22: =($B22/12)*(1+INDEX($C22:$E22,1,Control!$B$10))^DT5*INDEX($B$13:$M$13,1,MOD(119-1,12)+1) | DU22: =($B22/12)*(1+INDEX($C22:$E22,1,Control!$B$10))^DU5*INDEX($B$13:$M$13,1,MOD(120-1,12)+1)
