Workbook

Sheet DASHBOARD
A1: EXECUTIVE DASHBOARD
A3: FINANCIAL SUMMARY (FY2025 - First 12 Months)
B5: Metric | C5: Value
A6: VOLUME
B7: Total HL Sold (Year 1) | C7: =SUM(Volume_Build!F20:Q20)
B8: Average Monthly HL | C8: =C7/12
A9: REVENUE
B10: Net Revenue (Year 1) | C10: =SUM(Revenue!B9:M9)
B11: Revenue per HL | C11: =C10/C7*1000
A12: PROFITABILITY
B13: Gross Margin % | C13: =AVERAGE(IS!B7:M7)
B14: EBITDA Margin % | C14: =AVERAGE(IS!B17:M17)
B15: Net Margin % | C15: =AVERAGE(IS!B27:M27)
A16: CASH & LEVERAGE
B17: Cash Balance (Month 12) | C17: =CF!M24
B18: Cum. Net Income (Year 1) | C18: =SUM(IS!B26:M26)

Sheet CONTROL
A1: BEER BREWERY FINANCIAL MODEL
A2: CONTROL PANEL
A4: Scenario: | B4: Base
A5: Scenario ID: | B5: =MATCH(B4,{"Base","Upside","Downside"},0)
A7: Reporting Date: | B7: 45809
A10: Enable Contract Brewing? | B10: Yes
A11: Enable Excise Shock (Year 5)? | B11: Yes
A12: Enable Capacity Expansion? | B12: Yes

Sheet TIMELINE
A1: MODEL TIMELINE
A3: Model Start Date: | B3: 45658
A4: Number of Periods: | B4: 120
A5: Frequency: | B5: Monthly
A7: Date | B7: 45658 | C7: 45689 | D7: 45717 | E7: 45748 | F7: 45778 | G7: 45809 | H7: 45839 | I7: 45870 | J7: 45901 | K7: 45931 | L7: 45962 | M7: 45992 | N7: 46023 | O7: 46054 | P7: 46082 | Q7: 46113 | R7: 46143 | S7: 46174 | T7: 46204 | U7: 46235 | V7: 46266 | W7: 46296 | X7: 46327 | Y7: 46357 | Z7: 46388 | AA7: 46419 | AB7: 46447 | AC7: 46478 | AD7: 46508 | AE7: 46539 | AF7: 46569 | AG7: 46600 | AH7: 46631 | AI7: 46661 | AJ7: 46692 | AK7: 46722 | AL7: 46753 | AM7: 46784 | AN7: 46813 | AO7: 46844 | AP7: 46874 | AQ7: 46905 | AR7: 46935 | AS7: 46966 | AT7: 46997 | AU7: 47027 | AV7: 47058 | AW7: 47088 | AX7: 47119 | AY7: 47150 | AZ7: 47178 | BA7: 47209 | BB7: 47239 | BC7: 47270 | BD7: 47300 | BE7: 47331 | BF7: 47362 | BG7: 47392 | BH7: 47423 | BI7: 47453 | BJ7: 47484 | BK7: 47515 | BL7: 47543 | BM7: 47574 | BN7: 47604 | BO7: 47635 | BP7: 47665 | BQ7: 47696 | BR7: 47727 | BS7: 47757 | BT7: 47788 | BU7: 47818 | BV7: 47849 | BW7: 47880 | BX7: 47908 | BY7: 47939 | BZ7: 47969 | CA7: 48000 | CB7: 48030 | CC7: 48061 | CD7: 48092 | CE7: 48122 | CF7: 48153 | CG7: 48183 | CH7: 48214 | CI7: 48245 | CJ7: 48274 | CK7: 48305 | CL7: 48335 | CM7: 48366 | CN7: 48396 | CO7: 48427 | CP7: 48458 | CQ7: 48488 | CR7: 48519 | CS7: 48549 | CT7: 48580 | CU7: 48611 | CV7: 48639 | CW7: 48670 | CX7: 48700 | CY7: 48731 | CZ7: 48761 | DA7: 48792 | DB7: 48823 | DC7: 48853 | DD7: 48884 | DE7: 48914 | DF7: 48945 | DG7: 48976 | DH7: 49004 | DI7: 49035 | DJ7: 49065 | DK7: 49096 | DL7: 49126 | DM7: 49157 | DN7: 49188 | DO7: 49218 | DP7: 49249 | DQ7: 49279
A8: Period # | B8: 1 | C8: 2 | D8: 3 | E8: 4 | F8: 5 | G8: 6 | H8: 7 | I8: 8 | J8: 9 | K8: 10 | L8: 11 | M8: 12 | N8: 13 | O8: 14 | P8: 15 | Q8: 16 | R8: 17 | S8: 18 | T8: 19 | U8: 20 | V8: 21 | W8: 22 | X8: 23 | Y8: 24 | Z8: 25 | AA8: 26 | AB8: 27 | AC8: 28 | AD8: 29 | AE8: 30 | AF8: 31 | AG8: 32 | AH8: 33 | AI8: 34 | AJ8: 35 | AK8: 36 | AL8: 37 | AM8: 38 | AN8: 39 | AO8: 40 | AP8: 41 | AQ8: 42 | AR8: 43 | AS8: 44 | AT8: 45 | AU8: 46 | AV8: 47 | AW8: 48 | AX8: 49 | AY8: 50 | AZ8: 51 | BA8: 52 | BB8: 53 | BC8: 54 | BD8: 55 | BE8: 56 | BF8: 57 | BG8: 58 | BH8: 59 | BI8: 60 | BJ8: 61 | BK8: 62 | BL8: 63 | BM8: 64 | BN8: 65 | BO8: 66 | BP8: 67 | BQ8: 68 | BR8: 69 | BS8: 70 | BT8: 71 | BU8: 72 | BV8: 73 | BW8: 74 | BX8: 75 | BY8: 76 | BZ8: 77 | CA8: 78 | CB8: 79 | CC8: 80 | CD8: 81 | CE8: 82 | CF8: 83 | CG8: 84 | CH8: 85 | CI8: 86 | CJ8: 87 | CK8: 88 | CL8: 89 | CM8: 90 | CN8: 91 | CO8: 92 | CP8: 93 | CQ8: 94 | CR8: 95 | CS8: 96 | CT8: 97 | CU8: 98 | CV8: 99 | CW8: 100 | CX8: 101 | CY8: 102 | CZ8: 103 | DA8: 104 | DB8: 105 | DC8: 106 | DD8: 107 | DE8: 108 | DF8: 109 | DG8: 110 | DH8: 111 | DI8: 112 | DJ8: 113 | DK8: 114 | DL8: 115 | DM8: 116 | DN8: 117 | DO8: 118 | DP8: 119 | DQ8: 120
A9: Month | B9: Jan | C9: Feb | D9: Mar | E9: Apr | F9: May | G9: Jun | H9: Jul | I9: Aug | J9: Sep | K9: Oct | L9: Nov | M9: Dec | N9: Jan | O9: Feb | P9: Mar | Q9: Apr | R9: May | S9: Jun | T9: Jul | U9: Aug | V9: Sep | W9: Oct | X9: Nov | Y9: Dec | Z9: Jan | AA9: Feb | AB9: Mar | AC9: Apr | AD9: May | AE9: Jun | AF9: Jul | AG9: Aug | AH9: Sep | AI9: Oct | AJ9: Nov | AK9: Dec | AL9: Jan | AM9: Feb | AN9: Mar | AO9: Apr | AP9: May | AQ9: Jun | AR9: Jul | AS9: Aug | AT9: Sep | AU9: Oct | AV9: Nov | AW9: Dec | AX9: Jan | AY9: Feb | AZ9: Mar | BA9: Apr | BB9: May | BC9: Jun | BD9: Jul | BE9: Aug | BF9: Sep | BG9: Oct | BH9: Nov | BI9: Dec | BJ9: Jan | BK9: Feb | BL9: Mar | BM9: Apr | BN9: May | BO9: Jun | BP9: Jul | BQ9: Aug | BR9: Sep | BS9: Oct | BT9: Nov | BU9: Dec | BV9: Jan | BW9: Feb | BX9: Mar | BY9: Apr | BZ9: May | CA9: Jun | CB9: Jul | CC9: Aug | CD9: Sep | CE9: Oct | CF9: Nov | CG9: Dec | CH9: Jan | CI9: Feb | CJ9: Mar | CK9: Apr | CL9: May | CM9: Jun | CN9: Jul | CO9: Aug | CP9: Sep | CQ9: Oct | CR9: Nov | CS9: Dec | CT9: Jan | CU9: Feb | CV9: Mar | CW9: Apr | CX9: May | CY9: Jun | CZ9: Jul | DA9: Aug | DB9: Sep | DC9: Oct | DD9: Nov | DE9: Dec | DF9: Jan | DG9: Feb | DH9: Mar | DI9: Apr | DJ9: May | DK9: Jun | DL9: Jul | DM9: Aug | DN9: Sep | DO9: Oct | DP9: Nov | DQ9: Dec
A10: Quarter | B10: Q1 | C10: Q1 | D10: Q1 | E10: Q2 | F10: Q2 | G10: Q2 | H10: Q3 | I10: Q3 | J10: Q3 | K10: Q4 | L10: Q4 | M10: Q4 | N10: Q1 | O10: Q1 | P10: Q1 | Q10: Q2 | R10: Q2 | S10: Q2 | T10: Q3 | U10: Q3 | V10: Q3 | W10: Q4 | X10: Q4 | Y10: Q4 | Z10: Q1 | AA10: Q1 | AB10: Q1 | AC10: Q2 | AD10: Q2 | AE10: Q2 | AF10: Q3 | AG10: Q3 | AH10: Q3 | AI10: Q4 | AJ10: Q4 | AK10: Q4 | AL10: Q1 | AM10: Q1 | AN10: Q1 | AO10: Q2 | AP10: Q2 | AQ10: Q2 | AR10: Q3 | AS10: Q3 | AT10: Q3 | AU10: Q4 | AV10: Q4 | AW10: Q4 | AX10: Q1 | AY10: Q1 | AZ10: Q1 | BA10: Q2 | BB10: Q2 | BC10: Q2 | BD10: Q3 | BE10: Q3 | BF10: Q3 | BG10: Q4 | BH10: Q4 | BI10: Q4 | BJ10: Q1 | BK10: Q1 | BL10: Q1 | BM10: Q2 | BN10: Q2 | BO10: Q2 | BP10: Q3 | BQ10: Q3 | BR10: Q3 | BS10: Q4 | BT10: Q4 | BU10: Q4 | BV10: Q1 | BW10: Q1 | BX10: Q1 | BY10: Q2 | BZ10: Q2 | CA10: Q2 | CB10: Q3 | CC10: Q3 | CD10: Q3 | CE10: Q4 | CF10: Q4 | CG10: Q4 | CH10: Q1 | CI10: Q1 | CJ10: Q1 | CK10: Q2 | CL10: Q2 | CM10: Q2 | CN10: Q3 | CO10: Q3 | CP10: Q3 | CQ10: Q4 | CR10: Q4 | CS10: Q4 | CT10: Q1 | CU10: Q1 | CV10: Q1 | CW10: Q2 | CX10: Q2 | CY10: Q2 | CZ10: Q3 | DA10: Q3 | DB10: Q3 | DC10: Q4 | DD10: Q4 | DE10: Q4 | DF10: Q1 | DG10: Q1 | DH10: Q1 | DI10: Q2 | DJ10: Q2 | DK10: Q2 | DL10: Q3 | DM10: Q3 | DN10: Q3 | DO10: Q4 | DP10: Q4 | DQ10: Q4
A11: FY | B11: FY2025 | C11: FY2025 | D11: FY2025 | E11: FY2025 | F11: FY2025 | G11: FY2025 | H11: FY2026 | I11: FY2026 | J11: FY2026 | K11: FY2026 | L11: FY2026 | M11: FY2026 | N11: FY2026 | O11: FY2026 | P11: FY2026 | Q11: FY2026 | R11: FY2026 | S11: FY2026 | T11: FY2027 | U11: FY2027 | V11: FY2027 | W11: FY2027 | X11: FY2027 | Y11: FY2027 | Z11: FY2027 | AA11: FY2027 | AB11: FY2027 | AC11: FY2027 | AD11: FY2027 | AE11: FY2027 | AF11: FY2028 | AG11: FY2028 | AH11: FY2028 | AI11: FY2028 | AJ11: FY2028 | AK11: FY2028 | AL11: FY2028 | AM11: FY2028 | AN11: FY2028 | AO11: FY2028 | AP11: FY2028 | AQ11: FY2028 | AR11: FY2029 | AS11: FY2029 | AT11: FY2029 | AU11: FY2029 | AV11: FY2029 | AW11: FY2029 | AX11: FY2029 | AY11: FY2029 | AZ11: FY2029 | BA11: FY2029 | BB11: FY2029 | BC11: FY2029 | BD11: FY2030 | BE11: FY2030 | BF11: FY2030 | BG11: FY2030 | BH11: FY2030 | BI11: FY2030 | BJ11: FY2030 | BK11: FY2030 | BL11: FY2030 | BM11: FY2030 | BN11: FY2030 | BO11: FY2030 | BP11: FY2031 | BQ11: FY2031 | BR11: FY2031 | BS11: FY2031 | BT11: FY2031 | BU11: FY2031 | BV11: FY2031 | BW11: FY2031 | BX11: FY2031 | BY11: FY2031 | BZ11: FY2031 | CA11: FY2031 | CB11: FY2032 | CC11: FY2032 | CD11: FY2032 | CE11: FY2032 | CF11: FY2032 | CG11: FY2032 | CH11: FY2032 | CI11: FY2032 | CJ11: FY2032 | CK11: FY2032 | CL11: FY2032 | CM11: FY2032 | CN11: FY2033 | CO11: FY2033 | CP11: FY2033 | CQ11: FY2033 | CR11: FY2033 | CS11: FY2033 | CT11: FY2033 | CU11: FY2033 | CV11: FY2033 | CW11: FY2033 | CX11: FY2033 | CY11: FY2033 | CZ11: FY2034 | DA11: FY2034 | DB11: FY2034 | DC11: FY2034 | DD11: FY2034 | DE11: FY2034 | DF11: FY2034 | DG11: FY2034 | DH11: FY2034 | DI11: FY2034 | DJ11: FY2034 | DK11: FY2034 | DL11: FY2035 | DM11: FY2035 | DN11: FY2035 | DO11: FY2035 | DP11: FY2035 | DQ11: FY2035
A12: FY-End Flag | B12: 0 | C12: 0 | D12: 0 | E12: 0 | F12: 0 | G12: 1 | H12: 0 | I12: 0 | J12: 0 | K12: 0 | L12: 0 | M12: 0 | N12: 0 | O12: 0 | P12: 0 | Q12: 0 | R12: 0 | S12: 1 | T12: 0 | U12: 0 | V12: 0 | W12: 0 | X12: 0 | Y12: 0 | Z12: 0 | AA12: 0 | AB12: 0 | AC12: 0 | AD12: 0 | AE12: 1 | AF12: 0 | AG12: 0 | AH12: 0 | AI12: 0 | AJ12: 0 | AK12: 0 | AL12: 0 | AM12: 0 | AN12: 0 | AO12: 0 | AP12: 0 | AQ12: 1 | AR12: 0 | AS12: 0 | AT12: 0 | AU12: 0 | AV12: 0 | AW12: 0 | AX12: 0 | AY12: 0 | AZ12: 0 | BA12: 0 | BB12: 0 | BC12: 1 | BD12: 0 | BE12: 0 | BF12: 0 | BG12: 0 | BH12: 0 | BI12: 0 | BJ12: 0 | BK12: 0 | BL12: 0 | BM12: 0 | BN12: 0 | BO12: 1 | BP12: 0 | BQ12: 0 | BR12: 0 | BS12: 0 | BT12: 0 | BU12: 0 | BV12: 0 | BW12: 0 | BX12: 0 | BY12: 0 | BZ12: 0 | CA12: 1 | CB12: 0 | CC12: 0 | CD12: 0 | CE12: 0 | CF12: 0 | CG12: 0 | CH12: 0 | CI12: 0 | CJ12: 0 | CK12: 0 | CL12: 0 | CM12: 1 | CN12: 0 | CO12: 0 | CP12: 0 | CQ12: 0 | CR12: 0 | CS12: 0 | CT12: 0 | CU12: 0 | CV12: 0 | CW12: 0 | CX12: 0 | CY12: 1 | CZ12: 0 | DA12: 0 | DB12: 0 | DC12: 0 | DD12: 0 | DE12: 0 | DF12: 0 | DG12: 0 | DH12: 0 | DI12: 0 | DJ12: 0 | DK12: 1 | DL12: 0 | DM12: 0 | DN12: 0 | DO12: 0 | DP12: 0 | DQ12: 0
A13: Year # | B13: 1 | C13: 1 | D13: 1 | E13: 1 | F13: 1 | G13: 1 | H13: 1 | I13: 1 | J13: 1 | K13: 1 | L13: 1 | M13: 1 | N13: 2 | O13: 2 | P13: 2 | Q13: 2 | R13: 2 | S13: 2 | T13: 2 | U13: 2 | V13: 2 | W13: 2 | X13: 2 | Y13: 2 | Z13: 3 | AA13: 3 | AB13: 3 | AC13: 3 | AD13: 3 | AE13: 3 | AF13: 3 | AG13: 3 | AH13: 3 | AI13: 3 | AJ13: 3 | AK13: 3 | AL13: 4 | AM13: 4 | AN13: 4 | AO13: 4 | AP13: 4 | AQ13: 4 | AR13: 4 | AS13: 4 | AT13: 4 | AU13: 4 | AV13: 4 | AW13: 4 | AX13: 5 | AY13: 5 | AZ13: 5 | BA13: 5 | BB13: 5 | BC13: 5 | BD13: 5 | BE13: 5 | BF13: 5 | BG13: 5 | BH13: 5 | BI13: 5 | BJ13: 6 | BK13: 6 | BL13: 6 | BM13: 6 | BN13: 6 | BO13: 6 | BP13: 6 | BQ13: 6 | BR13: 6 | BS13: 6 | BT13: 6 | BU13: 6 | BV13: 7 | BW13: 7 | BX13: 7 | BY13: 7 | BZ13: 7 | CA13: 7 | CB13: 7 | CC13: 7 | CD13: 7 | CE13: 7 | CF13: 7 | CG13: 7 | CH13: 8 | CI13: 8 | CJ13: 8 | CK13: 8 | CL13: 8 | CM13: 8 | CN13: 8 | CO13: 8 | CP13: 8 | CQ13: 8 | CR13: 8 | CS13: 8 | CT13: 9 | CU13: 9 | CV13: 9 | CW13: 9 | CX13: 9 | CY13: 9 | CZ13: 9 | DA13: 9 | DB13: 9 | DC13: 9 | DD13: 9 | DE13: 9 | DF13: 10 | DG13: 10 | DH13: 10 | DI13: 10 | DJ13: 10 | DK13: 10 | DL13: 10 | DM13: 10 | DN13: 10 | DO13: 10 | DP13: 10 | DQ13: 10

Sheet Instructions
A1: USER INSTRUCTIONS
A4: BEER BREWERY FINANCIAL MODEL
A5: 10-Year Monthly Projection Model
A7: PURPOSE:
A8: This model projects financial performance for a beer brewery over 120 months (Jan 2025 - Dec 2034)
A9: with integrated Income Statement, Cash Flow, and Balance Sheet.
A11: HOW TO USE:
A13: 1. SELECT SCENARIO
A14: • Go to CONTROL sheet
A15: • Cell B4: Select scenario from dropdown (Base / Upside / Downside)
A16: • All calculations update automatically
A18: 2. CHANGE ASSUMPTIONS
... A61: FOR QUESTIONS: Contact CFO

Sheet SKU_Master
A1: SKU MASTER DATA
A3: SKU ID | B3: Brand | C3: Pack Type | D3: Size (mL) | E3: ABV % | F3: On-Trade % | G3: Off-Trade % | H3: Pack Category
A4: SKU-01 | B4: SkyBrew | C4: Bottle | D4: 330 | E4: 0.045 | F4: 0.3 | G4: 0.7 | H4: Packaged
A5: SKU-02 | B5: SkyBrew | C5: Can 6-pack | D5: 375 | E5: 0.045 | F5: 0.1 | G5: 0.9 | H5: Packaged
A6: SKU-03 | B6: SkyBrew | C6: Keg | D6: 50000 | E6: 0.045 | F6: 0.95 | G6: 0.05 | H6: Draught
A7: SKU-04 | B7: AllDark | C7: Bottle | D7: 330 | E7: 0.058 | F7: 0.4 | G7: 0.6 | H7: Packaged
A8: SKU-05 | B8: AllDark | C8: Can 4-pack | D8: 375 | E8: 0.058 | F8: 0.2 | G8: 0.8 | H8: Packaged
A9: SKU-06 | B9: AllDark | C9: Keg | D9: 50000 | E9: 0.058 | F9: 0.95 | G9: 0.05 | H9: Draught
A10: SKU-07 | B10: Craft IPA | C10: Bottle | D10: 330 | E10: 0.062 | F10: 0.5 | G10: 0.5 | H10: Packaged
A11: SKU-08 | B11: Craft IPA | C11: Can 4-pack | D11: 375 | E11: 0.062 | F11: 0.3 | G11: 0.7 | H11: Packaged
A12: SKU-09 | B12: Session | C12: Can 6-pack | D12: 375 | E12: 0.035 | F12: 0.1 | G12: 0.9 | H12: Packaged
A13: SKU-10 | B13: Premium Pilsner | C13: Bottle | D13: 330 | E13: 0.05 | F13: 0.4 | G13: 0.6 | H13: Packaged

Sheet Assumptions_Macro
A1: MACRO & TAX ASSUMPTIONS
A3: SCENARIO ASSUMPTIONS
A4: Driver | B4: Base | C4: Upside | D4: Downside
A5: Materials Inflation % p.a. | B5: 0.03 | C5: 0.02 | D5: 0.05
A6: Packaging Inflation % p.a. | B6: 0.025 | C6: 0.02 | D6: 0.045
A7: Labour Inflation % p.a. | B7: 0.035 | C7: 0.03 | D7: 0.05
A8: CPI (Excise Indexation) % p.a. | B8: 0.025 | C8: 0.02 | D8: 0.035
A9: FX Rate AUD/NZD | B9: 1.08 | C9: 1.05 | D9: 1.12
A10: Excise Shock Year 5 (%) | B10: 0 | C10: 0 | D10: 0.1
A12: TAX & EXCISE RATES
A13: Corporate Tax Rate | B13: 0.3
A14: Excise Rate - AU Draught (AUD/L alcohol) | B14: 36.32
A15: Excise Rate - AU Packaged >3.5% (AUD/L) | B15: 54.72
A16: Excise Rate - AU Packaged ≤3.5% (AUD/L) | B16: 36.32
A17: Excise Rate - NZ All Types (NZD/L alcohol) | B17: 30.23

Sheet Assumptions_Commercial
A1: COMMERCIAL ASSUMPTIONS
A3: VOLUME GROWTH RATES (% p.a.)
A4: Market | B4: Base | C4: Upside | D4: Downside
A5: Australia | B5: 0.04 | C5: 0.065 | D5: 0.01
A6: New Zealand | B6: 0.03 | C6: 0.05 | D6: 0
A7: Exports | B7: 0.15 | C7: 0.2 | D7: 0.08
A9: PRICE ESCALATION RATES (% p.a.)
A10: Channel | B10: Base | C10: Upside | D10: Downside
A11: On-Trade | B11: 0.035 | C11: 0.05 | D11: 0.015
A12: Off-Trade | B12: 0.02 | C12: 0.035 | D12: 0.005
A14: A&P SPEND (% of Net Revenue)
A15: A&P % | B15: 0.12 | C15: 0.14 | D15: 0.09
A17: SEASONALITY INDICES (Monthly)
A18: Month | B18: Index
A19: Jan | B19: 1.15
A20: Feb | B20: 1.1
A21: Mar | B21: 1.05
A22: Apr | B22: 0.95
A23: May | B23: 0.85
A24: Jun | B24: 0.8
A25: Jul | B25: 0.8
A26: Aug | B26: 0.85
A27: Sep | B27: 0.95
A28: Oct | B28: 1.05
A29: Nov | B29: 1.1
A30: Dec | B30: 1.35
A31: Average (must = 1.00) | B31: =AVERAGE(B19:B30)

Sheet Assumptions_Operations
A1: OPERATIONS & COST ASSUMPTIONS
A3: CAPACITY
A4: Installed Brewing Capacity (HL p.a.) | B4: 1000000
A5: Bottle Line Capacity (HL p.a.) | B5: 400000
A6: Can Line Capacity (HL p.a.) | B6: 450000
A7: Keg Line Capacity (HL p.a.) | B7: 200000
A8: Overall Yield % | B8: 0.93
A10: COGS PER HL (Base Year, AUD)
A11: Materials per HL (avg) | B11: 25
A12: Packaging per HL (avg) | B12: 60
A13: Direct Labour per HL | B13: 10
A14: Utilities per HL | B14: 6.5
A15: Variable Overhead per HL | B15: 7.5
A16: Fixed Overhead per month (AUD) | B16: 150000
A18: WORKING CAPITAL (Days)
A19: Days - Raw Materials Inventory | B19: 35
A20: Days - WIP Inventory | B20: 16
A21: Days - Finished Goods Inventory | B21: 25
A22: Days - Trade Receivables | B22: 40
A23: Days - Trade Payables | B23: 55
A24: Keg Deposit per 50L keg (AUD) | B24: 80

Sheet Assumptions_Finance
A1: FINANCING ASSUMPTIONS
A3: DEBT FACILITIES
A4: Term Loan A - Opening Balance (AUD M) | B4: 15
A5: Term Loan A - Interest Rate p.a. | B5: 0.065
A6: Term Loan A - Maturity (years) | B6: 7
A7: Capex Facility - Limit (AUD M) | B7: 10
A8: Capex Facility - Interest Rate p.a. | B8: 0.0675
A9: Overdraft - Limit (AUD M) | B9: 2
A10: Overdraft - Interest Rate p.a. | B10: 0.075
A12: EQUITY
A13: Opening Share Capital (AUD M) | B13: 25
A14: Planned Injection Year 3 (AUD M) | B14: 5
A15: Dividend Payout Ratio | B15: 0.4
A16: Minimum Cash Balance (AUD M) | B16: 2

Sheet Assumptions_Capex
A1: ASSUMPTIONS CAPEX
A3: Sheet structure to be completed in Phase 2

Sheet Volume_Build
A1: VOLUME BUILD-UP (Hectolitres)
A3: SKU | B3: Channel | C3: Market | D3: Base Annual HL (Y1) | E3: Growth % p.a. | F3: =TIMELINE!B7 | G3: =TIMELINE!C7 | H3: =TIMELINE!D7 | I3: =TIMELINE!E7 | J3: =TIMELINE!F7 | K3: =TIMELINE!G7 | L3: =TIMELINE!H7 | M3: =TIMELINE!I7 | ... DU3: =TIMELINE!DQ7
A4: SKU-01 | B4: On-Trade | C4: AU | D4: 35000 | E4: =INDEX(Assumptions_Commercial!$B$5:$D$5,CONTROL!$B$5) | F4: =$D4 *(1+$E4)^((YEAR(TIMELINE!B7)-2025)+(MONTH(TIMELINE!B7)-1)/12) /12 *INDEX(Assumptions_Commercial!$B$22:$B$33,MONTH(TIMELINE!B7)) | G4: =$D4 *(1+$E4)^((YEAR(TIMELINE!C7)-2025)+(MONTH(TIMELINE!C7)-1)/12) /12 *INDEX(Assumptions_Commercial!$B$22:$B$33,MONTH(TIMELINE!C7)) | H4: =$D4 *(1+$E4)^((YEAR(TIMELINE!D7)-2025)+(MONTH(TIMELINE!D7)-1)/12) /12 *INDEX(Assumptions_Commercial!$B$22:$B$33,MONTH(TIMELINE!D7)) | I4: =$D4 *(1+$E4)^((YEAR(TIMELINE!E7)-2025)+(MONTH(TIMELINE!E7)-1)/12) /12 *INDEX(Assumptions_Commercial!$B$22:$B$33,MONTH(TIMELINE!E7)) | J4: =$D4 *(1+$E4)^((YEAR(TIMELINE!F7)-2025)+(MONTH(TIMELINE!F7)-1)/12) /12 *INDEX(Assumptions_Commercial!$B$22:$B$33,MONTH(TIMELINE!F7)) | K4: =$D4 *(1+$E4)^((YEAR(TIMELINE!G7)-2025)+(MONTH(TIMELINE!G7)-1)/12) /12 *INDEX(Assumptions_Commercial!$B$22:$B$33,MONTH(TIMELINE!G7)) | L4: =$D4 *(1+$E4)^((YEAR(TIMELINE!H7)-2025)+(MONTH(TIMELINE!H7)-1)/12) /12 *INDEX(Assumptions_Commercial!$B$22:$B$33,MONTH(TIMELINE!H7)) | M4: =$D4 *(1+$E4)^((YEAR(TIMELINE!I7)-2025)+(MONTH(TIMELINE!I7)-1)/12) /12 *INDEX(Assumptions_Commercial!$B$22:$B$33,MONTH(TIMELINE!I7)) | ... DU4: =$D4 *(1+$E4)^((YEAR(TIMELINE!DQ7)-2025)+(MONTH(TIMELINE!DQ7)-1)/12) /12 *INDEX(Assumptions_Commercial!$B$22:$B$33,MONTH(TIMELINE!DQ7))
A5: SKU-01 | B5: Off-Trade | C5: AU | D5: 81667 | E5: =INDEX(Assumptions_Commercial!$B$5:$D$5,CONTROL!$B$5) | F5: =$D5 *(1+$E5)^((YEAR(TIMELINE!B7)-2025)+(MONTH(TIMELINE!B7)-1)/12) /12 *INDEX(Assumptions_Commercial!$B$22:$B$33,MONTH(TIMELINE!B7)) | G5: =$D5 *(1+$E5)^((YEAR(TIMELINE!C7)-2025)+(MONTH(TIMELINE!C7)-1)/12) /12 *INDEX(Assumptions_Commercial!$B$22:$B$33,MONTH(TIMELINE!C7)) | H5: =$D5 *(1+$E5)^((YEAR(TIMELINE!D7)-2025)+(MONTH(TIMELINE!D7)-1)/12) /12 *INDEX(Assumptions_Commercial!$B$22:$B$33,MONTH(TIMELINE!D7)) | I5: =$D5 *(1+$E5)^((YEAR(TIMELINE!E7)-2025)+(MONTH(TIMELINE!E7)-1)/12) /12 *INDEX(Assumptions_Commercial!$B$22:$B$33,MONTH(TIMELINE!E7)) | J5: =$D5 *(1+$E5)^((YEAR(TIMELINE!F7)-2025)+(MONTH(TIMELINE!F7)-1)/12) /12 *INDEX(Assumptions_Commercial!$B$22:$B$33,MONTH(TIMELINE!F7)) | K5: =$D5 *(1+$E5)^((YEAR(TIMELINE!G7)-2025)+(MONTH(TIMELINE!G7)-1)/12) /12 *INDEX(Assumptions_Commercial!$B$22:$B$33,MONTH(TIMELINE!G7)) | L5: =$D5 *(1+$E5)^((YEAR(TIMELINE!H7)-2025)+(MONTH(TIMELINE!H7)-1)/12) /12 *INDEX(Assumptions_Commercial!$B$22:$B$33,MONTH(TIMELINE!H7)) | M5: =$D5 *(1+$E5)^((YEAR(TIMELINE!I7)-2025)+(MONTH(TIMELINE!I7)-1)/12) /12 *INDEX(Assumptions_Commercial!$B$22:$B$33,MONTH(TIMELINE!I7)) | ... DU5: =$D5 *(1+$E5)^((YEAR(TIMELINE!DQ7)-2025)+(MONTH(TIMELINE!DQ7)-1)/12) /12 *INDEX(Assumptions_Commercial!$B$22:$B$33,MONTH(TIMELINE!DQ7))
A6: SKU-02 | B6: Off-Trade | C6: AU | D6: 70000 | E6: =INDEX(Assumptions_Commercial!$B$5:$D$5,CONTROL!$B$5) | F6: =$D6 *(1+$E6)^((YEAR(TIMELINE!B7)-2025)+(MONTH(TIMELINE!B7)-1)/12) /12 *INDEX(Assumptions_Commercial!$B$22:$B$33,MONTH(TIMELINE!B7)) | G6: =$D6 *(1+$E6)^((YEAR(TIMELINE!C7)-2025)+(MONTH(TIMELINE!C7)-1)/12) /12 *INDEX(Assumptions_Commercial!$B$22:$B$33,MONTH(TIMELINE!C7)) | H6: =$D6 *(1+$E6)^((YEAR(TIMELINE!D7)-2025)+(MONTH(TIMELINE!D7)-1)/12) /12 *INDEX(Assumptions_Commercial!$B$22:$B$33,MONTH(TIMELINE!D7)) | I6: =$D6 *(1+$E6)^((YEAR(TIMELINE!E7)-2025)+(MONTH(TIMELINE!E7)-1)/12) /12 *INDEX(Assumptions_Commercial!$B$22:$B$33,MONTH(TIMELINE!E7)) | J6: =$D6 *(1+$E6)^((YEAR(TIMELINE!F7)-2025)+(MONTH(TIMELINE!F7)-1)/12) /12 *INDEX(Assumptions_Commercial!$B$22:$B$33,MONTH(TIMELINE!F7)) | K6: =$D6 *(1+$E6)^((YEAR(TIMELINE!G7)-2025)+(MONTH(TIMELINE!G7)-1)/12) /12 *INDEX(Assumptions_Commercial!$B$22:$B$33,MONTH(TIMELINE!G7)) | L6: =$D6 *(1+$E6)^((YEAR(TIMELINE!H7)-2025)+(MONTH(TIMELINE!H7)-1)/12) /12 *INDEX(Assumptions_Commercial!$B$22:$B$33,MONTH(TIMELINE!H7)) | M6: =$D6 *(1+$E6)^((YEAR(TIMELINE!I7)-2025)+(MONTH(TIMELINE!I7)-1)/12) /12 *INDEX(Assumptions_Commercial!$B$22:$B$33,MONTH(TIMELINE!I7)) | ... DU6: =$D6 *(1+$E6)^((YEAR(TIMELINE!DQ7)-2025)+(MONTH(TIMELINE!DQ7)-1)/12) /12 *INDEX(Assumptions_Commercial!$B$22:$B$33,MONTH(TIMELINE!DQ7))
A7: SKU-03 | B7: On-Trade | C7: AU | D7: 95000 | E7: =INDEX(Assumptions_Commercial!$B$5:$D$5,CONTROL!$B$5) | F7: =$D7 *(1+$E7)^((YEAR(TIMELINE!B7)-2025)+(MONTH(TIMELINE!B7)-1)/12) /12 *INDEX(Assumptions_Commercial!$B$22:$B$33,MONTH(TIMELINE!B7)) | G7: =$D7 *(1+$E7)^((YEAR(TIMELINE!C7)-2025)+(MONTH(TIMELINE!C7)-1)/12) /12 *INDEX(Assumptions_Commercial!$B$22:$B$33,MONTH(TIMELINE!C7)) | H7: =$D7 *(1+$E7)^((YEAR(TIMELINE!D7)-2025)+(MONTH(TIMELINE!D7)-1)/12) /12 *INDEX(Assumptions_Commercial!$B$22:$B$33,MONTH(TIMELINE!D7)) | I7: =$D7 *(1+$E7)^((YEAR(TIMELINE!E7)-2025)+(MONTH(TIMELINE!E7)-1)/12) /12 *INDEX(Assumptions_Commercial!$B$22:$B$33,MONTH(TIMELINE!E7)) | J7: =$D7 *(1+$E7)^((YEAR(TIMELINE!F7)-2025)+(MONTH(TIMELINE!F7)-1)/12) /12 *INDEX(Assumptions_Commercial!$B$22:$B$33,MONTH(TIMELINE!F7)) | K7: =$D7 *(1+$E7)^((YEAR(TIMELINE!G7)-2025)+(MONTH(TIMELINE!G7)-1)/12) /12 *INDEX(Assumptions_Commercial!$B$22:$B$33,MONTH(TIMELINE!G7)) | L7: =$D7 *(1+$E7)^((YEAR(TIMELINE!H7)-2025)+(MONTH(TIMELINE!H7)-1)/12) /12 *INDEX(Assumptions_Commercial!$B$22:$B$33,MONTH(TIMELINE!H7)) | M7: =$D7 *(1+$E7)^((YEAR(TIMELINE!I7)-2025)+(MONTH(TIMELINE!I7)-1)/12) /12 *INDEX(Assumptions_Commercial!$B$22:$B$33,MONTH(TIMELINE!I7)) | ... DU7: =$D7 *(1+$E7)^((YEAR(TIMELINE!DQ7)-2025)+(MONTH(TIMELINE!DQ7)-1)/12) /12 *INDEX(Assumptions_Commercial!$B$22:$B$33,MONTH(TIMELINE!DQ7))
A8: SKU-04 | B8: On-Trade | C8: AU | D8: 20000 | E8: =INDEX(Assumptions_Commercial!$B$5:$D$5,CONTROL!$B$5) | F8: =$D8 *(1+$E8)^((YEAR(TIMELINE!B7)-2025)+(MONTH(TIMELINE!B7)-1)/12) /12 *INDEX(Assumptions_Commercial!$B$22:$B$33,MONTH(TIMELINE!B7)) | G8: =$D8 *(1+$E8)^((YEAR(TIMELINE!C7)-2025)+(MONTH(TIMELINE!C7)-1)/12) /12 *INDEX(Assumptions_Commercial!$B$22:$B$33,MONTH(TIMELINE!C7)) | H8: =$D8 *(1+$E8)^((YEAR(TIMELINE!D7)-2025)+(MONTH(TIMELINE!D7)-1)/12) /12 *INDEX(Assumptions_Commercial!$B$22:$B$33,MONTH(TIMELINE!D7)) | I8: =$D8 *(1+$E8)^((YEAR(TIMELINE!E7)-2025)+(MONTH(TIMELINE!E7)-1)/12) /12 *INDEX(Assumptions_Commercial!$B$22:$B$33,MONTH(TIMELINE!E7)) | J8: =$D8 *(1+$E8)^((YEAR(TIMELINE!F7)-2025)+(MONTH(TIMELINE!F7)-1)/12) /12 *INDEX(Assumptions_Commercial!$B$22:$B$33,MONTH(TIMELINE!F7)) | K8: =$D8 *(1+$E8)^((YEAR(TIMELINE!G7)-2025)+(MONTH(TIMELINE!G7)-1)/12) /12 *INDEX(Assumptions_Commercial!$B$22:$B$33,MONTH(TIMELINE!G7)) | L8: =$D8 *(1+$E8)^((YEAR(TIMELINE!H7)-2025)+(MONTH(TIMELINE!H7)-1)/12) /12 *INDEX(Assumptions_Commercial!$B$22:$B$33,MONTH(TIMELINE!H7)) | M8: =$D8 *(1+$E8)^((YEAR(TIMELINE!I7)-2025)+(MONTH(TIMELINE!I7)-1)/12) /12 *INDEX(Assumptions_Commercial!$B$22:$B$33,MONTH(TIMELINE!I7)) | ... DU8: =$D8 *(1+$E8)^((YEAR(TIMELINE!DQ7)-2025)+(MONTH(TIMELINE!DQ7)-1)/12) /12 *INDEX(Assumptions_Commercial!$B$22:$B$33,MONTH(TIMELINE!DQ7))
A9: SKU-04 | B9: Off-Trade | C9: AU | D9: 30000 | E9: =INDEX(Assumptions_Commercial!$B$5:$D$5,CONTROL!$B$5) | F9: =$D9 *(1+$E9)^((YEAR(TIMELINE!B7)-2025)+(MONTH(TIMELINE!B7)-1)/12) /12 *INDEX(Assumptions_Commercial!$B$22:$B$33,MONTH(TIMELINE!B7)) | G9: =$D9 *(1+$E9)^((YEAR(TIMELINE!C7)-2025)+(MONTH(TIMELINE!C7)-1)/12) /12 *INDEX(Assumptions_Commercial!$B$22:$B$33,MONTH(TIMELINE!C7)) | H9: =$D9 *(1+$E9)^((YEAR(TIMELINE!D7)-2025)+(MONTH(TIMELINE!D7)-1)/12) /12 *INDEX(Assumptions_Commercial!$B$22:$B$33,MONTH(TIMELINE!D7)) | I9: =$D9 *(1+$E9)^((YEAR(TIMELINE!E7)-2025)+(MONTH(TIMELINE!E7)-1)/12) /12 *INDEX(Assumptions_Commercial!$B$22:$B$33,MONTH(TIMELINE!E7)) | J9: =$D9 *(1+$E9)^((YEAR(TIMELINE!F7)-2025)+(MONTH(TIMELINE!F7)-1)/12) /12 *INDEX(Assumptions_Commercial!$B$22:$B$33,MONTH(TIMELINE!F7)) | K9: =$D9 *(1+$E9)^((YEAR(TIMELINE!G7)-2025)+(MONTH(TIMELINE!G7)-1)/12) /12 *INDEX(Assumptions_Commercial!$B$22:$B$33,MONTH(TIMELINE!G7)) | L9: =$D9 *(1+$E9)^((YEAR(TIMELINE!H7)-2025)+(MONTH(TIMELINE!H7)-1)/12) /12 *INDEX(Assumptions_Commercial!$B$22:$B$33,MONTH(TIMELINE!H7)) | M9: =$D9 *(1+$E9)^((YEAR(TIMELINE!I7)-2025)+(MONTH(TIMELINE!I7)-1)/12) /12 *INDEX(Assumptions_Commercial!$B$22:$B$33,MONTH(TIMELINE!I7)) | ... DU9: =$D9 *(1+$E9)^((YEAR(TIMELINE!DQ7)-2025)+(MONTH(TIMELINE!DQ7)-1)/12) /12 *INDEX(Assumptions_Commercial!$B$22:$B$33,MONTH(TIMELINE!DQ7))
A10: SKU-05 | B10: Off-Trade | C10: AU | D10: 35000 | E10: =INDEX(Assumptions_Commercial!$B$5:$D$5,CONTROL!$B$5) | F10: =$D10 *(1+$E10)^((YEAR(TIMELINE!B7)-2025)+(MONTH(TIMELINE!B7)-1)/12) /12 *INDEX(Assumptions_Commercial!$B$22:$B$33,MONTH(TIMELINE!B7)) | G10: =$D10 *(1+$E10)^((YEAR(TIMELINE!C7)-2025)+(MONTH(TIMELINE!C7)-1)/12) /12 *INDEX(Assumptions_Commercial!$B$22:$B$33,MONTH(TIMELINE!C7)) | H10: =$D10 *(1+$E10)^((YEAR(TIMELINE!D7)-2025)+(MONTH(TIMELINE!D7)-1)/12) /12 *INDEX(Assumptions_Commercial!$B$22:$B$33,MONTH(TIMELINE!D7)) | I10: =$D10 *(1+$E10)^((YEAR(TIMELINE!E7)-2025)+(MONTH(TIMELINE!E7)-1)/12) /12 *INDEX(Assumptions_Commercial!$B$22:$B$33,MONTH(TIMELINE!E7)) | J10: =$D10 *(1+$E10)^((YEAR(TIMELINE!F7)-2025)+(MONTH(TIMELINE!F7)-1)/12) /12 *INDEX(Assumptions_Commercial!$B$22:$B$33,MONTH(TIMELINE!F7)) | K10: =$D10 *(1+$E10)^((YEAR(TIMELINE!G7)-2025)+(MONTH(TIMELINE!G7)-1)/12) /12 *INDEX(Assumptions_Commercial!$B$22:$B$33,MONTH(TIMELINE!G7)) | L10: =$D10 *(1+$E10)^((YEAR(TIMELINE!H7)-2025)+(MONTH(TIMELINE!H7)-1)/12) /12 *INDEX(Assumptions_Commercial!$B$22:$B$33,MONTH(TIMELINE!H7)) | M10: =$D10 *(1+$E10)^((YEAR(TIMELINE!I7)-2025)+(MONTH(TIMELINE!I7)-1)/12) /12 *INDEX(Assumptions_Commercial!$B$22:$B$33,MONTH(TIMELINE!I7)) | ... DU10: =$D10 *(1+$E10)^((YEAR(TIMELINE!DQ7)-2025)+(MONTH(TIMELINE!DQ7)-1)/12) /12 *INDEX(Assumptions_Commercial!$B$22:$B$33,MONTH(TIMELINE!DQ7))
A11: SKU-06 | B11: On-Trade | C11: AU | D11: 38000 | E11: =INDEX(Assumptions_Commercial!$B$5:$D$5,CONTROL!$B$5) | F11: =$D11 *(1+$E11)^((YEAR(TIMELINE!B7)-2025)+(MONTH(TIMELINE!B7)-1)/12) /12 *INDEX(Assumptions_Commercial!$B$22:$B$33,MONTH(TIMELINE!B7)) | G11: =$D11 *(1+$E11)^((YEAR(TIMELINE!C7)-2025)+(MONTH(TIMELINE!C7)-1)/12) /12 *INDEX(Assumptions_Commercial!$B$22:$B$33,MONTH(TIMELINE!C7)) | H11: =$D11 *(1+$E11)^((YEAR(TIMELINE!D7)-2025)+(MONTH(TIMELINE!D7)-1)/12) /12 *INDEX(Assumptions_Commercial!$B$22:$B$33,MONTH(TIMELINE!D7)) | I11: =$D11 *(1+$E11)^((YEAR(TIMELINE!E7)-2025)+(MONTH(TIMELINE!E7)-1)/12) /12 *INDEX(Assumptions_Commercial!$B$22:$B$33,MONTH(TIMELINE!E7)) | J11: =$D11 *(1+$E11)^((YEAR(TIMELINE!F7)-2025)+(MONTH(TIMELINE!F7)-1)/12) /12 *INDEX(Assumptions_Commercial!$B$22:$B$33,MONTH(TIMELINE!F7)) | K11: =$D11 *(1+$E11)^((YEAR(TIMELINE!G7)-2025)+(MONTH(TIMELINE!G7)-1)/12) /12 *INDEX(Assumptions_Commercial!$B$22:$B$33,MONTH(TIMELINE!G7)) | L11: =$D11 *(1+$E11)^((YEAR(TIMELINE!H7)-2025)+(MONTH(TIMELINE!H7)-1)/12) /12 *INDEX(Assumptions_Commercial!$B$22:$B$33,MONTH(TIMELINE!H7)) | M11: =$D11 *(1+$E11)^((YEAR(TIMELINE!I7)-2025)+(MONTH(TIMELINE!I7)-1)/12) /12 *INDEX(Assumptions_Commercial!$B$22:$B$33,MONTH(TIMELINE!I7)) | ... DU11: =$D11 *(1+$E11)^((YEAR(TIMELINE!DQ7)-2025)+(MONTH(TIMELINE!DQ7)-1)/12) /12 *INDEX(Assumptions_Commercial!$B$22:$B$33,MONTH(TIMELINE!DQ7))
A12: SKU-07 | B12: On-Trade | C12: AU | D12: 18000 | E12: =INDEX(Assumptions_Commercial!$B$5:$D$5,CONTROL!$B$5) | F12: =$D12 *(1+$E12)^((YEAR(TIMELINE!B7)-2025)+(MONTH(TIMELINE!B7)-1)/12) /12 *INDEX(Assumptions_Commercial!$B$22:$B$33,MONTH(TIMELINE!B7)) | G12: =$D12 *(1+$E12)^((YEAR(TIMELINE!C7)-2025)+(MONTH(TIMELINE!C7)-1)/12) /12 *INDEX(Assumptions_Commercial!$B$22:$B$33,MONTH(TIMELINE!C7)) | H12: =$D12 *(1+$E12)^((YEAR(TIMELINE!D7)-2025)+(MONTH(TIMELINE!D7)-1)/12) /12 *INDEX(Assumptions_Commercial!$B$22:$B$33,MONTH(TIMELINE!D7)) | I12: =$D12 *(1+$E12)^((YEAR(TIMELINE!E7)-2025)+(MONTH(TIMELINE!E7)-1)/12) /12 *INDEX(Assumptions_Commercial!$B$22:$B$33,MONTH(TIMELINE!E7)) | J12: =$D12 *(1+$E12)^((YEAR(TIMELINE!F7)-2025)+(MONTH(TIMELINE!F7)-1)/12) /12 *INDEX(Assumptions_Commercial!$B$22:$B$33,MONTH(TIMELINE!F7)) | K12: =$D12 *(1+$E12)^((YEAR(TIMELINE!G7)-2025)+(MONTH(TIMELINE!G7)-1)/12) /12 *INDEX(Assumptions_Commercial!$B$22:$B$33,MONTH(TIMELINE!G7)) | L12: =$D12 *(1+$E12)^((YEAR(TIMELINE!H7)-2025)+(MONTH(TIMELINE!H7)-1)/12) /12 *INDEX(Assumptions_Commercial!$B$22:$B$33,MONTH(TIMELINE!H7)) | M12: =$D12 *(1+$E12)^((YEAR(TIMELINE!I7)-2025)+(MONTH(TIMELINE!I7)-1)/12) /12 *INDEX(Assumptions_Commercial!$B$22:$B$33,MONTH(TIMELINE!I7)) | ... DU12: =$D12 *(1+$E12)^((YEAR(TIMELINE!DQ7)-2025)+(MONTH(TIMELINE!DQ7)-1)/12) /12 *INDEX(Assumptions_Commercial!$B$22:$B$33,MONTH(TIMELINE!DQ7))
A13: SKU-07 | B13: Off-Trade | C13: AU | D13: 18000 | E13: =INDEX(Assumptions_Commercial!$B$5:$D$5,CONTROL!$B$5) | F13: =$D13 *(1+$E13)^((YEAR(TIMELINE!B7)-2025)+(MONTH(TIMELINE!B7)-1)/12) /12 *INDEX(Assumptions_Commercial!$B$22:$B$33,MONTH(TIMELINE!B7)) | G13: =$D13 *(1+$E13)^((YEAR(TIMELINE!C7)-2025)+(MONTH(TIMELINE!C7)-1)/12) /12 *INDEX(Assumptions_Commercial!$B$22:$B$33,MONTH(TIMELINE!C7)) | H13: =$D13 *(1+$E13)^((YEAR(TIMELINE!D7)-2025)+(MONTH(TIMELINE!D7)-1)/12) /12 *INDEX(Assumptions_Commercial!$B$22:$B$33,MONTH(TIMELINE!D7)) | I13: =$D13 *(1+$E13)^((YEAR(TIMELINE!E7)-2025)+(MONTH(TIMELINE!E7)-1)/12) /12 *INDEX(Assumptions_Commercial!$B$22:$B$33,MONTH(TIMELINE!E7)) | J13: =$D13 *(1+$E13)^((YEAR(TIMELINE!F7)-2025)+(MONTH(TIMELINE!F7)-1)/12) /12 *INDEX(Assumptions_Commercial!$B$22:$B$33,MONTH(TIMELINE!F7)) | K13: =$D13 *(1+$E13)^((YEAR(TIMELINE!G7)-2025)+(MONTH(TIMELINE!G7)-1)/12) /12 *INDEX(Assumptions_Commercial!$B$22:$B$33,MONTH(TIMELINE!G7)) | L13: =$D13 *(1+$E13)^((YEAR(TIMELINE!H7)-2025)+(MONTH(TIMELINE!H7)-1)/12) /12 *INDEX(Assumptions_Commercial!$B$22:$B$33,MONTH(TIMELINE!H7)) | M13: =$D13 *(1+$E13)^((YEAR(TIMELINE!I7)-2025)+(MONTH(TIMELINE!I7)-1)/12) /12 *INDEX(Assumptions_Commercial!$B$22:$B$33,MONTH(TIMELINE!I7)) | ... DU13: =$D13 *(1+$E13)^((YEAR(TIMELINE!DQ7)-2025)+(MONTH(TIMELINE!DQ7)-1)/12) /12 *INDEX(Assumptions_Commercial!$B$22:$B$33,MONTH(TIMELINE!DQ7))
A14: SKU-08 | B14: Off-Trade | C14: AU | D14: 25000 | E14: =INDEX(Assumptions_Commercial!$B$5:$D$5,CONTROL!$B$5) | F14: =$D14 *(1+$E14)^((YEAR(TIMELINE!B7)-2025)+(MONTH(TIMELINE!B7)-1)/12) /12 *INDEX(Assumptions_Commercial!$B$22:$B$33,MONTH(TIMELINE!B7)) | G14: =$D14 *(1+$E14)^((YEAR(TIMELINE!C7)-2025)+(MONTH(TIMELINE!C7)-1)/12) /12 *INDEX(Assumptions_Commercial!$B$22:$B$33,MONTH(TIMELINE!C7)) | H14: =$D14 *(1+$E14)^((YEAR(TIMELINE!D7)-2025)+(MONTH(TIMELINE!D7)-1)/12) /12 *INDEX(Assumptions_Commercial!$B$22:$B$33,MONTH(TIMELINE!D7)) | I14: =$D14 *(1+$E14)^((YEAR(TIMELINE!E7)-2025)+(MONTH(TIMELINE!E7)-1)/12) /12 *INDEX(Assumptions_Commercial!$B$22:$B$33,MONTH(TIMELINE!E7)) | J14: =$D14 *(1+$E14)^((YEAR(TIMELINE!F7)-2025)+(MONTH(TIMELINE!F7)-1)/12) /12 *INDEX(Assumptions_Commercial!$B$22:$B$33,MONTH(TIMELINE!F7)) | K14: =$D14 *(1+$E14)^((YEAR(TIMELINE!G7)-2025)+(MONTH(TIMELINE!G7)-1)/12) /12 *INDEX(Assumptions_Commercial!$B$22:$B$33,MONTH(TIMELINE!G7)) | L14: =$D14 *(1+$E14)^((YEAR(TIMELINE!H7)-2025)+(MONTH(TIMELINE!H7)-1)/12) /12 *INDEX(Assumptions_Commercial!$B$22:$B$33,MONTH(TIMELINE!H7)) | M14: =$D14 *(1+$E14)^((YEAR(TIMELINE!I7)-2025)+(MONTH(TIMELINE!I7)-1)/12) /12 *INDEX(Assumptions_Commercial!$B$22:$B$33,MONTH(TIMELINE!I7)) | ... DU14: =$D14 *(1+$E14)^((YEAR(TIMELINE!DQ7)-2025)+(MONTH(TIMELINE!DQ7)-1)/12) /12 *INDEX(Assumptions_Commercial!$B$22:$B$33,MONTH(TIMELINE!DQ7))
A15: SKU-09 | B15: Off-Trade | C15: AU | D15: 38000 | E15: =INDEX(Assumptions_Commercial!$B$5:$D$5,CONTROL!$B$5) | F15: =$D15 *(1+$E15)^((YEAR(TIMELINE!B7)-2025)+(MONTH(TIMELINE!B7)-1)/12) /12 *INDEX(Assumptions_Commercial!$B$22:$B$33,MONTH(TIMELINE!B7)) | G15: =$D15 *(1+$E15)^((YEAR(TIMELINE!C7)-2025)+(MONTH(TIMELINE!C7)-1)/12) /12 *INDEX(Assumptions_Commercial!$B$22:$B$33,MONTH(TIMELINE!C7)) | H15: =$D15 *(1+$E15)^((YEAR(TIMELINE!D7)-2025)+(MONTH(TIMELINE!D7)-1)/12) /12 *INDEX(Assumptions_Commercial!$B$22:$B$33,MONTH(TIMELINE!D7)) | I15: =$D15 *(1+$E15)^((YEAR(TIMELINE!E7)-2025)+(MONTH(TIMELINE!E7)-1)/12) /12 *INDEX(Assumptions_Commercial!$B$22:$B$33,MONTH(TIMELINE!E7)) | J15: =$D15 *(1+$E15)^((YEAR(TIMELINE!F7)-2025)+(MONTH(TIMELINE!F7)-1)/12) /12 *INDEX(Assumptions_Commercial!$B$22:$B$33,MONTH(TIMELINE!F7)) | K15: =$D15 *(1+$E15)^((YEAR(TIMELINE!G7)-2025)+(MONTH(TIMELINE!G7)-1)/12) /12 *INDEX(Assumptions_Commercial!$B$22:$B$33,MONTH(TIMELINE!G7)) | L15: =$D15 *(1+$E15)^((YEAR(TIMELINE!H7)-2025)+(MONTH(TIMELINE!H7)-1)/12) /12 *INDEX(Assumptions_Commercial!$B$22:$B$33,MONTH(TIMELINE!H7)) | M15: =$D15 *(1+$E15)^((YEAR(TIMELINE!I7)-2025)+(MONTH(TIMELINE!I7)-1)/12) /12 *INDEX(Assumptions_Commercial!$B$22:$B$33,MONTH(TIMELINE!I7)) | ... DU15: =$D15 *(1+$E15)^((YEAR(TIMELINE!DQ7)-2025)+(MONTH(TIMELINE!DQ7)-1)/12) /12 *INDEX(Assumptions_Commercial!$B$22:$B$33,MONTH(TIMELINE!DQ7))
A16: SKU-10 | B16: Off-Trade | C16: AU | D16: 20000 | E16: =INDEX(Assumptions_Commercial!$B$5:$D$5,CONTROL!$B$5) | F16: =$D16 *(1+$E16)^((YEAR(TIMELINE!B7)-2025)+(MONTH(TIMELINE!B7)-1)/12) /12 *INDEX(Assumptions_Commercial!$B$22:$B$33,MONTH(TIMELINE!B7)) | G16: =$D16 *(1+$E16)^((YEAR(TIMELINE!C7)-2025)+(MONTH(TIMELINE!C7)-1)/12) /12 *INDEX(Assumptions_Commercial!$B$22:$B$33,MONTH(TIMELINE!C7)) | H16: =$D16 *(1+$E16)^((YEAR(TIMELINE!D7)-2025)+(MONTH(TIMELINE!D7)-1)/12) /12 *INDEX(Assumptions_Commercial!$B$22:$B$33,MONTH(TIMELINE!D7)) | I16: =$D16 *(1+$E16)^((YEAR(TIMELINE!E7)-2025)+(MONTH(TIMELINE!E7)-1)/12) /12 *INDEX(Assumptions_Commercial!$B$22:$B$33,MONTH(TIMELINE!E7)) | J16: =$D16 *(1+$E16)^((YEAR(TIMELINE!F7)-2025)+(MONTH(TIMELINE!F7)-1)/12) /12 *INDEX(Assumptions_Commercial!$B$22:$B$33,MONTH(TIMELINE!F7)) | K16: =$D16 *(1+$E16)^((YEAR(TIMELINE!G7)-2025)+(MONTH(TIMELINE!G7)-1)/12) /12 *INDEX(Assumptions_Commercial!$B$22:$B$33,MONTH(TIMELINE!G7)) | L16: =$D16 *(1+$E16)^((YEAR(TIMELINE!H7)-2025)+(MONTH(TIMELINE!H7)-1)/12) /12 *INDEX(Assumptions_Commercial!$B$22:$B$33,MONTH(TIMELINE!H7)) | M16: =$D16 *(1+$E16)^((YEAR(TIMELINE!I7)-2025)+(MONTH(TIMELINE!I7)-1)/12) /12 *INDEX(Assumptions_Commercial!$B$22:$B$33,MONTH(TIMELINE!I7)) | ... DU16: =$D16 *(1+$E16)^((YEAR(TIMELINE!DQ7)-2025)+(MONTH(TIMELINE!DQ7)-1)/12) /12 *INDEX(Assumptions_Commercial!$B$22:$B$33,MONTH(TIMELINE!DQ7))
A17: SKU-01 | B17: Off-Trade | C17: NZ | D17: 18000 | E17: =INDEX(Assumptions_Commercial!$B$6:$D$6,CONTROL!$B$5) | F17: =$D17 *(1+$E17)^((YEAR(TIMELINE!B7)-2025)+(MONTH(TIMELINE!B7)-1)/12) /12 *INDEX(Assumptions_Commercial!$B$22:$B$33,MONTH(TIMELINE!B7)) | G17: =$D17 *(1+$E17)^((YEAR(TIMELINE!C7)-2025)+(MONTH(TIMELINE!C7)-1)/12) /12 *INDEX(Assumptions_Commercial!$B$22:$B$33,MONTH(TIMELINE!C7)) | H17: =$D17 *(1+$E17)^((YEAR(TIMELINE!D7)-2025)+(MONTH(TIMELINE!D7)-1)/12) /12 *INDEX(Assumptions_Commercial!$B$22:$B$33,MONTH(TIMELINE!D7)) | I17: =$D17 *(1+$E17)^((YEAR(TIMELINE!E7)-2025)+(MONTH(TIMELINE!E7)-1)/12) /12 *INDEX(Assumptions_Commercial!$B$22:$B$33,MONTH(TIMELINE!E7)) | J17: =$D17 *(1+$E17)^((YEAR(TIMELINE!F7)-2025)+(MONTH(TIMELINE!F7)-1)/12) /12 *INDEX(Assumptions_Commercial!$B$22:$B$33,MONTH(TIMELINE!F7)) | K17: =$D17 *(1+$E17)^((YEAR(TIMELINE!G7)-2025)+(MONTH(TIMELINE!G7)-1)/12) /12 *INDEX(Assumptions_Commercial!$B$22:$B$33,MONTH(TIMELINE!G7)) | L17: =$D17 *(1+$E17)^((YEAR(TIMELINE!H7)-2025)+(MONTH(TIMELINE!H7)-1)/12) /12 *INDEX(Assumptions_Commercial!$B$22:$B$33,MONTH(TIMELINE!H7)) | M17: =$D17 *(1+$E17)^((YEAR(TIMELINE!I7)-2025)+(MONTH(TIMELINE!I7)-1)/12) /12 *INDEX(Assumptions_Commercial!$B$22:$B$33,MONTH(TIMELINE!I7)) | ... DU17: =$D17 *(1+$E17)^((YEAR(TIMELINE!DQ7)-2025)+(MONTH(TIMELINE!DQ7)-1)/12) /12 *INDEX(Assumptions_Commercial!$B$22:$B$33,MONTH(TIMELINE!DQ7))
A18: SKU-02 | B18: Off-Trade | C18: NZ | D18: 15000 | E18: =INDEX(Assumptions_Commercial!$B$6:$D$6,CONTROL!$B$5) | F18: =$D18 *(1+$E18)^((YEAR(TIMELINE!B7)-2025)+(MONTH(TIMELINE!B7)-1)/12) /12 *INDEX(Assumptions_Commercial!$B$22:$B$33,MONTH(TIMELINE!B7)) | G18: =$D18 *(1+$E18)^((YEAR(TIMELINE!C7)-2025)+(MONTH(TIMELINE!C7)-1)/12) /12 *INDEX(Assumptions_Commercial!$B$22:$B$33,MONTH(TIMELINE!C7)) | H18: =$D18 *(1+$E18)^((YEAR(TIMELINE!D7)-2025)+(MONTH(TIMELINE!D7)-1)/12) /12 *INDEX(Assumptions_Commercial!$B$22:$B$33,MONTH(TIMELINE!D7)) | I18: =$D18 *(1+$E18)^((YEAR(TIMELINE!E7)-2025)+(MONTH(TIMELINE!E7)-1)/12) /12 *INDEX(Assumptions_Commercial!$B$22:$B$33,MONTH(TIMELINE!E7)) | J18: =$D18 *(1+$E18)^((YEAR(TIMELINE!F7)-2025)+(MONTH(TIMELINE!F7)-1)/12) /12 *INDEX(Assumptions_Commercial!$B$22:$B$33,MONTH(TIMELINE!F7)) | K18: =$D18 *(1+$E18)^((YEAR(TIMELINE!G7)-2025)+(MONTH(TIMELINE!G7)-1)/12) /12 *INDEX(Assumptions_Commercial!$B$22:$B$33,MONTH(TIMELINE!G7)) | L18: =$D18 *(1+$E18)^((YEAR(TIMELINE!H7)-2025)+(MONTH(TIMELINE!H7)-1)/12) /12 *INDEX(Assumptions_Commercial!$B$22:$B$33,MONTH(TIMELINE!H7)) | M18: =$D18 *(1+$E18)^((YEAR(TIMELINE!I7)-2025)+(MONTH(TIMELINE!I7)-1)/12) /12 *INDEX(Assumptions_Commercial!$B$22:$B$33,MONTH(TIMELINE!I7)) | ... DU18: =$D18 *(1+$E18)^((YEAR(TIMELINE!DQ7)-2025)+(MONTH(TIMELINE!DQ7)-1)/12) /12 *INDEX(Assumptions_Commercial!$B$22:$B$33,MONTH(TIMELINE!DQ7))
A19: SKU-03 | B19: On-Trade | C19: NZ | D19: 12000 | E19: =INDEX(Assumptions_Commercial!$B$6:$D$6,CONTROL!$B$5) | F19: =$D19 *(1+$E19)^((YEAR(TIMELINE!B7)-2025)+(MONTH(TIMELINE!B7)-1)/12) /12 *INDEX(Assumptions_Commercial!$B$22:$B$33,MONTH(TIMELINE!B7)) | G19: =$D19 *(1+$E19)^((YEAR(TIMELINE!C7)-2025)+(MONTH(TIMELINE!C7)-1)/12) /12 *INDEX(Assumptions_Commercial!$B$22:$B$33,MONTH(TIMELINE!C7)) | H19: =$D19 *(1+$E19)^((YEAR(TIMELINE!D7)-2025)+(MONTH(TIMELINE!D7)-1)/12) /12 *INDEX(Assumptions_Commercial!$B$22:$B$33,MONTH(TIMELINE!D7)) | I19: =$D19 *(1+$E19)^((YEAR(TIMELINE!E7)-2025)+(MONTH(TIMELINE!E7)-1)/12) /12 *INDEX(Assumptions_Commercial!$B$22:$B$33,MONTH(TIMELINE!E7)) | J19: =$D19 *(1+$E19)^((YEAR(TIMELINE!F7)-2025)+(MONTH(TIMELINE!F7)-1)/12) /12 *INDEX(Assumptions_Commercial!$B$22:$B$33,MONTH(TIMELINE!F7)) | K19: =$D19 *(1+$E19)^((YEAR(TIMELINE!G7)-2025)+(MONTH(TIMELINE!G7)-1)/12) /12 *INDEX(Assumptions_Commercial!$B$22:$B$33,MONTH(TIMELINE!G7)) | L19: =$D19 *(1+$E19)^((YEAR(TIMELINE!H7)-2025)+(MONTH(TIMELINE!H7)-1)/12) /12 *INDEX(Assumptions_Commercial!$B$22:$B$33,MONTH(TIMELINE!H7)) | M19: =$D19 *(1+$E19)^((YEAR(TIMELINE!I7)-2025)+(MONTH(TIMELINE!I7)-1)/12) /12 *INDEX(Assumptions_Commercial!$B$22:$B$33,MONTH(TIMELINE!I7)) | ... DU19: =$D19 *(1+$E19)^((YEAR(TIMELINE!DQ7)-2025)+(MONTH(TIMELINE!DQ7)-1)/12) /12 *INDEX(Assumptions_Commercial!$B$22:$B$33,MONTH(TIMELINE!DQ7))
A20: TOTAL HL | F20: =SUM(F4:F19) | G20: =SUM(G4:G19) | H20: =SUM(H4:H19) | I20: =SUM(I4:I19) | J20: =SUM(J4:J19) | K20: =SUM(K4:K19) | L20: =SUM(L4:L19) | M20: =SUM(M4:M19) | ... DU20: =SUM(DU4:DU19)

Sheet Pricing
A1: PRICING
A3: Sheet structure to be completed in Phase 2

Sheet Excise
A1: EXCISE
A3: Sheet structure to be completed in Phase 2

Sheet Revenue
A1: REVENUE (AUD '000)
A3: Line Item | B3: =TIMELINE!B7 | C3: =TIMELINE!C7 | D3: =TIMELINE!D7 | E3: =TIMELINE!E7 | F3: =TIMELINE!F7 | G3: =TIMELINE!G7 | H3: =TIMELINE!H7 | I3: =TIMELINE!I7 | ... DQ3: =TIMELINE!DQ7
A4: Total HL Sold | B4: =Volume_Build!B20 | C4: =Volume_Build!C20 | D4: =Volume_Build!D20 | E4: =Volume_Build!E20 | F4: =Volume_Build!F20 | G4: =Volume_Build!G20 | H4: =Volume_Build!H20 | I4: =Volume_Build!I20 | ... DQ4: =Volume_Build!DQ20
A5: Avg Net Revenue per HL (AUD) | B5: 215 | C5: 215 | D5: 215 | E5: 215 | F5: 215 | G5: 215 | H5: 215 | I5: 215 | J5: 215 | K5: 215 | L5: 215 | M5: 215 | N5: 215 | O5: 215 | P5: 215 | Q5: 215 | R5: 215 | S5: 215 | T5: 215 | U5: 215 | V5: 215 | W5: 215 | X5: 215 | Y5: 215 | Z5: 215 | AA5: 215 | AB5: 215 | AC5: 215 | AD5: 215 | AE5: 215 | AF5: 215 | AG5: 215 | AH5: 215 | AI5: 215 | AJ5: 215 | AK5: 215 | AL5: 215 | AM5: 215 | AN5: 215 | AO5: 215 | AP5: 215 | AQ5: 215 | AR5: 215 | AS5: 215 | AT5: 215 | AU5: 215 | AV5: 215 | AW5: 215 | AX5: 215 | AY5: 215 | AZ5: 215 | BA5: 215 | BB5: 215 | BC5: 215 | BD5: 215 | BE5: 215 | BF5: 215 | BG5: 215 | BH5: 215 | BI5: 215 | BJ5: 215 | BK5: 215 | BL5: 215 | BM5: 215 | BN5: 215 | BO5: 215 | BP5: 215 | BQ5: 215 | BR5: 215 | BS5: 215 | BT5: 215 | BU5: 215 | BV5: 215 | BW5: 215 | BX5: 215 | BY5: 215 | BZ5: 215 | CA5: 215 | CB5: 215 | CC5: 215 | CD5: 215 | CE5: 215 | CF5: 215 | CG5: 215 | CH5: 215 | CI5: 215 | CJ5: 215 | CK5: 215 | CL5: 215 | CM5: 215 | CN5: 215 | CO5: 215 | CP5: 215 | CQ5: 215 | CR5: 215 | CS5: 215 | CT5: 215 | CU5: 215 | CV5: 215 | CW5: 215 | CX5: 215 | CY5: 215 | CZ5: 215 | DA5: 215 | DB5: 215 | DC5: 215 | DD5: 215 | DE5: 215 | DF5: 215 | DG5: 215 | DH5: 215 | DI5: 215 | DJ5: 215 | DK5: 215 | DL5: 215 | DM5: 215 | DN5: 215 | DO5: 215 | DP5: 215 | DQ5: 215
A6: Gross Revenue | B6: =B4*B5/1000 | C6: =C4*C5/1000 | D6: =D4*D5/1000 | E6: =E4*E5/1000 | F6: =F4*F5/1000 | G6: =G4*G5/1000 | H6: =H4*H5/1000 | I6: =I4*I5/1000 | ... DQ6: =DQ4*DQ5/1000
A7: Less: Discounts & Promotions (8%) | B7: =-B6*0.08 | C7: =-C6*0.08 | D7: =-D6*0.08 | E7: =-E6*0.08 | F7: =-F6*0.08 | G7: =-G6*0.08 | H7: =-H6*0.08 | I7: =-I6*0.08 | ... DQ7: =-DQ6*0.08
A8: Less: Excise Duty (est) | B8: =-B4*25/1000 | C8: =-C4*25/1000 | D8: =-D4*25/1000 | E8: =-E4*25/1000 | F8: =-F4*25/1000 | G8: =-G4*25/1000 | H8: =-H4*25/1000 | I8: =-I4*25/1000 | ... DQ8: =-DQ4*25/1000
A9: NET REVENUE | B9: =B6+B7+B8 | C9: =C6+C7+C8 | D9: =D6+D7+D8 | E9: =E6+E7+E8 | F9: =F6+F7+F8 | G9: =G6+G7+G8 | H9: =H6+H7+H8 | I9: =I6+I7+I8 | ... DQ9: =DQ6+DQ7+DQ8

Sheet Production
A1: PRODUCTION
A3: Sheet structure to be completed in Phase 2

Sheet Capacity
A1: CAPACITY
A3: Sheet structure to be completed in Phase 2

Sheet COGS_Materials
A1: COGS MATERIALS
A3: Sheet structure to be completed in Phase 2

Sheet COGS_Packaging
A1: COGS PACKAGING
A3: Sheet structure to be completed in Phase 2

Sheet COGS_Labour
A1: COGS LABOUR
A3: Sheet structure to be completed in Phase 2

Sheet COGS_Overhead
A1: COGS OVERHEAD
A3: Sheet structure to be completed in Phase 2

Sheet COGS_Summary
A1: COST OF GOODS SOLD (AUD '000)
A3: Cost Component | B3: =TIMELINE!B7 | C3: =TIMELINE!C7 | D3: =TIMELINE!D7 | E3: =TIMELINE!E7 | F3: =TIMELINE!F7 | G3: =TIMELINE!G7 | H3: =TIMELINE!H7 | I3: =TIMELINE!I7 | ... DQ3: =TIMELINE!DQ7
A4: HL Produced (from Volume) | B4: =Volume_Build!B20 | C4: =Volume_Build!C20 | D4: =Volume_Build!D20 | E4: =Volume_Build!E20 | F4: =Volume_Build!F20 | G4: =Volume_Build!G20 | H4: =Volume_Build!H20 | I4: =Volume_Build!I20 | ... DQ4: =Volume_Build!DQ20
A5: Materials per HL | B5: =Assumptions_Operations!$B$8 | C5: =Assumptions_Operations!$B$8 | D5: =Assumptions_Operations!$B$8 | E5: =Assumptions_Operations!$B$8 | F5: =Assumptions_Operations!$B$8 | G5: =Assumptions_Operations!$B$8 | H5: =Assumptions_Operations!$B$8 | I5: =Assumptions_Operations!$B$8 | ... DQ5: =Assumptions_Operations!$B$8
A6: Materials Total | B6: =B4*B5/1000 | C6: =C4*C5/1000 | D6: =D4*D5/1000 | E6: =E4*E5/1000 | F6: =F4*F5/1000 | G6: =G4*G5/1000 | H6: =H4*H5/1000 | I6: =I4*I5/1000 | ... DQ6: =DQ4*DQ5/1000
A7: Packaging per HL | B7: =Assumptions_Operations!$B$9 | C7: =Assumptions_Operations!$B$9 | D7: =Assumptions_Operations!$B$9 | E7: =Assumptions_Operations!$B$9 | F7: =Assumptions_Operations!$B$9 | G7: =Assumptions_Operations!$B$9 | H7: =Assumptions_Operations!$B$9 | I7: =Assumptions_Operations!$B$9 | ... DQ7: =Assumptions_Operations!$B$9
A8: Packaging Total | B8: =B4*B8/1000 | C8: =C4*C8/1000 | D8: =D4*D8/1000 | E8: =E4*E8/1000 | F8: =F4*F8/1000 | G8: =G4*G8/1000 | H8: =H4*H8/1000 | I8: =I4*I8/1000 | ... DQ8: =DQ4*DQ8/1000
A9: Labour per HL | B9: =Assumptions_Operations!$B$10 | C9: =Assumptions_Operations!$B$10 | D9: =Assumptions_Operations!$B$10 | E9: =Assumptions_Operations!$B$10 | F9: =Assumptions_Operations!$B$10 | G9: =Assumptions_Operations!$B$10 | H9: =Assumptions_Operations!$B$10 | I9: =Assumptions_Operations!$B$10 | ... DQ9: =Assumptions_Operations!$B$10
A10: Labour Total | B10: =B4*B11/1000 | C10: =C4*C11/1000 | D10: =D4*D11/1000 | E10: =E4*E11/1000 | F10: =F4*F11/1000 | G10: =G4*G11/1000 | H10: =H4*H11/1000 | I10: =I4*I11/1000 | ... DQ10: =DQ4*DQ11/1000
A11: Utilities per HL | B11: =Assumptions_Operations!$B$11 | C11: =Assumptions_Operations!$B$11 | D11: =Assumptions_Operations!$B$11 | E11: =Assumptions_Operations!$B$11 | F11: =Assumptions_Operations!$B$11 | G11: =Assumptions_Operations!$B$11 | H11: =Assumptions_Operations!$B$11 | I11: =Assumptions_Operations!$B$11 | ... DQ11: =Assumptions_Operations!$B$11
A12: Utilities Total | B12: =B4*B14/1000 | C12: =C4*C14/1000 | D12: =D4*D14/1000 | E12: =E4*E14/1000 | F12: =F4*F14/1000 | G12: =G4*G14/1000 | H12: =H4*H14/1000 | I12: =I4*I14/1000 | ... DQ12: =DQ4*DQ14/1000
A13: Overhead Total | B13: =Assumptions_Operations!$B$13/1000 | C13: =Assumptions_Operations!$B$13/1000 | D13: =Assumptions_Operations!$B$13/1000 | E13: =Assumptions_Operations!$B$13/1000 | F13: =Assumptions_Operations!$B$13/1000 | G13: =Assumptions_Operations!$B$13/1000 | H13: =Assumptions_Operations!$B$13/1000 | I13: =Assumptions_Operations!$B$13/1000 | ... DQ13: =Assumptions_Operations!$B$13/1000
A14: TOTAL COGS | B14: =B6+B9+B12+B15+B16 | C14: =C6+C9+C12+C15+C16 | D14: =D6+D9+D12+D15+D16 | E14: =E6+E9+E12+E15+E16 | F14: =F6+F9+F12+F15+F16 | G14: =G6+G9+G12+G15+G16 | H14: =H6+H9+H12+H15+H16 | I14: =I6+I9+I12+I15+I16 | ... DQ14: =DQ6+DQ9+DQ12+DQ15+DQ16

Sheet Logistics
A1: LOGISTICS
A3: Sheet structure to be completed in Phase 2

Sheet SGA
A1: SGA
A3: Sheet structure to be completed in Phase 2

Sheet Capex_Schedule
A1: CAPEX SCHEDULE
A3: Sheet structure to be completed in Phase 2

Sheet Fixed_Assets
A1: FIXED ASSETS
A3: Sheet structure to be completed in Phase 2

Sheet Depreciation
A1: DEPRECIATION
A3: Sheet structure to be completed in Phase 2

Sheet Working_Capital
A1: WORKING CAPITAL
A3: Sheet structure to be completed in Phase 2

Sheet Debt_Schedule
A1: DEBT SCHEDULE
A3: Sheet structure to be completed in Phase 2

Sheet Equity
A1: EQUITY
A3: Sheet structure to be completed in Phase 2

Sheet IS
A1: INCOME STATEMENT (AUD '000)
A3: Line Item | B3: =TIMELINE!B7 | C3: =TIMELINE!C7 | D3: =TIMELINE!D7 | E3: =TIMELINE!E7 | F3: =TIMELINE!F7 | G3: =TIMELINE!G7 | H3: =TIMELINE!H7 | I3: =TIMELINE!I7 | ... DQ3: =TIMELINE!DQ7
A4: Net Revenue | B4: =Revenue!B9 | C4: =Revenue!C9 | D4: =Revenue!D9 | E4: =Revenue!E9 | F4: =Revenue!F9 | G4: =Revenue!G9 | H4: =Revenue!H9 | I4: =Revenue!I9 | ... DQ4: =Revenue!DQ9
A5: Cost of Goods Sold | B5: =-COGS_Summary!B17 | C5: =-COGS_Summary!C17 | D5: =-COGS_Summary!D17 | E5: =-COGS_Summary!E17 | F5: =-COGS_Summary!F17 | G5: =-COGS_Summary!G17 | H5: =-COGS_Summary!H17 | I5: =-COGS_Summary!I17 | ... DQ5: =-COGS_Summary!DQ17
A6: GROSS PROFIT | B6: =B4+B5 | C6: =C4+C5 | D6: =D4+D5 | E6: =E4+E5 | F6: =F4+F5 | G6: =G4+G5 | H6: =H4+H5 | I6: =I4+I5 | ... DQ6: =DQ4+DQ5
A7: Gross Margin % | B7: =B6/B4 | C7: =C6/C4 | D7: =D6/D4 | E7: =E6/E4 | F7: =F6/F4 | G7: =G6/G4 | H7: =H6/H4 | I7: =I6/I4 | ... DQ7: =DQ6/DQ4
A9: Operating Expenses
A10: Distribution & Logistics | B10: =-B4*12/1000 | C10: =-C4*12/1000 | D10: =-D4*12/1000 | E10: =-E4*12/1000 | F10: =-F4*12/1000 | G10: =-G4*12/1000 | H10: =-H4*12/1000 | I10: =-I4*12/1000 | ... DQ10: =-DQ4*12/1000
A11: SG&A | B11: =-B4*0.12 | C11: =-C4*0.12 | D11: =-D4*0.12 | E11: =-E4*0.12 | F11: =-F4*0.12 | G11: =-G4*0.12 | H11: =-H4*0.12 | I11: =-I4*0.12 | ... DQ11: =-DQ4*0.12
A12: Admin & Overhead | B12: -150 | C12: -150 | D12: -150 | E12: -150 | F12: -150 | G12: -150 | H12: -150 | I12: -150 | J12: -150 | K12: -150 | L12: -150 | M12: -150 | N12: -150 | O12: -150 | P12: -150 | Q12: -150 | R12: -150 | S12: -150 | T12: -150 | U12: -150 | V12: -150 | W12: -150 | X12: -150 | Y12: -150 | Z12: -150 | AA12: -150 | AB12: -150 | AC12: -150 | AD12: -150 | AE12: -150 | AF12: -150 | AG12: -150 | AH12: -150 | AI12: -150 | AJ12: -150 | AK12: -150 | AL12: -150 | AM12: -150 | AN12: -150 | AO12: -150 | AP12: -150 | AQ12: -150 | AR12: -150 | AS12: -150 | AT12: -150 | AU12: -150 | AV12: -150 | AW12: -150 | AX12: -150 | AY12: -150 | AZ12: -150 | BA12: -150 | BB12: -150 | BC12: -150 | BD12: -150 | BE12: -150 | BF12: -150 | BG12: -150 | BH12: -150 | BI12: -150 | BJ12: -150 | BK12: -150 | BL12: -150 | BM12: -150 | BN12: -150 | BO12: -150 | BP12: -150 | BQ12: -150 | BR12: -150 | BS12: -150 | BT12: -150 | BU12: -150 | BV12: -150 | BW12: -150 | BX12: -150 | BY12: -150 | BZ12: -150 | CA12: -150 | CB12: -150 | CC12: -150 | CD12: -150 | CE12: -150 | CF12: -150 | CG12: -150 | CH12: -150 | CI12: -150 | CJ12: -150 | CK12: -150 | CL12: -150 | CM12: -150 | CN12: -150 | CO12: -150 | CP12: -150 | CQ12: -150 | CR12: -150 | CS12: -150 | CT12: -150 | CU12: -150 | CV12: -150 | CW12: -150 | CX12: -150 | CY12: -150 | CZ12: -150 | DA12: -150 | DB12: -150 | DC12: -150 | DD12: -150 | DE12: -150 | DF12: -150 | DG12: -150 | DH12: -150 | DI12: -150 | DJ12: -150 | DK12: -150 | DL12: -150 | DM12: -150 | DN12: -150 | DO12: -150 | DP12: -150 | DQ12: -150
A13: Total OpEx | B13: =B11+B12+B13 | C13: =C11+C12+C13 | D13: =D11+D12+D13 | E13: =E11+E12+E13 | F13: =F11+F12+F13 | G13: =G11+G12+G13 | H13: =H11+H12+H13 | I13: =I11+I12+I13 | ... DQ13: =DQ11+DQ12+DQ13
A15: EBITDA | B15: =B6+B14 | C15: =C6+C14 | D15: =D6+D14 | E15: =E6+E14 | F15: =F6+F14 | G15: =G6+G14 | H15: =H6+H14 | I15: =I6+I14 | ... DQ15: =DQ6+DQ14
A16: EBITDA Margin % | B16: =B16/B4 | C16: =C16/C4 | D16: =D16/D4 | E16: =E16/E4 | F16: =F16/F4 | G16: =G16/G4 | H16: =H16/H4 | I16: =I16/I4 | ... DQ16: =DQ16/DQ4
A18: Depreciation & Amortisation | B18: -250 | C18: -250 | D18: -250 | E18: -250 | F18: -250 | G18: -250 | H18: -250 | I18: -250 | J18: -250 | K18: -250 | L18: -250 | M18: -250 | N18: -250 | O18: -250 | P18: -250 | Q18: -250 | R18: -250 | S18: -250 | T18: -250 | U18: -250 | V18: -250 | W18: -250 | X18: -250 | Y18: -250 | Z18: -250 | AA18: -250 | AB18: -250 | AC18: -250 | AD18: -250 | AE18: -250 | AF18: -250 | AG18: -250 | AH18: -250 | AI18: -250 | AJ18: -250 | AK18: -250 | AL18: -250 | AM18: -250 | AN18: -250 | AO18: -250 | AP18: -250 | AQ18: -250 | AR18: -250 | AS18: -250 | AT18: -250 | AU18: -250 | AV18: -250 | AW18: -250 | AX18: -250 | AY18: -250 | AZ18: -250 | BA18: -250 | BB18: -250 | BC18: -250 | BD18: -250 | BE18: -250 | BF18: -250 | BG18: -250 | BH18: -250 | BI18: -250 | BJ18: -250 | BK18: -250 | BL18: -250 | BM18: -250 | BN18: -250 | BO18: -250 | BP18: -250 | BQ18: -250 | BR18: -250 | BS18: -250 | BT18: -250 | BU18: -250 | BV18: -250 | BW18: -250 | BX18: -250 | BY18: -250 | BZ18: -250 | CA18: -250 | CB18: -250 | CC18: -250 | CD18: -250 | CE18: -250 | CF18: -250 | CG18: -250 | CH18: -250 | CI18: -250 | CJ18: -250 | CK18: -250 | CL18: -250 | CM18: -250 | CN18: -250 | CO18: -250 | CP18: -250 | CQ18: -250 | CR18: -250 | CS18: -250 | CT18: -250 | CU18: -250 | CV18: -250 | CW18: -250 | CX18: -250 | CY18: -250 | CZ18: -250 | DA18: -250 | DB18: -250 | DC18: -250 | DD18: -250 | DE18: -250 | DF18: -250 | DG18: -250 | DH18: -250 | DI18: -250 | DJ18: -250 | DK18: -250 | DL18: -250 | DM18: -250 | DN18: -250 | DO18: -250 | DP18: -250 | DQ18: -250
A19: EBIT | B19: =B16+B19 | C19: =C16+C19 | D19: =D16+D19 | E19: =E16+E19 | F19: =F16+F19 | G19: =G16+G19 | H19: =H16+H19 | I19: =I16+I19 | ... DQ19: =DQ16+DQ19
A21: Interest Expense | B21: -81.25 | C21: -81.25 | D21: -81.25 | E21: -81.25 | F21: -81.25 | G21: -81.25 | H21: -81.25 | I21: -81.25 | J21: -81.25 | K21: -81.25 | L21: -81.25 | M21: -81.25 | N21: -81.25 | O21: -81.25 | P21: -81.25 | Q21: -81.25 | R21: -81.25 | S21: -81.25 | T21: -81.25 | U21: -81.25 | V21: -81.25 | W21: -81.25 | X21: -81.25 | Y21: -81.25 | Z21: -81.25 | AA21: -81.25 | AB21: -81.25 | AC21: -81.25 | AD21: -81.25 | AE21: -81.25 | AF21: -81.25 | AG21: -81.25 | AH21: -81.25 | AI21: -81.25 | AJ21: -81.25 | AK21: -81.25 | AL21: -81.25 | AM21: -81.25 | AN21: -81.25 | AO21: -81.25 | AP21: -81.25 | AQ21: -81.25 | AR21: -81.25 | AS21: -81.25 | AT21: -81.25 | AU21: -81.25 | AV21: -81.25 | AW21: -81.25 | AX21: -81.25 | AY21: -81.25 | AZ21: -81.25 | BA21: -81.25 | BB21: -81.25 | BC21: -81.25 | BD21: -81.25 | BE21: -81.25 | BF21: -81.25 | BG21: -81.25 | BH21: -81.25 | BI21: -81.25 | BJ21: -81.25 | BK21: -81.25 | BL21: -81.25 | BM21: -81.25 | BN21: -81.25 | BO21: -81.25 | BP21: -81.25 | BQ21: -81.25 | BR21: -81.25 | BS21: -81.25 | BT21: -81.25 | BU21: -81.25 | BV21: -81.25 | BW21: -81.25 | BX21: -81.25 | BY21: -81.25 | BZ21: -81.25 | CA21: -81.25 | CB21: -81.25 | CC21: -81.25 | CD21: -81.25 | CE21: -81.25 | CF21: -81.25 | CG21: -81.25 | CH21: -81.25 | CI21: -81.25 | CJ21: -81.25 | CK21: -81.25 | CL21: -81.25 | CM21: -81.25 | CN21: -81.25 | CO21: -81.25 | CP21: -81.25 | CQ21: -81.25 | CR21: -81.25 | CS21: -81.25 | CT21: -81.25 | CU21: -81.25 | CV21: -81.25 | CW21: -81.25 | CX21: -81.25 | CY21: -81.25 | CZ21: -81.25 | DA21: -81.25 | DB21: -81.25 | DC21: -81.25 | DD21: -81.25 | DE21: -81.25 | DF21: -81.25 | DG21: -81.25 | DH21: -81.25 | DI21: -81.25 | DJ21: -81.25 | DK21: -81.25 | DL21: -81.25 | DM21: -81.25 | DN21: -81.25 | DO21: -81.25 | DP21: -81.25 | DQ21: -81.25
A22: EBT | B22: =B20+B22 | C22: =C20+C22 | D22: =D20+D22 | E22: =E20+E22 | F22: =F20+F22 | G22: =G20+G22 | H22: =H20+H22 | I22: =I20+I22 | ... DQ22: =DQ20+DQ22
A24: Tax Expense (30%) | B24: =-MAX(0,B23)*0.30 | C24: =-MAX(0,C23)*0.30 | D24: =-MAX(0,D23)*0.30 | E24: =-MAX(0,E23)*0.30 | F24: =-MAX(0,F23)*0.30 | G24: =-MAX(0,G23)*0.30 | H24: =-MAX(0,H23)*0.30 | I24: =-MAX(0,I23)*0.30 | ... DQ24: =-MAX(0,DQ23)*0.30
A25: NET INCOME | B25: =B23+B25 | C25: =C23+C25 | D25: =D23+D25 | E25: =E23+E25 | F25: =F23+F25 | G25: =G23+G25 | H25: =H23+H25 | I25: =I23+I25 | ... DQ25: =DQ23+DQ25
A26: Net Margin % | B26: =B26/B4 | C26: =C26/C4 | D26: =D26/D4 | E26: =E26/E4 | F26: =F26/F4 | G26: =G26/G4 | H26: =H26/H4 | I26: =I26/I4 | ... DQ26: =DQ26/DQ4

Sheet CF
A1: CASH FLOW STATEMENT (AUD '000)
A3: Line Item | B3: =TIMELINE!B7 | C3: =TIMELINE!C7 | D3: =TIMELINE!D7 | E3: =TIMELINE!E7 | F3: =TIMELINE!F7 | G3: =TIMELINE!G7 | H3: =TIMELINE!H7 | I3: =TIMELINE!I7 | ... DQ3: =TIMELINE!DQ7
A4: Operating Activities
A5: Net Income | B5: =IS!B26 | C5: =IS!C26 | D5: =IS!D26 | E5: =IS!E26 | F5: =IS!F26 | G5: =IS!G26 | H5: =IS!H26 | I5: =IS!I26 | ... DQ5: =IS!DQ26
A6: Add: Depreciation | B6: =IS!B19*-1 | C6: =IS!C19*-1 | D6: =IS!D19*-1 | E6: =IS!E19*-1 | F6: =IS!F19*-1 | G6: =IS!G19*-1 | H6: =IS!H19*-1 | I6: =IS!I19*-1 | ... DQ6: =IS!DQ19*-1
A7: Change in Working Capital | B7: 0 | C7: 0 | D7: 0 | E7: 0 | F7: 0 | G7: 0 | H7: 0 | I7: 0 | J7: 0 | K7: 0 | L7: 0 | M7: 0 | N7: 0 | O7: 0 | P7: 0 | Q7: 0 | R7: 0 | S7: 0 | T7: 0 | U7: 0 | V7: 0 | W7: 0 | X7: 0 | Y7: 0 | Z7: 0 | AA7: 0 | AB7: 0 | AC7: 0 | AD7: 0 | AE7: 0 | AF7: 0 | AG7: 0 | AH7: 0 | AI7: 0 | AJ7: 0 | AK7: 0 | AL7: 0 | AM7: 0 | AN7: 0 | AO7: 0 | AP7: 0 | AQ7: 0 | AR7: 0 | AS7: 0 | AT7: 0 | AU7: 0 | AV7: 0 | AW7: 0 | AX7: 0 | AY7: 0 | AZ7: 0 | BA7: 0 | BB7: 0 | BC7: 0 | BD7: 0 | BE7: 0 | BF7: 0 | BG7: 0 | BH7: 0 | BI7: 0 | BJ7: 0 | BK7: 0 | BL7: 0 | BM7: 0 | BN7: 0 | BO7: 0 | BP7: 0 | BQ7: 0 | BR7: 0 | BS7: 0 | BT7: 0 | BU7: 0 | BV7: 0 | BW7: 0 | BX7: 0 | BY7: 0 | BZ7: 0 | CA7: 0 | CB7: 0 | CC7: 0 | CD7: 0 | CE7: 0 | CF7: 0 | CG7: 0 | CH7: 0 | CI7: 0 | CJ7: 0 | CK7: 0 | CL7: 0 | CM7: 0 | CN7: 0 | CO7: 0 | CP7: 0 | CQ7: 0 | CR7: 0 | CS7: 0 | CT7: 0 | CU7: 0 | CV7: 0 | CW7: 0 | CX7: 0 | CY7: 0 | CZ7: 0 | DA7: 0 | DB7: 0 | DC7: 0 | DD7: 0 | DE7: 0 | DF7: 0 | DG7: 0 | DH7: 0 | DI7: 0 | DJ7: 0 | DK7: 0 | DL7: 0 | DM7: 0 | DN7: 0 | DO7: 0 | DP7: 0 | DQ7: 0
A8: Operating Cash Flow | B8: =B5+B6+B7 | C8: =C5+C6+C7 | D8: =D5+D6+D7 | E8: =E5+E6+E7 | F8: =F5+F6+F7 | G8: =G5+G6+G7 | H8: =H5+H6+H7 | I8: =I5+I6+I7 | ... DQ8: =DQ5+DQ6+DQ7
A10: Investing Activities
A11: Capex | B11: 0 | C11: 0 | D11: 0 | E11: 0 | F11: 0 | G11: 0 | H11: 0 | I11: 0 | J11: 0 | K11: 0 | L11: 0 | M11: 0 | N11: 0 | O11: 0 | P11: 0 | Q11: 0 | R11: 0 | S11: 0 | T11: 0 | U11: 0 | V11: 0 | W11: 0 | X11: 0 | Y11: 0 | Z11: 0 | AA11: 0 | AB11: 0 | AC11: 0 | AD11: 0 | AE11: 0 | AF11: 0 | AG11: 0 | AH11: 0 | AI11: 0 | AJ11: 0 | AK11: 0 | AL11: 0 | AM11: 0 | AN11: 0 | AO11: 0 | AP11: 0 | AQ11: 0 | AR11: 0 | AS11: 0 | AT11: 0 | AU11: 0 | AV11: 0 | AW11: 0 | AX11: 0 | AY11: 0 | AZ11: 0 | BA11: 0 | BB11: 0 | BC11: 0 | BD11: 0 | BE11: 0 | BF11: 0 | BG11: 0 | BH11: 0 | BI11: 0 | BJ11: 0 | BK11: 0 | BL11: 0 | BM11: 0 | BN11: 0 | BO11: 0 | BP11: 0 | BQ11: 0 | BR11: 0 | BS11: 0 | BT11: 0 | BU11: 0 | BV11: 0 | BW11: 0 | BX11: 0 | BY11: 0 | BZ11: 0 | CA11: 0 | CB11: 0 | CC11: 0 | CD11: 0 | CE11: 0 | CF11: 0 | CG11: 0 | CH11: 0 | CI11: 0 | CJ11: 0 | CK11: 0 | CL11: 0 | CM11: 0 | CN11: 0 | CO11: 0 | CP11: 0 | CQ11: 0 | CR11: 0 | CS11: 0 | CT11: 0 | CU11: 0 | CV11: 0 | CW11: 0 | CX11: 0 | CY11: 0 | CZ11: 0 | DA11: 0 | DB11: 0 | DC11: 0 | DD11: 0 | DE11: 0 | DF11: 0 | DG11: 0 | DH11: 0 | DI11: 0 | DJ11: 0 | DK11: 0 | DL11: 0 | DM11: 0 | DN11: 0 | DO11: 0 | DP11: 0 | DQ11: 0
A12: Investing Cash Flow | B12: =B11 | C12: =C11 | D12: =D11 | E12: =E11 | F12: =F11 | G12: =G11 | H12: =H11 | I12: =I11 | ... DQ12: =DQ11
A14: Financing Activities
A15: Debt Drawdowns | B15: 0 | C15: 0 | D15: 0 | E15: 0 | F15: 0 | G15: 0 | H15: 0 | I15: 0 | J15: 0 | K15: 0 | L15: 0 | M15: 0 | N15: 0 | O15: 0 | P15: 0 | Q15: 0 | R15: 0 | S15: 0 | T15: 0 | U15: 0 | V15: 0 | W15: 0 | X15: 0 | Y15: 0 | Z15: 0 | AA15: 0 | AB15: 0 | AC15: 0 | AD15: 0 | AE15: 0 | AF15: 0 | AG15: 0 | AH15: 0 | AI15: 0 | AJ15: 0 | AK15: 0 | AL15: 0 | AM15: 0 | AN15: 0 | AO15: 0 | AP15: 0 | AQ15: 0 | AR15: 0 | AS15: 0 | AT15: 0 | AU15: 0 | AV15: 0 | AW15: 0 | AX15: 0 | AY15: 0 | AZ15: 0 | BA15: 0 | BB15: 0 | BC15: 0 | BD15: 0 | BE15: 0 | BF15: 0 | BG15: 0 | BH15: 0 | BI15: 0 | BJ15: 0 | BK15: 0 | BL15: 0 | BM15: 0 | BN15: 0 | BO15: 0 | BP15: 0 | BQ15: 0 | BR15: 0 | BS15: 0 | BT15: 0 | BU15: 0 | BV15: 0 | BW15: 0 | BX15: 0 | BY15: 0 | BZ15: 0 | CA15: 0 | CB15: 0 | CC15: 0 | CD15: 0 | CE15: 0 | CF15: 0 | CG15: 0 | CH15: 0 | CI15: 0 | CJ15: 0 | CK15: 0 | CL15: 0 | CM15: 0 | CN15: 0 | CO15: 0 | CP15: 0 | CQ15: 0 | CR15: 0 | CS15: 0 | CT15: 0 | CU15: 0 | CV15: 0 | CW15: 0 | CX15: 0 | CY15: 0 | CZ15: 0 | DA15: 0 | DB15: 0 | DC15: 0 | DD15: 0 | DE15: 0 | DF15: 0 | DG15: 0 | DH15: 0 | DI15: 0 | DJ15: 0 | DK15: 0 | DL15: 0 | DM15: 0 | DN15: 0 | DO15: 0 | DP15: 0 | DQ15: 0
A16: Debt Repayments | B16: -178.57 | C16: -178.57 | D16: -178.57 | E16: -178.57 | F16: -178.57 | G16: -178.57 | H16: -178.57 | I16: -178.57 | J16: -178.57 | K16: -178.57 | L16: -178.57 | M16: -178.57 | N16: -178.57 | O16: -178.57 | P16: -178.57 | Q16: -178.57 | R16: -178.57 | S16: -178.57 | T16: -178.57 | U16: -178.57 | V16: -178.57 | W16: -178.57 | X16: -178.57 | Y16: -178.57 | Z16: -178.57 | AA16: -178.57 | AB16: -178.57 | AC16: -178.57 | AD16: -178.57 | AE16: -178.57 | AF16: -178.57 | AG16: -178.57 | AH16: -178.57 | AI16: -178.57 | AJ16: -178.57 | AK16: -178.57 | AL16: -178.57 | AM16: -178.57 | AN16: -178.57 | AO16: -178.57 | AP16: -178.57 | AQ16: -178.57 | AR16: -178.57 | AS16: -178.57 | AT16: -178.57 | AU16: -178.57 | AV16: -178.57 | AW16: -178.57 | AX16: -178.57 | AY16: -178.57 | AZ16: -178.57 | BA16: -178.57 | BB16: -178.57 | BC16: -178.57 | BD16: -178.57 | BE16: -178.57 | BF16: -178.57 | BG16: -178.57 | BH16: -178.57 | BI16: -178.57 | BJ16: -178.57 | BK16: -178.57 | BL16: -178.57 | BM16: -178.57 | BN16: -178.57 | BO16: -178.57 | BP16: -178.57 | BQ16: -178.57 | BR16: -178.57 | BS16: -178.57 | BT16: -178.57 | BU16: -178.57 | BV16: -178.57 | BW16: -178.57 | BX16: -178.57 | BY16: -178.57 | BZ16: -178.57 | CA16: -178.57 | CB16: -178.57 | CC16: -178.57 | CD16: -178.57 | CE16: -178.57 | CF16: -178.57 | CG16: -178.57 | CH16: -178.57 | CI16: -178.57 | CJ16: -178.57 | CK16: -178.57 | CL16: -178.57 | CM16: -178.57 | CN16: -178.57 | CO16: -178.57 | CP16: -178.57 | CQ16: -178.57 | CR16: -178.57 | CS16: -178.57 | CT16: -178.57 | CU16: -178.57 | CV16: -178.57 | CW16: -178.57 | CX16: -178.57 | CY16: -178.57 | CZ16: -178.57 | DA16: -178.57 | DB16: -178.57 | DC16: -178.57 | DD16: -178.57 | DE16: -178.57 | DF16: -178.57 | DG16: -178.57 | DH16: -178.57 | DI16: -178.57 | DJ16: -178.57 | DK16: -178.57 | DL16: -178.57 | DM16: -178.57 | DN16: -178.57 | DO16: -178.57 | DP16: -178.57 | DQ16: -178.57
A17: Interest Paid | B17: =IS!B22 | C17: =IS!C22 | D17: =IS!D22 | E17: =IS!E22 | F17: =IS!F22 | G17: =IS!G22 | H17: =IS!H22 | I17: =IS!I22 | ... DQ17: =IS!DQ22
